Workbook
Name _25년공급전수: '[1]분석(공급량및판매량))'!$B$406:$N$413
Name _25년예상판매량: '[2]분석(공급량및판매량))'!$C$422:$N$439
Name 매출년월: '[3](전산)집계'!$A$2:$A$24
Name 변동후단가표: '매출관리(월)'!$V$5:$X$285
Name 사용량: '[3](전산)집계'!$D$2:$D$24
Name 사용열량: '[3](전산)집계'!$E$2:$E$24
Name 상품: '[3](전산)집계'!$C$2:$C$24

Sheet 총괄표
A2: 2026년 1월 매출현황 | R2: (누계-집계용도) | AA2: 2025년 사업계획서 normal기준작성
A3: 1.판매량 | R3: 1.판매량(단위:GJ) | V3: 1번 )전월기준 누계값으로 작성
A5: 구 분 | C5: 당 월 | J5: 누 계 | R5: 구분 | T5: 구성비 | V5: 판매량(누계)
C6: 계획 (천MJ) | D6: 실적 (천N㎥) | E6: 실적 (천MJ) | F6: 대비 (%) | G6: 전년 (천MJ) | H6: 대비 (%) | I6: 구성비 (%) | J6: 계획 (천MJ) | K6: 실적 (천N㎥) | L6: 실적 (천MJ) | M6: 대비 (%) | N6: 전년 (천MJ) | O6: 대비 (%) | P6: 구성비 (%) | T6: 당월 | U6: 누계 | V6: 계획(GJ) | W6: 실적(천N㎥) | X6: 실적(GJ) | Y6: 전년(GJ)
A7: 주 택 용 | B7: 취사용 | C7: 24108 | D7: =(매출액표!D23)/1000 -> 499.1604 | E7: =ROUND((매출액표!E23)/1000,0) -> 21236 | F7: =ROUND(E7/C7*100,1) -> 88.1 | G7: 22528 | H7: =E7/G7*100 -> 94.264915 | I7: =IF(E7=MAX($E$7:$E$10,$E$12:$E$21),MAX($T$7:$T$21)+(100-SUM($T$7:$T$21)),T7) -> 0.3 | J7: =C7+V7 -> 24108 | K7: =D7+W7 -> 499.1604 | L7: =E7+X7 -> 21236 | M7: =L7/J7*100 -> 88.086942 | N7: =G7+Y7 -> 22528 | O7: =L7/N7*100 -> 94.264915 | P7: =IF(L7=MAX($L$7:$L$10,$L$12:$L$21),MAX($U$7:$U$21)+(100-SUM($U$7:$U$21)),U7) -> 0.3 | R7: 가정용 | S7: 취사용 | T7: =ROUND(E7/$E$23*100,1) -> 0.3 | U7: =ROUND(L7/$L$23*100,1) -> 0.3
B8: 개별난방용 | C8: 4615182 | D8: =((매출액표!D31+매출액표!D36)/1000)-1 -> 108780.59 | E8: =ROUND((매출액표!E31+매출액표!E36)/1000,0) -> 4627118 | F8: =ROUND(E8/C8*100,1) -> 100.3 | G8: 4605642 | H8: =E8/G8*100 -> 100.4663 | I8: =IF(E8=MAX($E$7:$E$10,$E$12:$E$21),MAX($T$7:$T$21)+(100-SUM($T$7:$T$21)),T8) -> 68.8 | J8: =C8+V8 -> 4615182 | K8: =D8+W8 -> 108780.59 | L8: =E8+X8 -> 4627118 | M8: =L8/J8*100 -> 100.25862 | N8: =G8+Y8 -> 4605642 | O8: =L8/N8*100 -> 100.4663 | P8: =IF(L8=MAX($L$7:$L$10,$L$12:$L$21),MAX($U$7:$U$21)+(100-SUM($U$7:$U$21)),U8) -> 68.8 | S8: 개별난방용 | T8: =ROUND(E8/$E$23*100,1) -> 68.9 | U8: =ROUND(L8/$L$23*100,1) -> 68.9
B9: 중앙난방용 | C9: 94160 | D9: =매출액표!D40/1000 -> 2259.7744 | E9: =ROUND(매출액표!E40/1000,0) -> 95999 | F9: =ROUND(E9/C9*100,1) -> 102 | G9: 108064 | H9: =E9/G9*100 -> 88.83532 | I9: =IF(E9=MAX($E$7:$E$10,$E$12:$E$21),MAX($T$7:$T$21)+(100-SUM($T$7:$T$21)),T9) -> 1.4 | J9: =C9+V9 -> 94160 | K9: =D9+W9 -> 2259.7744 | L9: =E9+X9 -> 95999 | M9: =L9/J9*100 -> 101.95306 | N9: =G9+Y9 -> 108064 | O9: =L9/N9*100 -> 88.83532 | P9: =IF(L9=MAX($L$7:$L$10,$L$12:$L$21),MAX($U$7:$U$21)+(100-SUM($U$7:$U$21)),U9) -> 1.4 | S9: 중앙난방용 | T9: =ROUND(E9/$E$23*100,1) -> 1.4 | U9: =ROUND(L9/$L$23*100,1) -> 1.4
B10: 자가열전용 | C10: 75657 | D10: =(매출액표!D44)/1000 -> 1798.021 | E10: =ROUND((매출액표!E44)/1000,0) -> 76391 | F10: =ROUND(E10/C10*100,1) -> 101 | G10: 73322 | H10: =E10/G10*100 -> 104.18565 | I10: =IF(E10=MAX($E$7:$E$10,$E$12:$E$21),MAX($T$7:$T$21)+(100-SUM($T$7:$T$21)),T10) -> 1.1 | J10: =C10+V10 -> 75657 | K10: =D10+W10 -> 1798.021 | L10: =E10+X10 -> 76391 | M10: =L10/J10*100 -> 100.97017 | N10: =G10+Y10 -> 73322 | O10: =L10/N10*100 -> 104.18565 | P10: =IF(L10=MAX($L$7:$L$10,$L$12:$L$21),MAX($U$7:$U$21)+(100-SUM($U$7:$U$21)),U10) -> 1.1 | S10: 자가열전용 | T10: =ROUND(E10/$E$23*100,1) -> 1.1 | U10: =ROUND(L10/$L$23*100,1) -> 1.1
B11: 소 계 | C11: =ROUND(SUM(C7:C10),0) -> 4809107 | D11: =SUM(D7:D10) -> 113337.54 | E11: =SUM(E7:E10) -> 4820744 | F11: =E11/C11*100 -> 100.24198 | G11: =SUM(G7:G10) -> 4809556 | H11: =E11/G11*100 -> 100.23262 | I11: =SUM(I7:I10) -> 71.6 | J11: =ROUNDUP(SUM(J7:J10),0) -> 4809107 | K11: =SUM(K7:K10) -> 113337.54 | L11: =SUM(L7:L10) -> 4820744 | M11: =L11/J11*100 -> 100.24198 | N11: =SUM(N7:N10) -> 4809556 | O11: =L11/N11*100 -> 100.23262 | P11: =SUM(P7:P10) -> 71.6 | S11: 소계 | V11: =ROUNDUP(SUM(V7:V10),0) -> 0 | W11: =SUM(W7:W10) -> 0 | X11: =SUM(X7:X10) -> 0 | Y11: =SUM(Y7:Y10) -> 0
A12: 일반용 | C12: 395548 | D12: =매출액표!D56/1000 -> 9157.08 | E12: =ROUND(매출액표!E56/1000,0) -> 389188 | F12: =ROUND(E12/C12*100,1) -> 98.4 | G12: 388583 | H12: =E12/G12*100 -> 100.15569 | I12: =IF(E12=MAX($E$7:$E$10,$E$12:$E$21),MAX($T$7:$T$21)+(100-SUM($T$7:$T$21)),T12) -> 5.8 | J12: =C12+V12 -> 395548 | K12: =D12+W12 -> 9157.08 | L12: =E12+X12 -> 389188 | M12: =L12/J12*100 -> 98.392104 | N12: =G12+Y12 -> 388583 | O12: =L12/N12*100 -> 100.15569 | P12: =IF(L12=MAX($L$7:$L$10,$L$12:$L$21),MAX($U$7:$U$21)+(100-SUM($U$7:$U$21)),U12) -> 5.8 | R12: 일반용 | T12: =ROUND(E12/$E$23*100,1) -> 5.8 | U12: =ROUND(L12/$L$23*100,1) -> 5.8
A13: 업무난방용 | C13: 130670 | D13: =매출액표!D65/1000 -> 3132.7596 | E13: =ROUND(매출액표!E65/1000,0) -> 133136 | F13: =ROUND(E13/C13*100,1) -> 101.9 | G13: 133088 | H13: =E13/G13*100 -> 100.03607 | I13: =IF(E13=MAX($E$7:$E$10,$E$12:$E$21),MAX($T$7:$T$21)+(100-SUM($T$7:$T$21)),T13) -> 2 | J13: =C13+V13 -> 130670 | K13: =D13+W13 -> 3132.7596 | L13: =E13+X13 -> 133136 | M13: =L13/J13*100 -> 101.8872 | N13: =G13+Y13 -> 133088 | O13: =L13/N13*100 -> 100.03607 | P13: =IF(L13=MAX($L$7:$L$10,$L$12:$L$21),MAX($U$7:$U$21)+(100-SUM($U$7:$U$21)),U13) -> 2 | R13: 업무난방용 | T13: =ROUND(E13/$E$23*100,1) -> 2 | U13: =ROUND(L13/$L$23*100,1) -> 2
A14: 냉방용 | C14: 156265 | D14: =매출액표!D73/1000 -> 3788.24 | E14: =ROUND(매출액표!E73/1000,0) -> 160912 | F14: =ROUND(E14/C14*100,1) -> 103 | G14: 165822 | H14: =E14/G14*100 -> 97.038994 | I14: =IF(E14=MAX($E$7:$E$10,$E$12:$E$21),MAX($T$7:$T$21)+(100-SUM($T$7:$T$21)),T14) -> 2.4 | J14: =C14+V14 -> 156265 | K14: =D14+W14 -> 3788.24 | L14: =E14+X14 -> 160912 | M14: =L14/J14*100 -> 102.97379 | N14: =G14+Y14 -> 165822 | O14: =L14/N14*100 -> 97.038994 | P14: =IF(L14=MAX($L$7:$L$10,$L$12:$L$21),MAX($U$7:$U$21)+(100-SUM($U$7:$U$21)),U14) -> 2.4 | R14: 냉방용 | T14: =ROUND(E14/$E$23*100,1) -> 2.4 | U14: =ROUND(L14/$L$23*100,1) -> 2.4
A15: 산업용 | C15: 918510 | D15: =매출액표!D77/1000 -> 20977.659 | E15: =ROUND(매출액표!E77/1000,0) -> 891075 | F15: =ROUND(E15/C15*100,1) -> 97 | G15: 876935 | H15: =E15/G15*100 -> 101.61243 | I15: =IF(E15=MAX($E$7:$E$10,$E$12:$E$21),MAX($T$7:$T$21)+(100-SUM($T$7:$T$21)),T15) -> 13.3 | J15: =C15+V15 -> 918510 | K15: =D15+W15 -> 20977.659 | L15: =E15+X15 -> 891075 | M15: =L15/J15*100 -> 97.013097 | N15: =G15+Y15 -> 876935 | O15: =L15/N15*100 -> 101.61243 | P15: =IF(L15=MAX($L$7:$L$10,$L$12:$L$21),MAX($U$7:$U$21)+(100-SUM($U$7:$U$21)),U15) -> 13.3 | R15: 산업용 | T15: =ROUND(E15/$E$23*100,1) -> 13.3 | U15: =ROUND(L15/$L$23*100,1) -> 13.3
A16: 수송용(CNG) | C16: 233193 | D16: =ROUND((매출액표!D57+매출액표!D59)/1000,0) -> 5922 | E16: =ROUND((매출액표!E57+매출액표!E59)/1000,0) -> 255560 | F16: =ROUND(E16/C16*100,1) -> 109.6 | G16: 245231 | H16: =E16/G16*100 -> 104.21195 | I16: =IF(E16=MAX($E$7:$E$10,$E$12:$E$21),MAX($T$7:$T$21)+(100-SUM($T$7:$T$21)),T16) -> 3.8 | J16: =C16+V16 -> 233193 | K16: =D16+W16 -> 5922 | L16: =E16+X16 -> 255560 | M16: =L16/J16*100 -> 109.59163 | N16: =G16+Y16 -> 245231 | O16: =L16/N16*100 -> 104.21195 | P16: =IF(L16=MAX($L$7:$L$10,$L$12:$L$21),MAX($U$7:$U$21)+(100-SUM($U$7:$U$21)),U16) -> 3.8 | R16: 수송용(CNG) | T16: =ROUND(E16/$E$23*100,1) -> 3.8 | U16: =ROUND(L16/$L$23*100,1) -> 3.8
A17: 수송용(BIO) | C17: 11266 | D17: =ROUND((매출액표!D58)/1000,0) -> 292 | E17: =ROUND((매출액표!E58)/1000,0) -> 12329 | F17: =ROUND(E17/C17*100,1) -> 109.4 | G17: 11393 | H17: =IFERROR(E17/G17*100,0) -> 108.21557 | I17: =IF(E17=MAX($E$7:$E$10,$E$12:$E$21),MAX($T$7:$T$21)+(100-SUM($T$7:$T$21)),T17) -> 0.2 | J17: =C17+V17 -> 11266 | K17: =D17+W17 -> 292 | L17: =E17+X17 -> 12329 | M17: =L17/J17*100 -> 109.43547 | N17: =G17+Y17 -> 11393 | O17: =IFERROR(L17/N17*100,0) -> 108.21557 | P17: =IF(L17=MAX($L$7:$L$10,$L$12:$L$21),MAX($U$7:$U$21)+(100-SUM($U$7:$U$21)),U17) -> 0.2 | R17: 수송용(BIO) | T17: =ROUND(E17/$E$23*100,1) -> 0.2 | U17: =ROUND(L17/$L$23*100,1) -> 0.2
A18: 열병합용 | C18: 25506 | D18: =매출액표!D82/1000 -> 634.379 | E18: =ROUND(매출액표!E82/1000,0) -> 26951 | F18: =ROUND(E18/C18*100,1) -> 105.7 | G18: 25962 | H18: =E18/G18*100 -> 103.80941 | I18: =IF(E18=MAX($E$7:$E$10,$E$12:$E$21),MAX($T$7:$T$21)+(100-SUM($T$7:$T$21)),T18) -> 0.4 | J18: =C18+V18 -> 25506 | K18: =D18+W18 -> 634.379 | L18: =E18+X18 -> 26951 | M18: =L18/J18*100 -> 105.66533 | N18: =G18+Y18 -> 25962 | O18: =L18/N18*100 -> 103.80941 | P18: =IF(L18=MAX($L$7:$L$10,$L$12:$L$21),MAX($U$7:$U$21)+(100-SUM($U$7:$U$21)),U18) -> 0.4 | R18: 열병합용 | T18: =ROUND(E18/$E$23*100,1) -> 0.4 | U18: =ROUND(L18/$L$23*100,1) -> 0.4
A19: 연료전지용 | C19: 18879 | D19: =매출액표!D87/1000 -> 401.06973 | E19: =ROUND(매출액표!E87/1000,0) -> 17039 | F19: =ROUND(E19/C19*100,1) -> 90.3 | G19: 19407 | H19: =E19/G19*100 -> 87.798217 | I19: =IF(E19=MAX($E$7:$E$10,$E$12:$E$21),MAX($T$7:$T$21)+(100-SUM($T$7:$T$21)),T19) -> 0.3 | J19: =C19+V19 -> 18879 | K19: =D19+W19 -> 401.06973 | L19: =E19+X19 -> 17039 | M19: =L19/J19*100 -> 90.253721 | N19: =G19+Y19 -> 19407 | O19: =L19/N19*100 -> 87.798217 | P19: =IF(L19=MAX($L$7:$L$10,$L$12:$L$21),MAX($U$7:$U$21)+(100-SUM($U$7:$U$21)),U19) -> 0.3 | R19: 연료전지용 | T19: =ROUND(E19/$E$23*100,1) -> 0.3 | U19: =ROUND(L19/$L$23*100,1) -> 0.3
A20: 열전용설비용 | C20: 800 | D20: =매출액표!D89/1000 -> 27.79 | E20: =ROUND(매출액표!E89/1000,0) -> 1181 | F20: =ROUND(E20/C20*100,1) -> 147.6 | G20: 787 | H20: =E20/G20*100 -> 150.06353 | I20: =IF(E20=MAX($E$7:$E$10,$E$12:$E$21),MAX($T$7:$T$21)+(100-SUM($T$7:$T$21)),T20) -> 0 | J20: =C20+V20 -> 800 | K20: =D20+W20 -> 27.79 | L20: =E20+X20 -> 1181 | M20: =L20/J20*100 -> 147.625 | N20: =G20+Y20 -> 787 | O20: =L20/N20*100 -> 150.06353 | P20: =IF(L20=MAX($L$7:$L$10,$L$12:$L$21),MAX($U$7:$U$21)+(100-SUM($U$7:$U$21)),U20) -> 0 | R20: 열전용설비용 | T20: =ROUND(E20/$E$23*100,1) -> 0 | U20: =ROUND(L20/$L$23*100,1) -> 0
A21: 주한미군 | C21: 12243 | D21: =매출액표!D92/1000 -> 268.82534 | E21: =ROUND(매출액표!E92/1000,0) -> 11421 | F21: =ROUND(E21/C21*100,1) -> 93.3 | G21: 12186 | H21: =E21/G21*100 -> 93.722304 | I21: =IF(E21=MAX($E$7:$E$10,$E$12:$E$21),MAX($T$7:$T$21)+(100-SUM($T$7:$T$21)),T21) -> 0.2 | J21: =C21+V21 -> 12243 | K21: =D21+W21 -> 268.82534 | L21: =E21+X21 -> 11421 | M21: =L21/J21*100 -> 93.285959 | N21: =G21+Y21 -> 12186 | O21: =L21/N21*100 -> 93.722304 | P21: =IF(L21=MAX($L$7:$L$10,$L$12:$L$21),MAX($U$7:$U$21)+(100-SUM($U$7:$U$21)),U21) -> 0.2 | R21: 주한미군 | T21: =ROUND(E21/$E$23*100,1) -> 0.2 | U21: =ROUND(L21/$L$23*100,1) -> 0.2
A22: 소 계 | C22: =SUM(C12:C21) -> 1902880 | D22: =SUM(D12:D21) -> 44601.803 | E22: =SUM(E12:E21) -> 1898792 | F22: =E22/C22*100 -> 99.785168 | G22: =SUM(G12:G21) -> 1879394 | H22: =E22/G22*100 -> 101.03214 | I22: =SUM(I12:I21) -> 28.4 | J22: =SUM(J12:J21) -> 1902880 | K22: =SUM(K12:K21) -> 44601.803 | L22: =SUM(L12:L21) -> 1898792 | M22: =L22/J22*100 -> 99.785168 | N22: =SUM(N12:N21) -> 1879394 | O22: =L22/N22*100 -> 101.03214 | P22: =P23-P11 -> 28.4 | R22: 소계 | V22: =SUM(V12:V21) -> 0 | W22: =SUM(W12:W21) -> 0 | X22: =SUM(X12:X21) -> 0 | Y22: =SUM(Y12:Y21) -> 0
A23: 합 계 | C23: =C11+C22 -> 6711987 | D23: =D11+D22 -> 157939.34 | E23: =E22+E11 -> 6719536 | F23: =E23/C23*100 -> 100.11247 | G23: =G22+G11 -> 6688950 | H23: =E23/G23*100 -> 100.45726 | I23: =I11+I22 -> 100 | J23: =J11+J22 -> 6711987 | K23: =K22+K11 -> 157939.34 | L23: =L11+L22 -> 6719536 | M23: =L23/J23*100 -> 100.11247 | N23: =N11+N22 -> 6688950 | O23: =L23/N23*100 -> 100.45726 | P23: 100 | R23: 합계 | V23: =V11+V22 -> 0 | W23: =W11+W22 -> 0 | X23: =X11+X22 -> 0 | Y23: =Y11+Y22 -> 0
A24: 공급량 | C24: 7484365 | D24: 180709365 | E24: 7679226.6 | F24: =E24/C24*100 -> 102.60358 | G24: 7224348 | H24: =$E$24/G24*100 -> 106.29647 | J24: =C24+V24 -> 7484365 | K24: =D24+W24 -> 180709365 | L24: =E24+X24 -> 7679226.6 | M24: =L24/J24*100 -> 102.60358 | N24: =G24+Y24 -> 7224348 | O24: =L24/N24*100 -> 106.29647 | R24: 공급량
R27: 2.판매금액(단위:백만원)
A28: 2.판매금액 | P28: 단위 : 백만원 | V28: 전월기준 누계값으로 작성
A29: 구 분 | C29: 당 월 | J29: 누 계 | R29: 구분 | T29: 구성비 | V29: 판매금액(누계)
C30: 계획 | D30: 실적 | E30: 대비 (%) | F30: 전년 | G30: 대비 (%) | H30: 구성비 (%) | J30: 계획 | K30: 실적 | L30: 대비 (%) | M30: 전년 | N30: 대비 (%) | O30: 구성비 (%) | T30: 당월 | U30: 누계 | V30: 계획 | W30: 실적 | X30: 전년누계
A31: 주 택 용 | B31: 취사용 | C31: 727652.9 | D31: =ROUND((매출액표!G23+매출액표!H23)/1000,0) -> 576888 | F31: 606619 | H31: =IF(D31=MAX($D$31:$D$34,$D$36:$D$45),MAX($T$31:$T$45)+(100-SUM($T$31:$T$45)),T31) -> 0.4 | J31: =C31+V31 -> 727652.9 | K31: =D31+W31 -> 576888 | M31: =X31+F31-1 -> 606618 | O31: =IF(K31=MAX($K$31:$K$34,$K$36:$K$45),MAX($U$31:$U$45)+(100-SUM($U$31:$U$45)),U31) -> 0.4 | R31: 가정용 | S31: 취사용 | T31: =ROUND(D31/$D$47*100,1) -> 0.4 | U31: =ROUND(K31/$K$47*100,1) -> 0.4
B32: 개별난방용 | C32: 1.0046292e+08 | D32: =ROUND((매출액표!G31+매출액표!H31+매출액표!G36+매출액표!H36)/1000,0) -> 101088740 | F32: 100657183 | H32: =IF(D32=MAX($D$31:$D$34,$D$36:$D$45),MAX($T$31:$T$45)+(100-SUM($T$31:$T$45)),T32) -> 70.7 | J32: =C32+V32 -> 1.0046292e+08 | K32: =D32+W32 -> 101088740 | M32: =X32+F32 -> 100657183 | O32: =IF(K32=MAX($K$31:$K$34,$K$36:$K$45),MAX($U$31:$U$45)+(100-SUM($U$31:$U$45)),U32) -> 70.7 | S32: 개별난방용 | T32: =ROUND(D32/$D$47*100,1) -> 70.6 | U32: =ROUND(K32/$K$47*100,1) -> 70.6
B33: 중앙난방용 | C33: 2221997 | D33: =ROUND((매출액표!G40+매출액표!H40)/1000,0) -> 1981558 | F33: 2252405.5 | H33: =IF(D33=MAX($D$31:$D$34,$D$36:$D$45),MAX($T$31:$T$45)+(100-SUM($T$31:$T$45)),T33) -> 1.4 | J33: =C33+V33 -> 2221997 | K33: =D33+W33 -> 1981558 | M33: =X33+F33 -> 2252405.5 | O33: =IF(K33=MAX($K$31:$K$34,$K$36:$K$45),MAX($U$31:$U$45)+(100-SUM($U$31:$U$45)),U33) -> 1.4 | S33: 중앙난방용 | T33: =ROUND(D33/$D$47*100,1) -> 1.4 | U33: =ROUND(K33/$K$47*100,1) -> 1.4
B34: 자가열전용 | C34: 1785361 | D34: =ROUND((매출액표!G44+매출액표!H44)/1000,0) -> 1758304 | F34: 1680631.2 | H34: =IF(D34=MAX($D$31:$D$34,$D$36:$D$45),MAX($T$31:$T$45)+(100-SUM($T$31:$T$45)),T34) -> 1.2 | J34: =C34+V34 -> 1785361 | K34: =D34+W34 -> 1758304 | M34: =X34+F34 -> 1680631.2 | O34: =IF(K34=MAX($K$31:$K$34,$K$36:$K$45),MAX($U$31:$U$45)+(100-SUM($U$31:$U$45)),U34) -> 1.2 | S34: 자가열전용 | T34: =ROUND(D34/$D$47*100,1) -> 1.2 | U34: =ROUND(K34/$K$47*100,1) -> 1.2
B35: 소 계 | C35: =SUM(C31:C34) -> 105197934 | D35: =SUM(D31:D34) -> 105405490 | E35: =D35/C35*100 -> 100.1973 | F35: =SUM(F31:F34) -> 1.0519684e+08 | G35: =D35/F35*100 -> 100.19834 | H35: =SUM(H31:I34) -> 73.7 | J35: =C35+V35 -> 105197934 | K35: =SUM(K31:K34) -> 105405490 | L35: =K35/J35*100 -> 100.1973 | M35: =SUM(M31:M34) -> 1.0519684e+08 | N35: =K35/M35*100 -> 100.19834 | O35: =SUM(O31:P34) -> 73.7 | S35: 소계 | V35: =SUM(V31:V34) -> 0 | W35: =SUM(W31:W34) -> 0 | X35: =SUM(X31:X34) -> 0
A36: 일반용 | C36: 9012204 | D36: =ROUNDDOWN((매출액표!G50+매출액표!G55)/1000,-3) -> 8832000 | F36: 8779204.9 | H36: =IF(D36=MAX($D$31:$D$34,$D$36:$D$45),MAX($T$31:$T$45)+(100-SUM($T$31:$T$45)),T36) -> 6.2 | J36: =C36+V36 -> 9012204 | K36: =D36+W36 -> 8832000 | M36: =X36+F36 -> 8779204.9 | O36: =IF(K36=MAX($K$31:$K$34,$K$36:$K$45),MAX($U$31:$U$45)+(100-SUM($U$31:$U$45)),U36) -> 6.2 | R36: 일반용 | T36: =ROUND(D36/$D$47*100,1) -> 6.2 | U36: =ROUND(K36/$K$47*100,1) -> 6.2
A37: 업무난방용 | C37: 2873289 | D37: =ROUND((매출액표!G65+매출액표!H65)/1000,0) -> 2849662 | F37: 3359604.2 | H37: =IF(D37=MAX($D$31:$D$34,$D$36:$D$45),MAX($T$31:$T$45)+(100-SUM($T$31:$T$45)),T37) -> 2 | J37: =C37+V37 -> 2873289 | K37: =D37+W37 -> 2849662 | M37: =X37+F37 -> 3359604.2 | O37: =IF(K37=MAX($K$31:$K$34,$K$36:$K$45),MAX($U$31:$U$45)+(100-SUM($U$31:$U$45)),U37) -> 2 | R37: 업무난방용 | T37: =ROUND(D37/$D$47*100,1) -> 2 | U37: =ROUND(K37/$K$47*100,1) -> 2
A38: 냉방용 | C38: 3335351 | D38: =ROUND((매출액표!G73+매출액표!H73)/1000,0) -> 3503212 | F38: 4230334.6 | H38: =IF(D38=MAX($D$31:$D$34,$D$36:$D$45),MAX($T$31:$T$45)+(100-SUM($T$31:$T$45)),T38) -> 2.4 | J38: =C38+V38 -> 3335351 | K38: =D38+W38 -> 3503212 | M38: =X38+F38 -> 4230334.6 | O38: =IF(K38=MAX($K$31:$K$34,$K$36:$K$45),MAX($U$31:$U$45)+(100-SUM($U$31:$U$45)),U38) -> 2.4 | R38: 냉방용 | T38: =ROUND(D38/$D$47*100,1) -> 2.4 | U38: =ROUND(K38/$K$47*100,1) -> 2.4
A39: 산업용 | C39: 15942394 | D39: =ROUND((매출액표!G77+매출액표!H77)/1000,0) -> 15937847 | F39: 18979153 | H39: =IF(D39=MAX($D$31:$D$34,$D$36:$D$45),MAX($T$31:$T$45)+(100-SUM($T$31:$T$45)),T39) -> 11.1 | J39: =C39+V39 -> 15942394 | K39: =D39+W39 -> 15937847 | M39: =X39+F39+1 -> 18979154 | O39: =IF(K39=MAX($K$31:$K$34,$K$36:$K$45),MAX($U$31:$U$45)+(100-SUM($U$31:$U$45)),U39) -> 11.1 | R39: 산업용 | T39: =ROUND(D39/$D$47*100,1) -> 11.1 | U39: =ROUND(K39/$K$47*100,1) -> 11.1
A40: 수송용(CNG) | C40: 4725959 | D40: =ROUND((매출액표!G57+매출액표!G59)/1000,0) -> 5276792 | F40: 5935667.8 | H40: =IF(D40=MAX($D$31:$D$34,$D$36:$D$45),MAX($T$31:$T$45)+(100-SUM($T$31:$T$45)),T40) -> 3.7 | J40: =C40+V40 -> 4725959 | K40: =D40+W40 -> 5276792 | M40: =X40+F40 -> 5935667.8 | O40: =IF(K40=MAX($K$31:$K$34,$K$36:$K$45),MAX($U$31:$U$45)+(100-SUM($U$31:$U$45)),U40) -> 3.7 | R40: 수송용(CNG) | T40: =ROUND(D40/$D$47*100,1) -> 3.7 | U40: =ROUND(K40/$K$47*100,1) -> 3.7
A41: 수송용(BIO) | C41: 228320 | D41: =ROUND(매출액표!G58/1000,0) -> 258302 | F41: 275762 | H41: =IF(D41=MAX($D$31:$D$34,$D$36:$D$45),MAX($T$31:$T$45)+(100-SUM($T$31:$T$45)),T41) -> 0.2 | J41: =C41+V41 -> 228320 | K41: =D41+W41 -> 258302 | M41: =X41+F41 -> 275762 | O41: =IF(K41=MAX($K$31:$K$34,$K$36:$K$45),MAX($U$31:$U$45)+(100-SUM($U$31:$U$45)),U41) -> 0.2 | R41: 수송용(BIO) | T41: =ROUND(D41/$D$47*100,1) -> 0.2 | U41: =ROUND(K41/$K$47*100,1) -> 0.2
A42: 열병합용 | C42: 459403 | D42: =ROUND((매출액표!G82)/1000,0) -> 499275 | F42: 605948.68 | H42: =IF(D42=MAX($D$31:$D$34,$D$36:$D$45),MAX($T$31:$T$45)+(100-SUM($T$31:$T$45)),T42) -> 0.3 | J42: =C42+V42 -> 459403 | K42: =D42+W42 -> 499275 | M42: =X42+F42 -> 605948.68 | O42: =IF(K42=MAX($K$31:$K$34,$K$36:$K$45),MAX($U$31:$U$45)+(100-SUM($U$31:$U$45)),U42) -> 0.3 | R42: 열병합용 | T42: =ROUND(D42/$D$47*100,1) -> 0.3 | U42: =ROUND(K42/$K$47*100,1) -> 0.3
A43: 연료전지용 | C43: 276692 | D43: =ROUND((매출액표!G87+매출액표!H87)/1000,0) -> 257115 | F43: 391774.41 | H43: =IF(D43=MAX($D$31:$D$34,$D$36:$D$45),MAX($T$31:$T$45)+(100-SUM($T$31:$T$45)),T43) -> 0.2 | J43: =C43+V43 -> 276692 | K43: =D43+W43 -> 257115 | M43: =X43+F43 -> 391774.41 | O43: =IF(K43=MAX($K$31:$K$34,$K$36:$K$45),MAX($U$31:$U$45)+(100-SUM($U$31:$U$45)),U43) -> 0.2 | R43: 연료전지용 | T43: =ROUND(D43/$D$47*100,1) -> 0.2 | U43: =ROUND(K43/$K$47*100,1) -> 0.2
A44: 열전용설비용 | C44: 16663 | D44: =ROUND((매출액표!G89+매출액표!H89)/1000,0) -> 25402 | F44: 20580.559 | H44: =IF(D44=MAX($D$31:$D$34,$D$36:$D$45),MAX($T$31:$T$45)+(100-SUM($T$31:$T$45)),T44) -> 0 | J44: =C44+V44 -> 16663 | K44: =D44+W44 -> 25402 | M44: =X44+F44 -> 20580.559 | O44: =IF(K44=MAX($K$31:$K$34,$K$36:$K$45),MAX($U$31:$U$45)+(100-SUM($U$31:$U$45)),U44) -> 0 | R44: 열전용설비용 | T44: =ROUND(D44/$D$47*100,1) -> 0 | U44: =ROUND(K44/$K$47*100,1) -> 0
...

Sheet 매출액표
A4: =LEFT(총괄표!A2,9)&" 매출액집계표" -> 2026년 1월 매출액집계표
A7: 구분 | B7: 적 요 | D7: 도시가스 | H7: 기본료 | I7: 계량기관리비 | J7: 보정기관리비 | K7: 가스부가세 | L7: 계량기부가세 | M7: 보정기부가세 | N7: 합계
D8: 수량(㎥) | E8: 수량(MJ) | F8: 단가 | G8: 공급가액
B9: 전월재고 | D9: 118651168 | E9: 5048844519
A10: 공 | B10: 당월생산(LNG)(+) | D10: 1.8070323e+08 | E10: 7679047435
B11: 자가소모(LNG)(-) | D11: =ROUND(-자가소모!D12-D12,4) -> -13364.88 | E11: =ROUND(-자가소모!E12-E12,4) -> -567806.93
B12: 타계정대체(-) | D12: =ROUND(-SUM(자가소모!D6:D7),4) -> -255836 | E12: =ROUND(-SUM(자가소모!E6:E7),4) -> -10869192
B13: 계 | D13: =D9+D10+D12+D11 -> 2.990852e+08 | E13: =E9+E10+E11+E12 -> 1.2716455e+10
B14: 전월재고 | D14: 0 | E14: 0
A15: 급 | B15: 당월생산(BIO)(+) | D15: 283432 | E15: 11966037
B16: 자가소모(BIO)(-)
B17: 계 | D17: =D14+D15+D16 -> 283432 | E17: =E14+E15+E16 -> 11966037
B18: 주 택 용 | C18: 취사용 변동전 | D18: 33.5444 | E18: 1431.616 | F18: =G18/E18 -> 23.476386 | G18: 33609.17 | H18: 15800 | I18: 840 | N18: =SUM(G18:M18) -> 50249.17
C19: 취사용 변동후 | D19: 502004.67 | E19: 21357246 | F19: =G19/E19 -> 23.634805 | G19: 5.0477435e+08 | H19: 88176990 | I19: 10090380 | N19: =SUM(G19:M19) -> 6.0304172e+08
C20: 사회복지시설할인액 | G20: -86979 | N20: =SUM(G20:M20) -> -86979
C21: 사회적배려 할인액 | G21: -13135380 | N21: =SUM(G21:M21) -> -13135380
C22: 검침착오분조정 | D22: -2877.8136 | E22: -122602.62 | G22: -2890663 | N22: =SUM(G22:M22) -> -2890663
C23: 소계 | D23: =SUM(D18:D22) -> 499160.4 | E23: =SUM(E18:E22) -> 21236075 | F23: =G23/E23 -> 23.012489 | G23: =SUM(G18:G22) -> 488694933 | H23: =SUM(H18:H22) -> 88192790 | I23: =SUM(I18:I22) -> 10091220 | J23: =SUM(J18:J22) -> 0 | K23: =SUM(K18:K22) -> 0 | L23: =SUM(L18:L22) -> 0 | M23: 0 | N23: =SUM(N18:N22) -> 5.8697894e+08
C24: 취사난방용(취사)변동전 | D24: 107.4249 | E24: 4582.5235 | F24: =G24/E24 -> 23.409351 | G24: 107273.9 | H24: 26100 | I24: 1100 | N24: =SUM(G24:M24) -> 134473.9
C25: 취사난방용(취사)변동후 | D25: 4924078.4 | E25: 2.0945241e+08 | F25: =G25/E25 -> 23.636044 | G25: 4.9506265e+09 | H25: 378297900 | I25: 30667410 | N25: =SUM(G25:M25) -> 5.3595918e+09
C26: 취사난방용(난방)변동전 | D26: 311.6689 | E26: 13292.675 | F26: =G26/E26 -> 23.504993 | G26: 312444.22 | N26: =SUM(G26:M26) -> 312444.22
C27: 취사난방용(난방)변동후 | D27: 42928622 | E27: 1.826009e+09 | F27: =G27/E27 -> 23.635991 | G27: 4.3159533e+10 | N27: =SUM(G27:M27) -> 4.3159533e+10
C28: 사회복지시설할인액 | G28: -16720993 | N28: =SUM(G28:M28) -> -16720993
C29: 사회적배려 할인액 | G29: -9232982474 | N29: =SUM(G29:M29) -> -9232982474
C30: 검침착오분조정 | D30: -31977.31 | E30: -1361726.4 | G30: -32154058 | N30: =SUM(G30:M30) -> -32154058
A31: 검 | C31: 소계 | D31: =SUM(D24:D30) -> 47821142 | E31: =SUM(E24:E30) -> 2.0341176e+09 | F31: =G31/E31 -> 19.08873 | G31: =SUM(G24:G30) -> 38828722123 | H31: =SUM(H24:H30) -> 378324000 | I31: =SUM(I24:I30) -> 30668510 | J31: =SUM(J24:J30) -> 0 | K31: =SUM(K24:K30) -> 0 | L31: =SUM(L24:L30) -> 0 | M31: =SUM(M24:M30) -> 0 | N31: =SUM(N24:N30) -> 39237714633
C32: 개별난방용 변동전 | D32: 316.2218 | E32: 13488.848 | F32: =G32/E32 -> 23.412162 | G32: 315803.1 | H32: 18000 | I32: 0 | N32: =SUM(G32:M32) -> 333803.1
C33: 개별난방용 변동후 | D33: 60986149 | E33: 2.5940953e+09 | F33: =G33/E33 -> 23.635974 | G33: 6.1313967e+10 | H33: 599688000 | I33: 143228970 | N33: =SUM(G33:M33) -> 6.2056884e+10
C34: 사회복지시설할인액 | G34: -6137309 | N34: =SUM(G34:M34) -> -6137309
C35: 검침착오분조정 | D35: -26021.891 | E35: -1107961.2 | G35: -26157500 | N35: =SUM(G35:M35) -> -26157500
C36: 소계 | D36: =SUM(D32:D35) -> 60960443 | E36: =SUM(E32:E35) -> 2.5930008e+09 | F36: =G36/E36 -> 23.633617 | G36: =SUM(G32:G35) -> 61281988231 | H36: =SUM(H32:H35) -> 599706000 | I36: =SUM(I32:I35) -> 143228970 | J36: 0 | K36: =SUM(K32:K35) -> 0 | L36: =SUM(L32:L35) -> 0 | M36: 0 | N36: =SUM(N32:N35) -> 62024923201
C37: 중앙난방용(중앙난방) | D37: 2179930.2 | E37: 92607647 | F37: =G37/E37 -> 23.598099 | G37: 2185364454 | I37: 1772750 | J37: 960800 | N37: =L37+K37+I37+H37+G37+J37 -> 2188098004
C38: 냉난방용(주택)(중앙난방) | D38: 79844.281 | E38: 3391273.3 | F38: =G38/E38 -> 23.598096 | G38: 80027594 | I38: 270690 | J38: 98200 | N38: =L38+K38+I38+H38+G38+J38 -> 80396484
C39: 사회적배려 할인액 | G39: -283833649 | N39: =SUM(G39:M39) -> -283833649
C40: 소계 | D40: =SUM(D37:D39) -> 2259774.4 | E40: =SUM(E37:E39) -> 95998920 | F40: =G40/E40 -> 20.641466 | G40: =SUM(G37:G39) -> 1981558399 | H40: =SUM(H39:H39) -> 0 | I40: =SUM(I37:I39) -> 2043440 | J40: =SUM(J37:J39) -> 1059000 | K40: =SUM(K37:K39) -> 0 | L40: =SUM(L37:L39) -> 0 | M40: 0 | N40: =SUM(N37:N39) -> 1984660839
C41: 자가열전용 | D41: 1798021 | E41: 76391353 | F41: =G41/E41 -> 23.5981 | G41: 1802690781 | I41: 712570 | J41: 735000 | N41: =SUM(G41:M41) -> 1804138351
C42: 자가열전용 변동후 | N42: =SUM(G42:M42) -> 0
C43: 사회적배려 할인액 | G43: -44386915 | N43: =SUM(G43:M43) -> -44386915
C44: 소계 | D44: =SUM(D41:D43) -> 1798021 | E44: =SUM(E41:E43) -> 76391353 | F44: =G44/E44 -> 23.017054 | G44: =SUM(G41:G43) -> 1758303866 | H44: =SUM(H41:H43) -> 0 | I44: =SUM(I41:I43) -> 712570 | J44: =SUM(J41:J43) -> 735000 | K44: =SUM(K41:K43) -> 0 | L44: =SUM(L41:L43) -> 0 | M44: 0 | N44: =SUM(N41:N43) -> 1759751436
C45: 계 | D45: =D23+D31+D36+D44+D40 -> 1.1333854e+08 | E45: =E23+E31+E36+E44+E40 -> 4.8207447e+09 | F45: =G45/E45 -> 21.643807 | G45: =G23+G31+G36+G44+G40 -> 104339267552 | H45: =H23+H31+H36+H44+H40 -> 1066222790 | I45: =I23+I31+I36+I44+I40 -> 186744710 | J45: =J23+J31+J36+J44+J40 -> 1794000 | K45: =K23+K31+K36+K44+K40 -> 0 | L45: =L23+L31+L36+L44+L40 -> 0 | M45: 0 | N45: =N23+N31+N36+N44+N40 -> 105594029052
...

Sheet 가스공사용(MJ)
B1: ="한국가스공사 제출용 구성비 ("&LEFT(총괄표!A2,9)&")" -> 한국가스공사 제출용 구성비 (2026년 1월 ) | S1: ※ 사회복지시설 정산('23.04.) 물량에서 3월 실사용분 제외 ※ 1. 복지시설에 대한 소급 정산(일반용 단가 적용) 소급 정산: '23.02. 완료 2. 소급대상청구년월: '22.12. ~ '23.01. - 참고사항: 청구월 기준 12월 물량 소급정산하는 대신 3월분 제외하기로 함 (4월 매출에 포함된 물량 일부 제외) ==> 신재홍 차장 (가스공사 전 담당자)와 사회복지시설 한시적할인 정산은 3월까지 하기로 함 ==> 김광연 주임 (가스공사 현 담당자)과도 해당 내용 확인 완료됨
B3: 구 분 | E3: 판 매 량 | F3: 개별소비세 | G3: 사회복지 | H3: 사회적배려 | I3: 차상위할인 | J3: 다자녀할인 | K3: 자가소모 | L3: 판 매 량 계 | M3: 구성비 | Q3: 자가소모
E4: (MJ) | F4: (MJ) | G4: (MJ) | H4: (MJ) | I4: (MJ) | J4: (MJ) | K4: (MJ) | L4: (MJ) | M4: (%) | Q4: (MJ)
B5: 주택용 | C5: 취사용 | E5: =ROUND((매출액표!E23-G5-H5-I5),0) -> 21221782 | G5: =ROUNDDOWN(('사회복지시설(MJ)'!D7),0) -> 14293 | L5: =ROUND((E5+G5+K5),0) -> 21236075 | M5: =ROUND(L5/$L$21*100,4) -> 0.3161
C6: 개별난방용 | E6: =ROUND((매출액표!E31+매출액표!E36-G6-H6-I6),0)-1 -> 4623294076 | G6: =ROUNDDOWN(('사회복지시설(MJ)'!D10),0) -> 3824324 | L6: =ROUND((E6+G6+K6),0)+1 -> 4627118401 | M6: =ROUND(L6/$L$21*100,4) -> 68.8698 | T6: ※ 판매량+(개별소비세+사회복지+사회적배려+차상위할인)=매출액표 수량합계(자가소모포함되어있으므로 제외됨)
C7: 중앙난방용 | E7: =ROUND((매출액표!E40-G7-H7-I7),0) -> 95998920 | L7: =ROUND((E7+G7+K7),0) -> 95998920 | M7: =ROUND(L7/$L$21*100,4)-0.0002 -> 1.4286 | T7: ※ 업무난방과 냉방용은 구별요(5월~9월 냉방용적용)
C8: 자가열전용 | E8: =ROUND((매출액표!E44-G8-H8-I8),0) -> 76391353 | L8: =ROUND((E8+G8+K8),0) -> 76391353 | M8: =ROUND(L8/$L$21*100,4) -> 1.137 | T8: ※ 매출내역서의 자가소모를 확인한다
C9: 소 계 | E9: =SUM(E5:E8) -> 4816906131 | F9: =SUM(F5:F8) -> 0 | G9: =SUM(G5:G8) -> 3838617 | H9: =SUM(H5:H8) -> 0 | I9: =SUM(I5:I8) -> 0 | J9: =SUM(J5:J8) -> 0 | L9: =SUM(L5:L8) -> 4820744749 | M9: =SUM(M5:M8) -> 71.7515 | Q9: =SUM(Q5:Q8) -> 0 | T9: ※ 개별소비세=특소세할인, 2022년 5월부터 판매량(MJ)에 포함 (가스공사 신재홍차장 확인 시, 구성비 공문으로 개소세 관련내용 확인사항 없음)
B10: 일반용 | C10: 일반용1 | E10: =ROUND((매출액표!E50-G10),0) -> 234095235 | G10: =ROUND(('사회복지시설(MJ)'!D21),0) -> 6899559 | K10: =ROUND(Q10,0) -> 22135 | L10: =ROUND((E10+F10+G10+K10+H10),0) -> 241016929 | M10: =ROUND(L10/$L$21*100,4) -> 3.5873 | Q10: =Q12 -> 22134.685
C11: 일반용2 | E11: =ROUND((매출액표!E55-G11),0) -> 148193094 | L11: =ROUND((E11+F11+G11+K11+H11),0) -> 148193094 | M11: =ROUND(L11/$L$21*100,4) -> 2.2057 | Q11: 0
B12: 일 반 용 | E12: =SUM(E10:E11) -> 382288329 | G12: ='사회복지시설(MJ)'!D21 -> 6899558.6 | H12: =SUM(H10:H11) -> 0 | I12: =SUM(I10:I11) -> 0 | K12: =SUM(K10:K11) -> 22135 | L12: =SUM(E12:K12) -> 3.8921002e+08 | M12: =SUM(M10:M11) -> 5.793 | Q12: =자가소모!E4 -> 22134.685
B13: 냉난방공조용 | E13: =ROUND((매출액표!E73-G13),0) -> 158441421 | G13: =('사회복지시설(MJ)'!D17) -> 2471007.1 | K13: =ROUND(Q13,0) -> 544913 | L13: =ROUND((E13+G13+K13),0) -> 161457341 | M13: =ROUND(L13/$L$21*100,4) -> 2.4031 | Q13: =자가소모!E5 -> 544912.61
B14: 업무난방용 | E14: =ROUND((매출액표!E65-G14),0) -> 104550840 | G14: =('사회복지시설(MJ)'!D14) -> 28584833 | K14: =ROUNDDOWN(Q14,0) -> 759 | L14: =ROUND((E14+G14+K14),0) -> 133136432 | M14: =ROUND(L14/$L$21*100,4) -> 1.9816 | Q14: =자가소모!E3+자가소모!E8+자가소모!E9 -> 759.6318
B15: 산 업 용 | E15: =ROUND((매출액표!E77-G15),0) -> 891074758 | K15: =ROUND(Q15,0) -> 0 | L15: =ROUND((E15+G15+K15),0) -> 891074758 | M15: =ROUND(L15/$L$21*100,4) -> 13.2627
B16: 수 송 용 | E16: =ROUND(((매출액표!E57+매출액표!E59)-G16),0) -> 255559765 | K16: =ROUND(Q16,0) -> 0 | L16: =ROUND((E16+G16+K16),0) -> 255559765 | M16: =ROUND(L16/$L$21*100,4) -> 3.8037
B17: 열 병 합 용 | E17: =ROUND((매출액표!E82-G17),0) -> 26951288 | K17: =ROUND(Q17,0) -> 0 | L17: =ROUND((E17+G17+K17),0) -> 26951288 | M17: =ROUND(L17/$L$21*100,4) -> 0.4011 | Q17: =자가소모!E7 -> 0
B18: 연료전지용 | E18: =ROUND((매출액표!E87-G18),0) -> 17038717 | K18: =ROUND(Q18,0) -> 0 | L18: =ROUND((E18+G18+K18),0) -> 17038717 | M18: =ROUND(L18/$L$21*100,4) -> 0.2536
B19: 열전용설비용 | E19: =ROUND((매출액표!E89-G19),0) -> 1180658 | K19: =ROUND(Q19,0) -> 10869192 | L19: =ROUND((E19+G19+K19),0) -> 12049850 | M19: =ROUND(L19/$L$21*100,4) -> 0.1793 | Q19: =자가소모!E6 -> 10869192
B20: 주한미군 | E20: =ROUND((매출액표!E92-G20),0) -> 11421045 | K20: =ROUND(Q20,0) -> 0 | L20: =ROUND((E20+G20+K20),0) -> 11421045 | M20: =ROUND(L20/$L$21*100,4) -> 0.17
B21: 합 계 | E21: =SUM(E13:E20)+E12+E9 -> 6665412952 | F21: =F20+F17+F16+F15+F13+F12+F9+F14 -> 0 | G21: =ROUNDUP((G20+G17+G16+G15+G13+G12+G9+G14),0) -> 41794017 | H21: =H20+H17+H16+H15+H13+H12+H9+H14 -> 0 | I21: =I20+I17+I16+I15+I13+I12+I9+I14 -> 0 | J21: =J20+J19+J17+J16+J15+J14+J13+J12+J9 -> 0 | K21: =K20+K17+K16+K15+K13+K12+K9+K14+K19 -> 11436999 | L21: =ROUND((SUM(L13:L20)+L12+L9),0) -> 6718643968 | M21: =SUM(M5:M8,M12:M20) -> 99.9996 | Q21: =Q20+Q17+Q16+Q15+Q13+Q12+Q9+Q14+Q19 -> 11436999
E24: =ROUND(E21+G21,0) -> 6707206969 | K24: =ROUNDDOWN(Q21,0)=K21 -> TRUE | L24: =ROUND(L21-K21,0) -> 6707206969
E25: =ROUND(SUMIFS(매출액표!E:E,매출액표!$B:$B,"합계")-SUMIFS(매출액표!E:E,매출액표!$C:$C,"수송용(BIO)"),0) -> 6707206969 | L25: =ROUND(매출액표!E93-매출액표!E58,0) -> 6707206969
E26: =E24-E25 -> 0 | L26: =L24-L25 -> 0
B64: 구분 | E64: 판매열량(MJ) | H64: 5147 | I64: 4602
B65: 냉방물량(9월) | K65: ※ 관리납기와 일반납기의판매량전산실의뢰 (일반납기 청구작업이후)
B66: (월초) | C66: 관리납기(변동) | K66: - 9월판매실적 작성을 위한 냉방용 상품에대한 변동검침사용량 자료 요청
B67: (청구일) | C67: 일반납기(일수)
B68: 계 | K68: ※ 계절이 바뀌는 4월(기타)↔5월(하절기) 냉방집계 조정
K69: - 시기: 2022년 4월 매출분부터
K70: - 사유: 기존 9월, 10월만 물량조정했으나 가스공사 이의제기로 4월, 5월도 시행하게 됨
K71: - 방법: 5월 일반납기 청구작업 후 냉난방물량(업무, 주택) 일반납기(4/30까지 일할계산), 관리납기(변동검침 4/30까지) ==> 냉난방공조용에 4월 기타월 사용분 추가(+) , 5월 차감 (-)
K74: ※ 9월 판매량에 냉방용을 추가청구하여 10월 판매량에서 차감함
K75: ※ 매출건
K76: - 9월매출은일반납기의 경우 (8/1~8 부터9/1~8사용량)이므로 9월사용분(10월 청구분) 포함
K77: - 관리납기는 (8/16~9/16)까지이나 관리납기는 10월에 변동검침을 했으므로, 9/16~10초까지 변동검침 물량 포함
K79: ※ 사 유 : 냉난방의 경우 10월 하절기ㅡ> 기타 단가로 변동됨에 따라 도매요금인상이 많이 이루어지므로 보전차원에서 9월 정산
K80: [5월의 경우 (기타 ㅡ> 하절기 단가 변동)는 회사 손해가 없으므로 물량정산 안함.]
K82: ※ 9월 냉방용집계확인 할 것
K83: - 냉방용 (+), 10월매출(-) 변동검침확인할 것
K84: - 10/14청구작업후 자료요청할것
...

Sheet 사회복지시설(MJ)
A2: ="사회복지시설 용도별 판매량 ( "&LEFT(총괄표!A2,9)&")" -> 사회복지시설 용도별 판매량 ( 2026년 1월 )
A4: 구분 | C4: 세대수 | D4: 판매량(MJ) | E4: 금액(원) | G4: 차액
E5: 미적용 | F5: 적용
A6: 주 택 용 | B6: 취사용
D7: =SUMIFS(청구할인정산관리!$D:$D,청구할인정산관리!$B:$B,"취사용") -> 14293.025 | E7: =SUMIFS(청구할인정산관리!$E:$E,청구할인정산관리!$B:$B,"취사용") -> 337805 | F7: =SUMIFS(청구할인정산관리!$G:$G,청구할인정산관리!$B:$B,"취사용") -> 250826 | G7: =E7-F7 -> 86979 | H7: =G7/E7 -> 0.25748287
B9: 개 별 난방용
D10: =SUMIFS(청구할인정산관리!$D:$D,청구할인정산관리!$B:$B,"취사난방용")+SUMIFS(청구할인정산관리!$D:$D,청구할인정산관리!$B:$B,"개별난방용") -> 3824324.2 | E10: =SUMIFS(청구할인정산관리!$E:$E,청구할인정산관리!$B:$B,"취사난방용")+SUMIFS(청구할인정산관리!$E:$E,청구할인정산관리!$B:$B,"개별난방용") -> 90391612 | F10: =SUMIFS(청구할인정산관리!$G:$G,청구할인정산관리!$B:$B,"취사난방용")+SUMIFS(청구할인정산관리!$G:$G,청구할인정산관리!$B:$B,"개별난방용") -> 67533310 | G10: =E10-F10 -> 22858302 | H10: =G10/E10 -> 0.25288079
A12: 소 계 | D12: =D10+D7 -> 3838617.2 | E12: =E10+E7 -> 90729417 | F12: =F10+F7 -> 67784136 | G12: =G10+G7 -> 22945281 | H12: =G12/E12 -> 0.25289792
A13: 업 무 용 | B13: 업 무 난방용
D14: =SUMIFS(청구할인정산관리!$D:$D,청구할인정산관리!$B:$B,"업무난방용") -> 28584833 | E14: =SUMIFS(청구할인정산관리!$E:$E,청구할인정산관리!$B:$B,"업무난방용") -> 638365093 | F14: =SUMIFS(청구할인정산관리!$G:$G,청구할인정산관리!$B:$B,"업무난방용") -> 505958169 | G14: =E14-F14 -> 132406924 | H14: =G14/E14 -> 0.20741567
B16: 냉난방용 (업무)
D17: =SUMIFS(청구할인정산관리!$D:$D,청구할인정산관리!$B:$B,"냉난방용(업무)") -> 2471007.1 | E17: =SUMIFS(청구할인정산관리!$E:$E,청구할인정산관리!$B:$B,"냉난방용(업무)") -> 53903009 | F17: =SUMIFS(청구할인정산관리!$G:$G,청구할인정산관리!$B:$B,"냉난방용(업무)") -> 44050128 | G17: =E17-F17 -> 9852881 | H17: =G17/E17 -> 0.18278907
A19: 소 계 | D19: =D14+D17 -> 31055841 | E19: =E14+E17 -> 692268102 | F19: =F14+F17 -> 550008297 | G19: =G14+G17 -> 142259805 | H19: =G19/E19 -> 0.20549814
A20: 일 반 용
D21: =SUMIFS(청구할인정산관리!$D:$D,청구할인정산관리!$B:$B,"일반용(1)")+SUMIFS(청구할인정산관리!$D:$D,청구할인정산관리!$B:$B,"일반용(2)") -> 6899558.6 | E21: =SUMIFS(청구할인정산관리!$E:$E,청구할인정산관리!$B:$B,"일반용(1)")+SUMIFS(청구할인정산관리!$E:$E,청구할인정산관리!$B:$B,"일반용(2)") -> 157199794 | F21: =SUMIFS(청구할인정산관리!$G:$G,청구할인정산관리!$B:$B,"일반용(1)")+SUMIFS(청구할인정산관리!$G:$G,청구할인정산관리!$B:$B,"일반용(2)") -> 122502744 | G21: =E21-F21 -> 34697050
A23: 소 계 | D23: =SUM(D20:D22) -> 6899558.6 | E23: =SUM(E20:E22) -> 157199794 | F23: =SUM(F20:F22) -> 122502744 | G23: =SUM(G20:G22) -> 34697050
A24: 연료전지용
G25: =E25-F25 -> 0
A27: 소 계 | D27: =SUM(D24:D26) -> 0 | E27: =SUM(E24:E26) -> 0 | F27: =SUM(F24:F26) -> 0 | G27: =SUM(G24:G26) -> 0
A28: 합 계 | D28: =D23+D12+D19+D27 -> 41794016 | E28: =E23+E12+E19+E27 -> 940197313 | F28: =F23+F12+F19+F27 -> 740295177 | G28: =G23+G12+G19+G27 -> 199902136 | H28: =G28/E28 -> 0.21261722
D39: 정산관리=>청구할인정산관리=>정산년월:마감월, 원가정산항목:사회적복지할인

Sheet 자가소모
B1: 1월
C2: 상품 | D2: 사용량(㎥) | E2: 사용열랑(MJ) | F2: 자가소모량 확인대장
B3: 자가소모 | C3: 업무난방용 | F3: 경산지사(업무난방-->냉난방용으로 상품변경)
B4: 자가소모 | C4: 일반용 | D4: 521 | E4: 22134.685 | F4: 본사 일반용
B5: 자가소모 | C5: 냉난방용 | D5: 12826 | E5: 544912.61 | F5: 본사 냉난방용+서부지사+수성안전팀
B6: 자가소모 | C6: 열전용설비용 | D6: 255836 | E6: 10869192 | F6: 1~3번 보일러 합계
B7: 자가소모 | C7: 열병합용1 | F7: 세너지 (1번 ~ 3번발전기) 계-보일러합계
B8: 자가소모 | C8: 퍼지량(CNG) | D8: 0 | E8: 0 | F8: 앞으로 없음. 다 없앰. 관리비가 더 많이 들어서?
B9: 자가소모 | C9: 퍼지량(업무난방) | D9: 17.88 | E9: 759.6318 | F9: 퍼지량 계 | G9: 총무결재본
B10: 자가소모(LNG) 소계 | D10: =SUM(D3:D9) -> 269200.88 | E10: =SUM(E3:E9) -> 11436999
B11: 자가소모 | C11: 수송용 (BIO) | D11: 0 | E11: 0
B12: 자가소모 합계 | D12: =SUM(D3:D9) -> 269200.88 | E12: =SUM(E3:E9) -> 11436999 | F12: 총계와 같아야됨
A16: .
A17: (샘플참고)
F41: 왼쪽 자동 계산 됨

Sheet 판매량-월별추이
B1: 1. 2025년 판매량 현황
AI2: (단위:천MJ)
B3: 용 도 [판매전수] | C3: 판 매 실 적 | F3: 판 매 실 적 | N3: 판 매 실 적 | Q3: 판 매 실 적 | Y3: 판 매 실 적 | AB3: 판 매 실 적
C4: 판매량 | D4: 사업계획 | F4: 사업계획 | G4: 전월누계(1~11월) | I4: 전년동월 | K4: 전년동월 | M4: 구성비 | N4: 판매량 | O4: 사업계획 | Q4: 사업계획 | R4: =MID(총괄표!A2,7,3) -> 1월 | T4: 전년동월 | V4: 전년동월 | X4: 구성비 | Y4: 판매량 | Z4: 사업계획 | AB4: 사업계획 | AC4: 누 계 | AE4: 전년동월 | AG4: 전년동월 | AI4: 구성비
D5: 차이 | E5: 사용량 | G5: 차이 | H5: 사용량 | I5: 차이 | J5: 대비(%) | K5: 차이 | L5: 사용량 | O5: 차이 | P5: 사용량 | R5: 차이 | S5: 사용량 | T5: 차이 | U5: 대비(%) | V5: 차이 | W5: 사용량 | Z5: 차이 | AA5: 사용량 | AC5: 차이 | AD5: 사용량 | AE5: 차이 | AF5: 대비(%) | AG5: 차이 | AH5: 사용량
B6: 주 택 용 | C6: =총괄표!$X$11 -> 0 | E6: =총괄표!V11 -> 0 | F6: =E6 -> 0 | H6: =C6 -> 0 | I6: =K7 -> 0 | J6: =L7 -> #DIV/0! | L6: =총괄표!Y11 -> 0 | M6: =C6/$C$18 -> #DIV/0! | N6: =총괄표!E11 -> 4820744 | P6: =총괄표!C11 -> 4809107 | Q6: =P6 -> 4809107 | R6: =O7 -> 11637 | S6: =N6 -> 4820744 | T6: =V7 -> 11188 | U6: =W7 -> 1.0023262 | W6: =총괄표!G11 -> 4809556 | X6: =총괄표!I11 -> 71.6 | Y6: =C6+N6 -> 4820744 | AA6: =E6+P6 -> 4809107 | AB6: =AA6 -> 4809107 | AC6: =Z7 -> 11637 | AD6: =Y6 -> 4820744 | AE6: =AG7 -> 11188 | AF6: =AH7 -> 1.0023262 | AH6: =L6+W6 -> 4809556 | AI6: =총괄표!P11 -> 71.6
B7: =VLOOKUP(B6,데이터!$D$33:$E$38,2,FALSE) -> 1153124 | D7: =C6-E6 -> 0 | E7: =C6/E6 -> #DIV/0! | G7: =H6-F6 -> 0 | H7: =H6/E6 -> #DIV/0! | K7: =C6-L6 -> 0 | L7: =C6/L6 -> #DIV/0! | O7: =N6-P6 -> 11637 | P7: =N6/P6 -> 1.0024198 | R7: =(S7-1) -> 0.002419784 | S7: =P7 -> 1.0024198 | T7: =U6-1 -> 0.0023262023 | V7: =N6-W6 -> 11188 | W7: =N6/W6 -> 1.0023262 | Z7: =Y6-AA6 -> 11637 | AA7: =Y6/AA6 -> 1.0024198 | AC7: =AD7-1 -> 0.002419784 | AD7: =AA7 -> 1.0024198 | AE7: =AF6-1 -> 0.0023262023 | AG7: =Y6-AH6 -> 11188 | AH7: =Y6/AH6 -> 1.0023262
B8: 일 반 용 | C8: =총괄표!$X$12 -> 0 | E8: =총괄표!V12 -> 0 | F8: =E8 -> 0 | H8: =C8 -> 0 | I8: =K9 -> 0 | J8: =L9 -> #DIV/0! | L8: =총괄표!Y12 -> 0 | M8: =C8/$C$18 -> #DIV/0! | N8: =총괄표!E12 -> 389188 | P8: =총괄표!C12 -> 395548 | Q8: =P8 -> 395548 | R8: =O9 -> -6360 | S8: =N8 -> 389188 | T8: =V9 -> 605 | U8: =W9 -> 1.0015569 | W8: =총괄표!G12 -> 388583 | X8: =총괄표!I12 -> 5.8 | Y8: =C8+N8 -> 389188 | AA8: =E8+P8 -> 395548 | AB8: =AA8 -> 395548 | AC8: =Z9 -> -6360 | AD8: =Y8 -> 389188 | AE8: =AG9 -> 605 | AF8: =AH9 -> 1.0015569 | AH8: =L8+W8 -> 388583 | AI8: =총괄표!P12 -> 5.8
B9: =VLOOKUP(B8,데이터!$D$33:$E$38,2,FALSE) -> 21407 | D9: =C8-E8 -> 0 | E9: =C8/E8 -> #DIV/0! | G9: =H8-F8 -> 0 | H9: =H8/E8 -> #DIV/0! | K9: =C8-L8 -> 0 | L9: =C8/L8 -> #DIV/0! | O9: =N8-P8 -> -6360 | P9: =N8/P8 -> 0.98392104 | R9: =S9-1 -> -0.016078959 | S9: =P9 -> 0.98392104 | T9: =U8-1 -> 0.0015569389 | V9: =N8-W8 -> 605 | W9: =N8/W8 -> 1.0015569 | Z9: =Y8-AA8 -> -6360 | AA9: =Y8/AA8 -> 0.98392104 | AC9: =AD9-1 -> -0.016078959 | AD9: =AA9 -> 0.98392104 | AE9: =AF8-1 -> 0.0015569389 | AG9: =Y8-AH8 -> 605 | AH9: =Y8/AH8 -> 1.0015569
B10: 업무냉난방용 | C10: =총괄표!$X$13+총괄표!$X$14 -> 0 | E10: =총괄표!V13+총괄표!V14 -> 0 | F10: =E10 -> 0 | H10: =C10 -> 0 | I10: =K11 -> 0 | J10: =L11 -> #DIV/0! | L10: =총괄표!Y13+총괄표!Y14 -> 0 | M10: =C10/$C$18 -> #DIV/0! | N10: =총괄표!E13+총괄표!E14 -> 294048 | P10: =총괄표!C13+총괄표!C14 -> 286935 | Q10: =P10 -> 286935 | R10: =O11 -> 7113 | S10: =N10 -> 294048 | T10: =V11 -> -4862 | U10: =W11 -> 0.98373423 | W10: =총괄표!G13+총괄표!G14 -> 298910 | X10: =SUM(총괄표!I13:I14) -> 4.4 | Y10: =C10+N10 -> 294048 | AA10: =E10+P10 -> 286935 | AB10: =AA10 -> 286935 | AC10: =Z11 -> 7113 | AD10: =Y10 -> 294048 | AE10: =AG11 -> -4862 | AF10: =AH11 -> 0.98373423 | AH10: =L10+W10 -> 298910 | AI10: =SUM(총괄표!P13:P14) -> 4.4
B11: =VLOOKUP(B10,데이터!$D$33:$E$38,2,FALSE) -> 8536 | D11: =C10-E10 -> 0 | E11: =C10/E10 -> #DIV/0! | G11: =H10-F10 -> 0 | H11: =H10/E10 -> #DIV/0! | K11: =C10-L10 -> 0 | L11: =C10/L10 -> #DIV/0! | O11: =N10-P10 -> 7113 | P11: =N10/P10 -> 1.0247896 | R11: =S11-1 -> 0.024789586 | S11: =P11 -> 1.0247896 | T11: =U10-1 -> -0.016265766 | V11: =N10-W10 -> -4862 | W11: =N10/W10 -> 0.98373423 | Z11: =Y10-AA10 -> 7113 | AA11: =Y10/AA10 -> 1.0247896 | AC11: =AD11-1 -> 0.024789586 | AD11: =AA11 -> 1.0247896 | AE11: =AF10-1 -> -0.016265766 | AG11: =Y10-AH10 -> -4862 | AH11: =Y10/AH10 -> 0.98373423
B12: 산 업 용 | C12: =총괄표!$X$15 -> 0 | E12: =총괄표!V15 -> 0 | F12: =E12 -> 0 | H12: =C12 -> 0 | I12: =K13 -> 0 | J12: =L13 -> #DIV/0! | L12: =총괄표!Y15 -> 0 | M12: =C12/$C$18 -> #DIV/0! | N12: =총괄표!E15 -> 891075 | P12: =총괄표!C15 -> 918510 | Q12: =P12 -> 918510 | R12: =O13 -> -27435 | S12: =N12 -> 891075 | T12: =V13 -> 14140 | U12: =W13 -> 1.0161243 | W12: =총괄표!G15 -> 876935 | X12: =총괄표!I15 -> 13.3 | Y12: =C12+N12 -> 891075 | AA12: =E12+P12 -> 918510 | AB12: =AA12 -> 918510 | AC12: =Z13 -> -27435 | AD12: =Y12 -> 891075 | AE12: =AG13 -> 14140 | AF12: =AH13 -> 1.0161243 | AH12: =L12+W12 -> 876935 | AI12: =총괄표!P15 -> 13.3
B13: =VLOOKUP(B12,데이터!$D$33:$E$38,2,FALSE) -> 1119 | D13: =C12-E12 -> 0 | E13: =C12/E12 -> #DIV/0! | G13: =H12-F12 -> 0 | H13: =H12/E12 -> #DIV/0! | K13: =C12-L12 -> 0 | L13: =C12/L12 -> #DIV/0! | O13: =N12-P12 -> -27435 | P13: =N12/P12 -> 0.97013097 | R13: =S13-1 -> -0.029869027 | S13: =P13 -> 0.97013097 | T13: =U12-1 -> 0.016124342 | V13: =N12-W12 -> 14140 | W13: =N12/W12 -> 1.0161243 | Z13: =Y12-AA12 -> -27435 | AA13: =Y12/AA12 -> 0.97013097 | AC13: =AD13-1 -> -0.029869027 | AD13: =AA13 -> 0.97013097 | AE13: =AF12-1 -> 0.016124342 | AG13: =Y12-AH12 -> 14140 | AH13: =Y12/AH12 -> 1.0161243
B14: 수 송 용 | C14: =총괄표!$X$16+총괄표!$X$17 -> 0 | E14: =총괄표!V16+총괄표!V17 -> 0 | F14: =E14 -> 0 | H14: =C14 -> 0 | I14: =K15 -> 0 | J14: =L15 -> #DIV/0! | L14: =총괄표!Y16+총괄표!Y17 -> 0 | M14: =C14/$C$18 -> #DIV/0! | N14: =총괄표!E16+총괄표!E17 -> 267889 | P14: =총괄표!C16+총괄표!C17 -> 244459 | Q14: =P14 -> 244459 | R14: =O15 -> 23430 | S14: =N14 -> 267889 | T14: =V15 -> 11265 | U14: =W15 -> 1.0438969 | W14: =총괄표!G16+총괄표!G17 -> 256624 | X14: =SUM(총괄표!I16:I17) -> 4 | Y14: =C14+N14 -> 267889 | AA14: =E14+P14 -> 244459 | AB14: =AA14 -> 244459 | AC14: =Z15 -> 23430 | AD14: =Y14 -> 267889 | AE14: =AG15 -> 11265 | AF14: =AH15 -> 1.0438969 | AH14: =L14+W14 -> 256624 | AI14: =SUM(총괄표!P16:P17) -> 4
B15: =VLOOKUP(B14,데이터!$D$33:$E$38,2,FALSE) -> 98 | D15: =C14-E14 -> 0 | E15: =C14/E14 -> #DIV/0! | G15: =H14-F14 -> 0 | H15: =H14/E14 -> #DIV/0! | K15: =C14-L14 -> 0 | L15: =C14/L14 -> #DIV/0! | O15: =N14-P14 -> 23430 | P15: =N14/P14 -> 1.0958443 | R15: =S15-1 -> 0.095844293 | S15: =P15 -> 1.0958443 | T15: =U14-1 -> 0.043896908 | V15: =N14-W14 -> 11265 | W15: =N14/W14 -> 1.0438969 | Z15: =Y14-AA14 -> 23430 | AA15: =Y14/AA14 -> 1.0958443 | AC15: =AD15-1 -> 0.095844293 | AD15: =AA15 -> 1.0958443 | AE15: =AF14-1 -> 0.043896908 | AG15: =Y14-AH14 -> 11265 | AH15: =Y14/AH14 -> 1.0438969
B16: 기 타 | C16: =총괄표!X18+총괄표!X19+총괄표!X20+총괄표!X21 -> 0 | E16: =총괄표!V18+총괄표!V19+총괄표!V20+총괄표!V21 -> 0 | F16: =E16 -> 0 | H16: =C16 -> 0 | I16: =K17 -> 0 | J16: =L17 -> #DIV/0! | L16: =총괄표!Y18+총괄표!Y19+총괄표!Y20+총괄표!Y21 -> 0 | M16: =C16/$C$18 -> #DIV/0! | N16: =총괄표!E18+총괄표!E19+총괄표!E20+총괄표!E21 -> 56592 | P16: =총괄표!C18+총괄표!C19+총괄표!C20+총괄표!C21 -> 57428 | Q16: =P16 -> 57428 | R16: =O17 -> -836 | S16: =N16 -> 56592 | T16: =V17 -> -1750 | U16: =W17 -> 0.97000446 | W16: =총괄표!G18+총괄표!G19+총괄표!G20+총괄표!G21 -> 58342 | X16: =SUM(총괄표!I18:I21) -> 0.9 | Y16: =C16+N16 -> 56592 | AA16: =E16+P16 -> 57428 | AB16: =AA16 -> 57428 | AC16: =Z17 -> -836 | AD16: =Y16 -> 56592 | AE16: =AG17 -> -1750 | AF16: =AH17 -> 0.97000446 | AH16: =L16+W16 -> 58342 | AI16: =SUM(총괄표!P18:P21) -> 0.9
B17: =VLOOKUP(B16,데이터!$D$33:$E$38,2,FALSE) -> 341 | D17: =C16-E16 -> 0 | E17: =C16/E16 -> #DIV/0! | G17: =H16-F16 -> 0 | H17: =H16/F16 -> #DIV/0! | K17: =C16-L16 -> 0 | L17: =C16/L16 -> #DIV/0! | O17: =N16-P16 -> -836 | P17: =N16/P16 -> 0.98544264 | R17: =S17-1 -> -0.014557359 | S17: =P17 -> 0.98544264 | T17: =U16-1 -> -0.029995544 | V17: =N16-W16 -> -1750 | W17: =N16/W16 -> 0.97000446 | Z17: =Y16-AA16 -> -836 | AA17: =Y16/AA16 -> 0.98544264 | AC17: =AD17-1 -> -0.014557359 | AD17: =AA17 -> 0.98544264 | AE17: =AF16-1 -> -0.029995544 | AG17: =Y16-AH16 -> -1750 | AH17: =Y16/AH16 -> 0.97000446
B18: 총 합 계 | C18: =SUM(C6:C17) -> 0 | E18: =E6+E8+E10+E12+E14+E16 -> 0 | F18: =SUM(F6:F17) -> 0 | H18: =H6+H8+H10+H12+H14+H16 -> 0 | I18: =K19 -> 0 | J18: =L19 -> #DIV/0! | L18: =L6+L8+L10+L12+L14+L16 -> 0 | N18: =SUM(N6:N17) -> 6719536 | P18: =P6+P8+P10+P12+P14+P16 -> 6711987 | Q18: =SUM(Q6:Q17) -> 6711987 | R18: =O19 -> 7549 | S18: =S6+'판매량-월별추이'!S8+S10+S12+S14+S16 -> 6719536 | T18: =V19 -> 30586 | U18: =W19 -> 1.0045726 | W18: =W6+W8+W10+W12+W14+W16 -> 6688950 | Y18: =SUM(Y6:Y17) -> 6719536 | AA18: =AA6+AA8+AA10+AA12+AA14+AA16 -> 6711987 | AB18: =SUM(AB6:AB17) -> 6711987 | AC18: =Z19 -> 7549 | AD18: =AD6+AD8+AD10+AD12+AD14+AD16 -> 6719536 | AE18: =AG19 -> 30586 | AF18: =AH19 -> 1.0045726 | AH18: =AH6+AH8+AH10+AH12+AH14+AH16 -> 6688950
B19: =IF(B7+B9+B11+B13+B15+B17=데이터!E39,B7+B9+B11+B13+B15+B17,"") -> 1184625 | D19: =C18-E18 -> 0 | E19: =C18/E18 -> #DIV/0! | G19: =H18-F18 -> 0 | H19: =H18/F18 -> #DIV/0! | K19: =C18-L18 -> 0 | L19: =C18/L18 -> #DIV/0! | O19: =N18-P18 -> 7549 | P19: =N18/P18 -> 1.0011247 | R19: =S19-1 -> 0.0011247042 | S19: =P19 -> 1.0011247 | T19: =U18-1 -> 0.004572616 | V19: =N18-W18 -> 30586 | W19: =N18/W18 -> 1.0045726 | Z19: =Y18-AA18 -> 7549 | AA19: =Y18/AA18 -> 1.0011247 | AC19: =AD19-1 -> 0.0011247042 | AD19: =AA19 -> 1.0011247 | AE19: =AF18-1 -> 0.004572616 | AG19: =Y18-AH18 -> 30586 | AH19: =Y18/AH18 -> 1.0045726
B21: ※ 기타 : 열병합용, 연료전지, 열전용설비(주택용외), 주한미군
B22: ※ 구성비는 판매량 정산서 기준으로 작성되었으며 한국가스공사 정산시 수송용(BIO)은 제외되고 자가소모분이 추가 됨 | AL22: =SUM(AD19) -> 1.0011247
AL23: =SUM(S19) -> 1.0011247

Sheet 판매금액-월별추이
B1: 2. 2024년 판매금액 현황
N2: (단위:백만원)
B3: 용 도 | C3: 판 매 금 액 | I3: 판 매 금 액
C4: 사업계획 | D4: ='판매량-월별추이'!R4 -> 1월 | F4: 전년동월 | H4: 구성비 | I4: 사업계획 | J4: 누 계 | L4: 전년동월 | N4: 구성비
D5: 차이 | E5: 금액 | F5: 차이 | G5: 대비(%) | J5: 차이 | K5: 금 액 | L5: 차이 | M5: 대비(%)
B6: 주 택 용 | C6: =총괄표!C35 -> 105197934 | D6: =E6-C6 -> 207556 | E6: =총괄표!D35 -> 105405490 | F6: =총괄표!D35-총괄표!F35 -> 208651.25 | G6: =E6/총괄표!F35 -> 1.0019834 | H6: =데이터!B24 -> 73.7 | I6: =총괄표!J35 -> 105197934 | J6: =K6-I6 -> 207556 | K6: =총괄표!K35 -> 105405490 | L6: =총괄표!K35-총괄표!M35 -> 208652.25 | M6: =K6/총괄표!M35 -> 1.0019834 | N6: =데이터!D24 -> 73.7
D7: =E7-1 -> 0.0019730045 | E7: =E6/C6 -> 1.001973 | F7: =G6-1 -> 0.0019834366 | J7: =K7-1 -> 0.0019730045 | K7: =K6/I6 -> 1.001973 | L7: =M6-1 -> 0.0019834461
B8: 일 반 용 | C8: =총괄표!C36 -> 9012204 | D8: =E8-C8 -> -180204 | E8: =총괄표!D36 -> 8832000 | F8: =총괄표!D36-총괄표!F36 -> 52795.138 | G8: =E8/총괄표!F36 -> 1.0060137 | H8: =데이터!B25 -> 6.2 | I8: =총괄표!J36 -> 9012204 | J8: =K8-I8 -> -180204 | K8: =총괄표!K36 -> 8832000 | L8: =총괄표!K36-총괄표!M36 -> 52795.138 | M8: =K8/총괄표!M36 -> 1.0060137 | N8: =데이터!D25 -> 6.2
D9: =E9-1 -> -0.019995553 | E9: =E8/C8 -> 0.98000445 | F9: =G8-1 -> 0.0060136583 | J9: =K9-1 -> -0.019995553 | K9: =K8/I8 -> 0.98000445 | L9: =M8-1 -> 0.0060136583
B10: 업무냉난방용 | C10: =총괄표!C37+총괄표!C38 -> 6208640 | D10: =E10-C10 -> 144234 | E10: =총괄표!D37+총괄표!D38 -> 6352874 | F10: =(총괄표!D37+총괄표!D38)-(총괄표!F37+총괄표!F38) -> -1237064.8 | G10: =E10/(총괄표!F37+총괄표!F38) -> 0.83701255 | H10: =데이터!B26 -> 4.4 | I10: =총괄표!J37+총괄표!J38 -> 6208640 | J10: =K10-I10 -> 144234 | K10: =총괄표!K37+총괄표!K38 -> 6352874 | L10: =(총괄표!K37+총괄표!K38)-(총괄표!M37+총괄표!M38) -> -1237064.8 | M10: =K10/(총괄표!M37+총괄표!M38) -> 0.83701255 | N10: =데이터!D26 -> 4.4
D11: =E11-1 -> 0.023231175 | E11: =E10/C10 -> 1.0232312 | F11: =G10-1 -> -0.16298745 | J11: =K11-1 -> 0.023231175 | K11: =K10/I10 -> 1.0232312 | L11: =M10-1 -> -0.16298745
B12: 산 업 용 | C12: =총괄표!C39 -> 15942394 | D12: =E12-C12 -> -4547 | E12: =총괄표!D39 -> 15937847 | F12: =총괄표!D39-총괄표!F39 -> -3041306.1 | G12: =E12/총괄표!F39 -> 0.83975544 | H12: =데이터!B27 -> 11.1 | I12: =총괄표!J39 -> 15942394 | J12: =K12-I12 -> -4547 | K12: =총괄표!K39 -> 15937847 | L12: =총괄표!K39-총괄표!M39 -> -3041307.1 | M12: =K12/총괄표!M39 -> 0.83975539 | N12: =데이터!D27 -> 11.1
D13: =E13-1 -> -0.00028521438 | E13: =E12/C12 -> 0.99971479 | F13: =G12-1 -> -0.16024456 | J13: =K13-1 -> -0.00028521438 | K13: =K12/I12 -> 0.99971479 | L13: =M12-1 -> -0.16024461
B14: 수 송 용 | C14: =SUM(총괄표!C40:C41) -> 4954279 | D14: =E14-C14 -> 580815 | E14: =SUM(총괄표!D40:D41) -> 5535094 | F14: =(총괄표!D40+총괄표!D41)-(총괄표!F40+총괄표!F41) -> -676335.79 | G14: =E14/(총괄표!F40+총괄표!F41) -> 0.89111431 | H14: =데이터!B28 -> 3.9 | I14: =SUM(총괄표!J40:J41) -> 4954279 | J14: =K14-I14 -> 580815 | K14: =SUM(총괄표!K40:K41) -> 5535094 | L14: =(총괄표!K40+총괄표!K41)-(총괄표!M40+총괄표!M41) -> -676335.79 | M14: =K14/(총괄표!M40+총괄표!M41) -> 0.89111431 | N14: =데이터!D28 -> 3.9
D15: =E15-1 -> 0.11723502 | E15: =E14/C14 -> 1.117235 | F15: =G14-1 -> -0.10888569 | J15: =K15-1 -> 0.11723502 | K15: =K14/I14 -> 1.117235 | L15: =M14-1 -> -0.10888569
B16: 기 타 | C16: =총괄표!C42+총괄표!C43+총괄표!C44+총괄표!C45 -> 1023780 | D16: =E16-C16 -> -2770 | E16: =총괄표!D42+총괄표!D43+총괄표!D44+총괄표!D45 -> 1021010 | F16: =(총괄표!D42+총괄표!D43+총괄표!D44+총괄표!D45)-(총괄표!F42+총괄표!F43+총괄표!F44+총괄표!F45) -> -272576.39 | G16: =E16/(총괄표!F42+총괄표!F43+총괄표!F44+총괄표!F45) -> 0.78928629 | H16: =100-SUM(H6:H15) -> 0.7 | I16: =총괄표!J42+총괄표!J43+총괄표!J44+총괄표!J45 -> 1023780 | J16: =K16-I16 -> -2770 | K16: =총괄표!K42+총괄표!K43+총괄표!K44+총괄표!K45 -> 1021010 | L16: =(총괄표!K42+총괄표!K43+총괄표!K44+총괄표!K45)-(총괄표!M42+총괄표!M43+총괄표!M44+총괄표!M45) -> -272576.39 | M16: =K16/(총괄표!M42+총괄표!M43+총괄표!M44+총괄표!M45) -> 0.78928629 | N16: =100-SUM(N6:N15) -> 0.7
D17: =E17-1 -> -0.0027056594 | E17: =E16/C16 -> 0.99729434 | F17: =G16-1 -> -0.21071371 | J17: =K17-1 -> -0.0027056594 | K17: =K16/I16 -> 0.99729434 | L17: =M16-1 -> -0.21071371
B18: 총 합 계 | C18: =SUM(C6:C17) -> 142339231 | D18: =E18-C18 -> 745084 | E18: =E6+E8+E10+E12+E14+E16 -> 143084315 | F18: =F6+F8+F10+F12+F14+F16 -> -4965836.7 | G18: =(E18/총괄표!F47) -> 0.96645842 | I18: =SUM(I6:I17) -> 142339231 | J18: =K18-I18 -> 745084 | K18: =K6+K8+K10+K12+K14+K16 -> 143084315 | L18: =L6+L8+L10+L12+L14+L16 -> -4965836.7 | M18: =(K18/총괄표!M47) -> 0.96645842
D19: =D18/C18 -> 0.0052345653 | E19: =E18/C18 -> 1.0052346 | F19: =G18-1 -> -0.033541585 | J19: =J18/I18 -> 0.0052345653 | K19: =K18/I18 -> 1.0052346 | L19: =M18-1 -> -0.033541585

Sheet 데이터
A2: 판매량
A3: ='판매량-월별추이'!R4 -> 1월 | C3: ='판매량-월별추이'!AC4 -> 누 계 | F3: 계획 | G3: 실적
A4: 계획 | B4: 실적 | C4: 계획 | D4: 실적 | E4: 당월 | F4: =A5 -> 6711987 | G4: =B5 -> 6719536
A5: =총괄표!C23 -> 6711987 | B5: =총괄표!E23 -> 6719536 | C5: =총괄표!J23 -> 6711987 | D5: =총괄표!L23 -> 6719536 | E5: 누계 | F5: =C5 -> 6711987 | G5: =D5 -> 6719536
A9: 구성비
A10: =A3 -> 1월 | B10: 구성비 | C10: =C3 -> 누 계 | D10: 구성비
A11: 주 택 용 | B11: =총괄표!I11 -> 71.6 | C11: 주 택 용 | D11: =총괄표!P11 -> 71.6
A12: 일 반 용 | B12: =총괄표!I12 -> 5.8 | C12: 일 반 용 | D12: =총괄표!P12 -> 5.8
A13: 업무냉방용 | B13: =총괄표!I13+총괄표!I14 -> 4.4 | C13: 업무냉방용 | D13: =총괄표!P13+총괄표!P14 -> 4.4
A14: 산 업 용 | B14: =총괄표!I15 -> 13.3 | C14: 산 업 용 | D14: =총괄표!P15 -> 13.3
A15: 수 송 용 | B15: =총괄표!I16+총괄표!I17 -> 4 | C15: 수 송 용 | D15: =총괄표!P16+총괄표!P17 -> 4
A16: 기 타 | B16: =총괄표!I18+총괄표!I19+총괄표!I20+총괄표!I21 -> 0.9 | C16: 기 타 | D16: =총괄표!P18+총괄표!P19+총괄표!P20+총괄표!P21 -> 0.9
A17: 판매금액
A18: =A3 -> 1월 | C18: =C3 -> 누 계 | F18: 계획 | G18: 실적
A19: 계획 | B19: 실적 | C19: 계획 | D19: 실적 | E19: 당월 | F19: =A20 -> 142339231 | G19: =B20 -> 143084315
A20: =총괄표!C47 -> 142339231 | B20: =총괄표!D47 -> 143084315 | C20: =총괄표!J47 -> 142339231 | D20: =총괄표!K47 -> 143084315 | E20: 누계 | F20: =C20 -> 142339231 | G20: =D20 -> 143084315
A22: 판매금액 구성비
A23: =A18 -> 1월 | B23: 구성비 | C23: =C18 -> 누 계 | D23: 구성비
A24: 주 택 용 | B24: =총괄표!H35 -> 73.7 | C24: 주 택 용 | D24: =총괄표!O35 -> 73.7
A25: 일 반 용 | B25: =총괄표!H36 -> 6.2 | C25: 일 반 용 | D25: =총괄표!O36 -> 6.2
A26: 업무냉방용 | B26: =총괄표!H37+총괄표!H38 -> 4.4 | C26: 업무냉방용 | D26: =총괄표!O37+총괄표!O38 -> 4.4
A27: 산 업 용 | B27: =총괄표!H39 -> 11.1 | C27: 산 업 용 | D27: =총괄표!O39 -> 11.1
A28: 수 송 용 | B28: =총괄표!H40+총괄표!H41 -> 3.9 | C28: 수 송 용 | D28: =총괄표!O40+총괄표!O41 -> 3.9
A29: 기 타 | B29: =총괄표!H42+총괄표!H43+총괄표!H44+총괄표!H45 -> 0.7 | C29: 기 타 | D29: =총괄표!O42+총괄표!O43+총괄표!O44+총괄표!O45 -> 0.7
A31: 상품별 건수 (전산요청, 파일입력 후 => 판매량월별추이 상품별 전수 입력할 것)
A32: 상품 | B32: 공급전수 | D32: 용도 | E32: 검수
A33: 취사용 | B33: 60560 | D33: 주 택 용 | E33: =SUM(B33:B35,B37,B47) -> 1153124
A34: 취사난방용 | B34: 420601 | D34: 일 반 용 | E34: =SUM(B38:B39) -> 21407
A35: 중앙난방용 | B35: 103 | D35: 업무냉난방용 | E35: =SUM(B43,B45:B46) -> 8536
A36: 주한미군 | B36: 266 | D36: 산 업 용 | E36: =SUM(B44) -> 1119
A37: 자가열전용 | B37: 26 | D37: 수 송 용 | E37: =SUM(B48:B50) -> 98
A38: 일반용(2) | B38: 1072 | D38: 기 타 | E38: =SUM(B36,B40,B41,B42) -> 341
A39: 일반용(1) | B39: 20335 | D39: 합 계 | E39: =SUM(E33:E38) -> 1184625
A40: 열전용설비용 | B40: 5
A41: 열병합용 | B41: 17
A42: 연료전지 | B42: 53
A43: 업무난방용 | B43: 7457
A44: 산업용 | B44: 1119
A45: 냉난방용(주택) | B45: 30
A46: 냉난방용(업무) | B46: 1049
...

Sheet 매출관리(월)
A2: 매 출 내 역
A4: 매출년월 : | B4: 45413 | U4: 정상매출
A5: 적용일 | B5: 매출구분 | C5: 상품 | D5: 서비스 | E5: 단가 | F5: 사용량 | G5: 사용열량 | H5: 사용료 | I5: 기본료 | J5: 관리비(계) | K5: 관리비(보) | L5: 사용료(할인전) | M5: 사회복지 | N5: 배려할인 | O5: 차상위 | P5: 다자녀 | Q5: 안전관리비 | R5: 수입부과금 | S5: 특소세 | U5: 상품 | V5: 서비스 | W5: 단가변동갯수 | X5: 변동 후 단가
A6: 43654 | B6: 정상매출 | C6: 취사난방용 | D6: 개별난방(취사) | E6: 16.9367 | F6: 0.0781 | G6: 3.3403 | H6: 56.57 | I6: 900 | L6: 56.57 | R6: 0 | U6: 취사용 | V6: 취사용 | W6: =COUNTIFS($B:$B,$U$4,$C:$C,U6) -> 3 | X6: {=MAX(IF($D:$D=V6,$A:$A))} -> 45139
A7: 44013 | B7: 정상매출 | C7: 취사난방용 | D7: 개별난방(취사) | E7: 15.1523 | F7: 2.4291 | G7: 103.8789 | H7: 1574 | I7: 900 | L7: 1574 | R7: 0 | U7: 개별난방용 | V7: 개별난방 | W7: =COUNTIFS($B:$B,$U$4,$C:$C,U7) -> 7 | X7: {=MAX(IF($D:$D=V7,$A:$A))} -> 45139
A8: 44378 | B8: 정상매출 | C8: 개별난방용 | D8: 개별난방 | E8: 15.1392 | F8: 3.8915 | G8: 166.6285 | H8: 2522.61 | I8: 1800 | L8: 2522.61 | R8: 0 | U8: 취사난방용 | V8: 개별난방 | W8: =COUNTIFS($B:$B,$U$4,$C:$C,U8) -> 13 | X8: {=MAX(IF($D:$D=V8,$A:$A))} -> 45139
A9: 44378 | B9: 정상매출 | C9: 취사난방용 | D9: 개별난방(취사) | E9: 15.1392 | F9: 2.4038 | G9: 102.7997 | H9: 1556.29 | L9: 1556.29 | R9: 0 | U9: 취사난방용 | V9: 개별난방(취사) | W9: =COUNTIFS($B:$B,$U$4,$C:$C,U9) -> 13 | X9: {=MAX(IF($D:$D=V9,$A:$A))} -> 45139
A10: 44652 | B10: 정상매출 | C10: 개별난방용 | D10: 개별난방 | E10: 15.5692 | F10: 0.7134 | G10: 30.5486 | H10: 475.6 | L10: 475.6 | R10: 0 | U10: 일반용(1) | V10: 일반용(1)(동절기) | W10: =COUNTIFS($B:$B,$U$4,$C:$C,U10) -> 3 | X10: {=MAX(IF($D:$D=V10,$A:$A))} -> 45139
A11: 44652 | B11: 정상매출 | C11: 취사난방용 | D11: 개별난방(취사) | E11: 15.5692 | F11: 0.2632 | G11: 11.2554 | H11: 175.23 | L11: 175.23 | R11: 0 | U11: 일반용(1) | V11: 일반용(1)(기타) | W11: =COUNTIFS($B:$B,$U$4,$C:$C,U11) -> 3 | X11: {=MAX(IF($D:$D=V11,$A:$A))} -> 45139 | Y11: 매출관리(월)'!$A:$A,VLOOKUP("일반용(1)(하절기)",변동후단가표,3,FALSE))+SUMIFS('매출관리(월)'!$F:$F,'매출관리(월)'!$B:$B,"정상매출",'매출관리(월)'!$C:$C,LEFT($C53,6),'매출관리(월)'!$D:$D,"XXXXXX")
A12: 44682 | B12: 정상매출 | C12: 개별난방용 | D12: 개별난방 | E12: 16.7959 | F12: 1.4506 | G12: 62.1155 | H12: 1043.27 | L12: 1043.27 | R12: 0 | U12: 일반용(1) | V12: 일반용(1)(하절기) | W12: =COUNTIFS($B:$B,$U$4,$C:$C,U12) -> 3 | X12: {=MAX(IF($D:$D=V12,$A:$A))} -> 45139
A13: 44682 | B13: 정상매출 | C13: 취사난방용 | D13: 개별난방(취사) | E13: 16.7959 | F13: 0.5352 | G13: 22.8861 | H13: 384.38 | L13: 384.38 | R13: 0 | U13: 주한미군 | V13: 주한미군 | W13: =COUNTIFS($B:$B,$U$4,$C:$C,U13) -> 1 | X13: {=MAX(IF($D:$D=V13,$A:$A))} -> 45352
A14: 44743 | B14: 정상매출 | C14: 개별난방용 | D14: 개별난방 | E14: 17.9547 | F14: 2.1878 | G14: 93.6824 | H14: 1682.03 | L14: 1682.03 | R14: 0 | U14: 업무난방용 | V14: 업무난방 | W14: =COUNTIFS($B:$B,$U$4,$C:$C,U14) -> 5 | X14: {=MAX(IF($D:$D=V14,$A:$A))} -> 45444
A15: 44743 | B15: 정상매출 | C15: 취사난방용 | D15: 개별난방(취사) | E15: 17.9547 | F15: 0.8071 | G15: 34.5167 | H15: 619.72 | L15: 619.72 | R15: 0 | U15: 중앙난방용 | V15: 중앙난방 | W15: =COUNTIFS($B:$B,$U$4,$C:$C,U15) -> 1 | X15: {=MAX(IF($D:$D=V15,$A:$A))} -> 45139
A16: 44835 | B16: 정상매출 | C16: 취사용 | D16: 취사용 | E16: 20.6547 | F16: 5.9035 | G16: 252.6116 | H16: 5217.58 | I16: 8940 | J16: 1160 | L16: 5217.58 | R16: 0 | U16: 일반용(2) | V16: 일반용(2)(동절기) | W16: =COUNTIFS($B:$B,$U$4,$C:$C,U16) -> 2 | X16: {=MAX(IF($D:$D=V16,$A:$A))} -> 0
A17: 44835 | B17: 정상매출 | C17: 개별난방용 | D17: 개별난방 | E17: 20.6547 | F17: 24.2009 | G17: 1034.3156 | H17: 21363.45 | I17: 2700 | J17: 580 | L17: 21363.45 | R17: 0 | U17: 일반용(2) | V17: 일반용(2)(기타) | W17: =COUNTIFS($B:$B,$U$4,$C:$C,U17) -> 2 | X17: {=MAX(IF($D:$D=V17,$A:$A))} -> 45139
A18: 44835 | B18: 정상매출 | C18: 취사난방용 | D18: 개별난방(취사) | E18: 20.6547 | F18: 15.146 | G18: 647.4868 | H18: 13373.59 | I18: 6300 | L18: 13373.59 | R18: 0 | U18: 일반용(2) | V18: 일반용(2)(하절기) | W18: =COUNTIFS($B:$B,$U$4,$C:$C,U18) -> 2 | X18: {=MAX(IF($D:$D=V18,$A:$A))} -> 45139
A19: 44835 | B19: 정상매출 | C19: 취사난방용 | D19: 개별난방 | E19: 20.6547 | F19: 76.333 | G19: 3264.5569 | H19: 67428.42 | L19: 67428.42 | R19: 0 | U19: 자가열전용 | V19: 자가열전용 | W19: =COUNTIFS($B:$B,$U$4,$C:$C,U19) -> 1 | X19: {=MAX(IF($D:$D=V19,$A:$A))} -> 45139
A20: 45062 | B20: 정상매출 | C20: 취사용 | D20: 취사용 | E20: 21.6991 | F20: 8.8399 | G20: 377.5479 | H20: 8192.39 | I20: 8350 | J20: 1160 | L20: 8192.39 | R20: 0 | U20: 산업용 | V20: 산업용(동절기) | W20: =COUNTIFS($B:$B,$U$4,$C:$C,U20) -> 2 | X20: {=MAX(IF($D:$D=V20,$A:$A))} -> 0
A21: 45062 | B21: 정상매출 | C21: 개별난방용 | D21: 개별난방 | E21: 21.6991 | F21: 23.0577 | G21: 985.015 | H21: 21373.9 | L21: 21373.9 | R21: 0 | U21: 산업용 | V21: 산업용(기타) | W21: =COUNTIFS($B:$B,$U$4,$C:$C,U21) -> 2 | X21: {=MAX(IF($D:$D=V21,$A:$A))} -> 45413
A22: 45062 | B22: 정상매출 | C22: 취사난방용 | D22: 개별난방(취사) | E22: 21.6991 | F22: 13.9899 | G22: 597.6859 | H22: 12969.19 | I22: 2700 | L22: 12969.19 | R22: 0 | U22: 산업용 | V22: 산업용(하절기) | W22: =COUNTIFS($B:$B,$U$4,$C:$C,U22) -> 2 | X22: {=MAX(IF($D:$D=V22,$A:$A))} -> 45444
A23: 45062 | B23: 정상매출 | C23: 취사난방용 | D23: 개별난방 | E23: 21.6991 | F23: 49.7608 | G23: 2127.2721 | H23: 46159.87 | L23: 46159.87 | R23: 0 | U23: 냉난방용(업무) | V23: 냉난방(동절기) | W23: =COUNTIFS($B:$B,$U$4,$C:$C,U23) -> 3 | X23: {=MAX(IF($D:$D=V23,$A:$A))} -> 0
A24: 45139 | B24: 정상매출 | C24: 취사용 | D24: 취사용 | E24: 21.8472 | F24: 480547.55 | G24: 20505703 | H24: 4.4793194e+08 | I24: 92691770 | J24: 17135370 | L24: 4.4796404e+08 | M24: 32105 | R24: 0 | U24: 냉난방용(업무) | V24: 냉난방(기타) | W24: =COUNTIFS($B:$B,$U$4,$C:$C,U24) -> 3 | X24: {=MAX(IF($D:$D=V24,$A:$A))} -> 0
A25: 45139 | B25: 정상매출 | C25: 개별난방용 | D25: 개별난방 | E25: 21.8472 | F25: 10846906 | G25: 4.6203551e+08 | H25: 1.009365e+10 | I25: 526008600 | J25: 119152980 | L25: 1.0093901e+10 | M25: 251663 | R25: 0 | U25: 냉난방용(업무) | V25: 냉난방(하절기) | W25: =COUNTIFS($B:$B,$U$4,$C:$C,U25) -> 3 | X25: {=MAX(IF($D:$D=V25,$A:$A))} -> 45444
A26: 45139 | B26: 정상매출 | C26: 취사난방용 | D26: 개별난방(취사) | E26: 21.8472 | F26: 4795920.8 | G26: 2.0428957e+08 | H26: 4.4628248e+09 | I26: 417552300 | J26: 37963000 | L26: 4.4630846e+09 | M26: 259746.18 | R26: 0 | U26: 냉난방용(업무) | V26: 중앙난방 | W26: =COUNTIFS($B:$B,$U$4,$C:$C,U26) -> 3 | X26: {=MAX(IF($D:$D=V26,$A:$A))} -> 45139
A27: 45139 | B27: 정상매출 | C27: 취사난방용 | D27: 개별난방 | E27: 21.8472 | F27: 6119621.4 | G27: 2.6067845e+08 | H27: 5.6943698e+09 | L27: 5.6949365e+09 | M27: 566772.82 | R27: 0 | U27: 열전용설비용 | V27: 열전용설비용 | W27: =COUNTIFS($B:$B,$U$4,$C:$C,U27) -> 1 | X27: {=MAX(IF($D:$D=V27,$A:$A))} -> 45444
A28: 45139 | B28: 정상매출 | C28: 중앙난방용 | D28: 중앙난방 | E28: 21.8144 | F28: 469114.53 | G28: 19916008 | H28: 434455731 | J28: 1804180 | K28: 1049000 | L28: 434455731 | R28: 0 | U28: 냉난방용(주택) | V28: 냉난방(하절기) | W28: =COUNTIFS($B:$B,$U$4,$C:$C,U28) -> 2 | X28: {=MAX(IF($D:$D=V28,$A:$A))} -> 45444
A29: 45139 | B29: 정상매출 | C29: 일반용(1) | D29: 일반용(1)(동절기) | E29: 21.1877 | F29: 47.5751 | G29: 2036.4354 | H29: 43147.36 | J29: 1300 | L29: 43147.36 | R29: 0 | U29: 냉난방용(주택) | V29: 냉난방(기타) | W29: =COUNTIFS($B:$B,$U$4,$C:$C,U29) -> 2 | X29: {=MAX(IF($D:$D=V29,$A:$A))} -> 0
A30: 45139 | B30: 정상매출 | C30: 일반용(1) | D30: 일반용(1)(하절기) | E30: 20.9808 | F30: 1131902.4 | G30: 48106659 | H30: 1.0084343e+09 | J30: 618880 | K30: 117600 | L30: 1.0093064e+09 | M30: 872144.69 | R30: 0 | U30: 냉난방용(주택) | V30: 중앙난방 | W30: =COUNTIFS($B:$B,$U$4,$C:$C,U30) -> 2 | X30: {=MAX(IF($D:$D=V30,$A:$A))} -> 45139
A31: 45139 | B31: 정상매출 | C31: 일반용(1) | D31: 일반용(1)(기타) | E31: 20.9934 | F31: 3695365 | G31: 1.5733697e+08 | H31: 3.3019727e+09 | J31: 38016940 | K31: 1168900 | L31: 3.3030378e+09 | M31: 1065083.3 | R31: 0 | U31: 열병합용 | V31: 열병합용(동절기) | W31: =COUNTIFS($B:$B,$U$4,$C:$C,U31) -> 3 | X31: {=MAX(IF($C:$C=U31,$A:$A))} -> 45444
A32: 45139 | B32: 정상매출 | C32: 일반용(2) | D32: 일반용(2)(하절기) | E32: 20.9808 | F32: 841753.16 | G32: 35745418 | H32: 7.4910574e+08 | J32: 186700 | K32: 29400 | L32: 7.4996702e+08 | M32: 861283.42 | R32: 0 | U32: 열병합용 | V32: 열병합용(기타) | W32: =COUNTIFS($B:$B,$U$4,$C:$C,U32) -> 3 | X32: {=MAX(IF($C:$C=U32,$A:$A))} -> 45444
A33: 45139 | B33: 정상매출 | C33: 일반용(2) | D33: 일반용(2)(기타) | E33: 20.9934 | F33: 709236.7 | G33: 30144216 | H33: 6.3230675e+08 | J33: 10158960 | K33: 2578400 | L33: 6.3282958e+08 | M33: 522836.58 | R33: 0 | U33: 열병합용 | V33: 열병합용(하절기) | W33: =COUNTIFS($B:$B,$U$4,$C:$C,U33) -> 3 | X33: {=MAX(IF($C:$C=U33,$A:$A))} -> 45444
A34: 45139 | B34: 정상매출 | C34: 자가열전용 | D34: 자가열전용 | E34: 21.8144 | F34: 126655 | G34: 5375871.5 | H34: 117271403 | J34: 712570 | K34: 735000 | L34: 117271403 | R34: 0 | U34: 연료전지 | V34: 연료전지(하절기) | W34: =COUNTIFS($B:$B,$U$4,$C:$C,U34) -> 3 | X34: {=MAX(IF($D:$D=V34,$A:$A))} -> 45444
A35: 45323 | B35: 정상매출 | C35: 업무난방용 | D35: 업무난방 | E35: 24.6278 | F35: 0.3956 | G35: 16.937 | H35: 417.12 | J35: 320 | L35: 417.12 | R35: 0 | U35: 연료전지 | V35: 연료전지(기타) | W35: =COUNTIFS($B:$B,$U$4,$C:$C,U35) -> 3 | X35: {=MAX(IF($D:$D=V35,$A:$A))} -> 45413
A36: 45352 | B36: 정상매출 | C36: 업무난방용 | D36: 업무난방 | E36: 25.1414 | F36: 0.4717 | G36: 20.1941 | H36: 507.7 | L36: 507.7 | R36: 0 | U36: 연료전지 | V36: 연료전지(동절기) | W36: =COUNTIFS($B:$B,$U$4,$C:$C,U36) -> 3 | X36: {=MAX(IF($D:$D=V36,$A:$A))} -> 0
A37: 45352 | B37: 정상매출 | C37: 주한미군 | D37: 주한미군 | E37: 21.8778 | F37: 48863.487 | G37: 2072740.3 | H37: 45346800 | J37: 1243410 | L37: 45346800 | R37: 0 | U37: 수송용(CNG) | V37: 수송용(CNG) | W37: =COUNTIFS($B:$B,$U$4,$C:$C,U37) -> 1 | X37: {=MAX(IF($D:$D=V37,$A:$A))} -> 45444
A38: 45383 | B38: 정상매출 | C38: 업무난방용 | D38: 업무난방 | E38: 23.6741 | F38: 399.354 | G38: 17042.606 | H38: 351823.78 | J38: 14970 | L38: 403468.24 | M38: 51644.46 | R38: 0
A39: 45413 | B39: 정상매출 | C39: 업무난방용 | D39: 업무난방 | E39: 24.9195 | F39: 383811.25 | G39: 16335712 | H39: 3.917277e+08 | J39: 13198450 | K39: 1529100 | L39: 4.0707772e+08 | M39: 15350012 | R39: 0
A40: 45413 | B40: 정상매출 | C40: 산업용 | D40: 산업용(기타) | E40: 20.4195 | F40: 6556748.1 | G40: 2.7889131e+08 | H40: 5.6948207e+09 | J40: 1054890 | K40: 235200 | L40: 5.6948207e+09 | R40: 0
A41: 45413 | B41: 정상매출 | C41: 냉난방용(업무) | D41: 냉난방(하절기) | E41: 14.7867 | F41: 798094.69 | G41: 33952558 | H41: 5.0204628e+08 | J41: 10678650 | K41: 4275700 | L41: 5.0204628e+08 | R41: 0
A42: 45413 | B42: 정상매출 | C42: 냉난방용(주택) | D42: 냉난방(하절기) | E42: 14.7867 | F42: 27489.418 | G42: 1169639 | H42: 17295101 | J42: 289450 | K42: 98200 | L42: 17295101 | R42: 0
...

Sheet 기안결재표지
K1: [이미지 830*523]
B2: =LEFT(총괄표!A2,9)&" 매출현황을 다음과 같이 보고하오니 결재 바랍니다." -> 2026년 1월 매출현황을 다음과 같이 보고하오니 결재 바랍니다.
E3: - 다 음 -
B5: ="1. 매출년월: "&LEFT(총괄표!A2,9) -> 1. 매출년월: 2026년 1월
B6: 2. 매출현황
B7: 구 분 | D7: 계획 | E7: 실적 | F7: 계획대비 | G7: 전년대비 | H7: 전월대비
B8: 판매량 | C8: =RIGHT(B5,3) -> 1월 | D8: =데이터!C56 -> 6711987 | E8: =데이터!D56 -> 6719536 | F8: =E8/D8 -> 1.0011247 | G8: =데이터!G56 -> 1.0045726 | H8: =데이터!I56 -> 1.5231413
B9: [GJ] | C9: 누계 | D9: =데이터!C57 -> 6711987 | E9: =데이터!D57 -> 6719536 | F9: =E9/D9 -> 1.0011247 | G9: =데이터!G57 -> 1.0045726
B10: 금 액 | C10: =C8 -> 1월 | D10: =데이터!C58 -> 142339231 | E10: =데이터!D58 -> 143084315 | F10: =E10/D10 -> 1.0052346 | G10: =데이터!G58 -> 0.96645842 | H10: =데이터!I58 -> 1.4846747
