Workbook
Name _25년공급전수: '[1]분석(공급량및판매량))'!$B$406:$N$413
Name _25년예상판매량: '[2]분석(공급량및판매량))'!$C$422:$N$439
Name 매출년월: '[3](전산)집계'!$A$2:$A$24
Name 변동후단가표: '매출관리(월)'!$V$5:$X$285
Name 사용량: '[3](전산)집계'!$D$2:$D$24
Name 사용열량: '[3](전산)집계'!$E$2:$E$24
Name 상품: '[3](전산)집계'!$C$2:$C$24

Sheet 총괄표
A2: 2026년 4월 매출현황 | R2: (누계-집계용도) | AA2: 2025년 사업계획서 normal기준작성
A3: 1.판매량 | R3: 1.판매량(단위:GJ) | V3: 1번 )전월기준 누계값으로 작성
A5: 구 분 | C5: 당 월 | J5: 누 계 | R5: 구분 | T5: 구성비 | V5: 판매량(누계)
C6: 계획 (천MJ) | D6: 실적 (천N㎥) | E6: 실적 (천MJ) | F6: 대비 (%) | G6: 전년 (천MJ) | H6: 대비 (%) | I6: 구성비 (%) | J6: 계획 (천MJ) | K6: 실적 (천N㎥) | L6: 실적 (천MJ) | M6: 대비 (%) | N6: 전년 (천MJ) | O6: 대비 (%) | P6: 구성비 (%) | T6: 당월 | U6: 누계 | V6: 계획(GJ) | W6: 실적(천N㎥) | X6: 실적(GJ) | Y6: 전년(GJ)
A7: 주 택 용 | B7: 취사용 | C7: 22557 | D7: =(매출액표!D23)/1000 -> 448.38784 | E7: =ROUND((매출액표!E23)/1000,0) -> 19147 | F7: =ROUND(E7/C7*100,1) -> 84.9 | G7: 20458 | H7: =E7/G7*100 -> 93.591749 | I7: =IF(E7=MAX($E$7:$E$10,$E$12:$E$21),MAX($T$7:$T$21)+(100-SUM($T$7:$T$21)),T7) -> 0.4 | J7: =C7+V7 -> 90674 | K7: =D7+W7 -> 1920.1584 | L7: =E7+X7 -> 81777 | M7: =L7/J7*100 -> 90.187926 | N7: =G7+Y7 -> 89065 | O7: =L7/N7*100 -> 91.817212 | P7: =IF(L7=MAX($L$7:$L$10,$L$12:$L$21),MAX($U$7:$U$21)+(100-SUM($U$7:$U$21)),U7) -> 0.3 | R7: 가정용 | S7: 취사용 | T7: =ROUND(E7/$E$23*100,1) -> 0.4 | U7: =ROUND(L7/$L$23*100,1) -> 0.3 | V7: 68117 | W7: 1471.7705 | X7: 62630 | Y7: 68607
B8: 개별난방용 | C8: 2977526 | D8: =((매출액표!D31+매출액표!D36)/1000)-1 -> 67397.668 | E8: =ROUND((매출액표!E31+매출액표!E36)/1000,0) -> 2877534 | F8: =ROUND(E8/C8*100,1) -> 96.6 | G8: 2927253 | H8: =E8/G8*100 -> 98.301513 | I8: =IF(E8=MAX($E$7:$E$10,$E$12:$E$21),MAX($T$7:$T$21)+(100-SUM($T$7:$T$21)),T8) -> 64 | J8: =C8+V8 -> 16803565 | K8: =D8+W8 -> 396015.08 | L8: =E8+X8 -> 16868443 | M8: =L8/J8*100 -> 100.3861 | N8: =G8+Y8 -> 17407801 | O8: =L8/N8*100 -> 96.90163 | P8: =IF(L8=MAX($L$7:$L$10,$L$12:$L$21),MAX($U$7:$U$21)+(100-SUM($U$7:$U$21)),U8) -> 69.3 | S8: 개별난방용 | T8: =ROUND(E8/$E$23*100,1) -> 64 | U8: =ROUND(L8/$L$23*100,1) -> 69.3 | V8: 13826039 | W8: 328617.41 | X8: 13990909 | Y8: 14480548
B9: 중앙난방용 | C9: 46563 | D9: =매출액표!D40/1000 -> 1025.4339 | E9: =ROUND(매출액표!E40/1000,0) -> 43732 | F9: =ROUND(E9/C9*100,1) -> 93.9 | G9: 52880 | H9: =E9/G9*100 -> 82.700454 | I9: =IF(E9=MAX($E$7:$E$10,$E$12:$E$21),MAX($T$7:$T$21)+(100-SUM($T$7:$T$21)),T9) -> 1 | J9: =C9+V9 -> 295685 | K9: =D9+W9 -> 6984.977 | L9: =E9+X9 -> 297661 | M9: =L9/J9*100 -> 100.66828 | N9: =G9+Y9 -> 346753 | O9: =L9/N9*100 -> 85.842372 | P9: =IF(L9=MAX($L$7:$L$10,$L$12:$L$21),MAX($U$7:$U$21)+(100-SUM($U$7:$U$21)),U9) -> 1.2 | S9: 중앙난방용 | T9: =ROUND(E9/$E$23*100,1) -> 1 | U9: =ROUND(L9/$L$23*100,1) -> 1.2 | V9: 249122 | W9: 5959.5431 | X9: 253929 | Y9: 293873
B10: 자가열전용 | C10: 21888 | D10: =(매출액표!D44)/1000 -> 426.052 | E10: =ROUND((매출액표!E44)/1000,0) -> 18180 | F10: =ROUND(E10/C10*100,1) -> 83.1 | G10: 19757 | H10: =E10/G10*100 -> 92.018019 | I10: =IF(E10=MAX($E$7:$E$10,$E$12:$E$21),MAX($T$7:$T$21)+(100-SUM($T$7:$T$21)),T10) -> 0.4 | J10: =C10+V10 -> 205494 | K10: =D10+W10 -> 4580.876 | L10: =E10+X10 -> 195191 | M10: =L10/J10*100 -> 94.986228 | N10: =G10+Y10 -> 206909 | O10: =L10/N10*100 -> 94.336641 | P10: =IF(L10=MAX($L$7:$L$10,$L$12:$L$21),MAX($U$7:$U$21)+(100-SUM($U$7:$U$21)),U10) -> 0.8 | S10: 자가열전용 | T10: =ROUND(E10/$E$23*100,1) -> 0.4 | U10: =ROUND(L10/$L$23*100,1) -> 0.8 | V10: 183606 | W10: 4154.824 | X10: 177011 | Y10: 187152
B11: 소 계 | C11: =ROUND(SUM(C7:C10),0) -> 3068534 | D11: =SUM(D7:D10) -> 69297.542 | E11: =SUM(E7:E10) -> 2958593 | F11: =E11/C11*100 -> 96.417149 | G11: =SUM(G7:G10) -> 3020348 | H11: =E11/G11*100 -> 97.955368 | I11: =SUM(I7:I10) -> 65.8 | J11: =ROUNDUP(SUM(J7:J10),0) -> 17395418 | K11: =SUM(K7:K10) -> 409501.09 | L11: =SUM(L7:L10) -> 17443072 | M11: =L11/J11*100 -> 100.27395 | N11: =SUM(N7:N10) -> 18050528 | O11: =L11/N11*100 -> 96.634691 | P11: =SUM(P7:P10) -> 71.6 | S11: 소계 | V11: =ROUNDUP(SUM(V7:V10),0) -> 14326884 | W11: =SUM(W7:W10) -> 340203.55 | X11: =SUM(X7:X10) -> 14484479 | Y11: =SUM(Y7:Y10) -> 15030180
A12: 일반용 | C12: 331181 | D12: =매출액표!D56/1000 -> 7666.9325 | E12: =ROUND(매출액표!E56/1000,0) -> 327092 | F12: =ROUND(E12/C12*100,1) -> 98.8 | G12: 329149 | H12: =E12/G12*100 -> 99.375055 | I12: =IF(E12=MAX($E$7:$E$10,$E$12:$E$21),MAX($T$7:$T$21)+(100-SUM($T$7:$T$21)),T12) -> 7.3 | J12: =C12+V12 -> 1450288 | K12: =D12+W12 -> 33456.649 | L12: =E12+X12 -> 1425500 | M12: =L12/J12*100 -> 98.290822 | N12: =G12+Y12 -> 1441833 | O12: =L12/N12*100 -> 98.867206 | P12: =IF(L12=MAX($L$7:$L$10,$L$12:$L$21),MAX($U$7:$U$21)+(100-SUM($U$7:$U$21)),U12) -> 5.9 | R12: 일반용 | T12: =ROUND(E12/$E$23*100,1) -> 7.3 | U12: =ROUND(L12/$L$23*100,1) -> 5.9 | V12: 1119107 | W12: 25789.717 | X12: 1098408 | Y12: 1112684
A13: 업무난방용 | C13: 77263 | D13: =매출액표!D65/1000 -> 1643.8409 | E13: =ROUND(매출액표!E65/1000,0) -> 70133 | F13: =ROUND(E13/C13*100,1) -> 90.8 | G13: 70529 | H13: =E13/G13*100 -> 99.438529 | I13: =IF(E13=MAX($E$7:$E$10,$E$12:$E$21),MAX($T$7:$T$21)+(100-SUM($T$7:$T$21)),T13) -> 1.6 | J13: =C13+V13 -> 454418 | K13: =D13+W13 -> 10751.157 | L13: =E13+X13 -> 457959 | M13: =L13/J13*100 -> 100.77924 | N13: =G13+Y13 -> 466623 | O13: =L13/N13*100 -> 98.143255 | P13: =IF(L13=MAX($L$7:$L$10,$L$12:$L$21),MAX($U$7:$U$21)+(100-SUM($U$7:$U$21)),U13) -> 1.9 | R13: 업무난방용 | T13: =ROUND(E13/$E$23*100,1) -> 1.6 | U13: =ROUND(L13/$L$23*100,1) -> 1.9 | V13: 377155 | W13: 9107.3157 | X13: 387826 | Y13: 396094
A14: 냉방용 | C14: 67578 | D14: =매출액표!D73/1000 -> 1081.9661 | E14: =ROUND(매출액표!E73/1000,0) -> 46145 | F14: =ROUND(E14/C14*100,1) -> 68.3 | G14: 51962 | H14: =E14/G14*100 -> 88.805281 | I14: =IF(E14=MAX($E$7:$E$10,$E$12:$E$21),MAX($T$7:$T$21)+(100-SUM($T$7:$T$21)),T14) -> 1 | J14: =C14+V14 -> 500002 | K14: =D14+W14 -> 11308.131 | L14: =E14+X14 -> 481602 | M14: =L14/J14*100 -> 96.320015 | N14: =G14+Y14 -> 509204 | O14: =L14/N14*100 -> 94.579383 | P14: =IF(L14=MAX($L$7:$L$10,$L$12:$L$21),MAX($U$7:$U$21)+(100-SUM($U$7:$U$21)),U14) -> 2 | R14: 냉방용 | T14: =ROUND(E14/$E$23*100,1) -> 1 | U14: =ROUND(L14/$L$23*100,1) -> 2 | V14: 432424 | W14: 10226.165 | X14: 435457 | Y14: 457242
A15: 산업용 | C15: 786084 | D15: =매출액표!D77/1000 -> 18609.036 | E15: =ROUND(매출액표!E77/1000,0)+1 -> 793601 | F15: =ROUND(E15/C15*100,1) -> 101 | G15: 811060 | H15: =E15/G15*100 -> 97.847385 | I15: =IF(E15=MAX($E$7:$E$10,$E$12:$E$21),MAX($T$7:$T$21)+(100-SUM($T$7:$T$21)),T15) -> 17.6 | J15: =C15+V15 -> 3291908 | K15: =D15+W15 -> 77552.809 | L15: =E15+X15 -> 3304859 | M15: =L15/J15*100 -> 100.39342 | N15: =G15+Y15 -> 3383198 | O15: =L15/N15*100 -> 97.684469 | P15: =IF(L15=MAX($L$7:$L$10,$L$12:$L$21),MAX($U$7:$U$21)+(100-SUM($U$7:$U$21)),U15) -> 13.6 | R15: 산업용 | T15: =ROUND(E15/$E$23*100,1) -> 17.6 | U15: =ROUND(L15/$L$23*100,1) -> 13.6 | V15: 2505824 | W15: 58943.772 | X15: 2511258 | Y15: 2572138
A16: 수송용(CNG) | C16: 239599 | D16: =ROUND((매출액표!D57+매출액표!D59)/1000,0) -> 5747 | E16: =ROUND((매출액표!E57+매출액표!E59)/1000,0) -> 247986 | F16: =ROUND(E16/C16*100,1) -> 103.5 | G16: 251298 | H16: =E16/G16*100 -> 98.682043 | I16: =IF(E16=MAX($E$7:$E$10,$E$12:$E$21),MAX($T$7:$T$21)+(100-SUM($T$7:$T$21)),T16) -> 5.5 | J16: =C16+V16 -> 938948 | K16: =D16+W16 -> 22664 | L16: =E16+X16 -> 977986 | M16: =L16/J16*100 -> 104.15763 | N16: =G16+Y16 -> 984501 | O16: =L16/N16*100 -> 99.338243 | P16: =IF(L16=MAX($L$7:$L$10,$L$12:$L$21),MAX($U$7:$U$21)+(100-SUM($U$7:$U$21)),U16) -> 4 | R16: 수송용(CNG) | T16: =ROUND(E16/$E$23*100,1) -> 5.5 | U16: =ROUND(L16/$L$23*100,1) -> 4 | V16: 699349 | W16: 16917 | X16: 730000 | Y16: 733203
A17: 수송용(BIO) | C17: 11669 | D17: =ROUND((매출액표!D58)/1000,0) -> 297 | E17: =ROUND((매출액표!E58)/1000,0) -> 12554 | F17: =ROUND(E17/C17*100,1) -> 107.6 | G17: 11815 | H17: =IFERROR(E17/G17*100,0) -> 106.25476 | I17: =IF(E17=MAX($E$7:$E$10,$E$12:$E$21),MAX($T$7:$T$21)+(100-SUM($T$7:$T$21)),T17) -> 0.3 | J17: =C17+V17 -> 44426 | K17: =D17+W17 -> 1172 | L17: =E17+X17 -> 49533 | M17: =L17/J17*100 -> 111.49552 | N17: =G17+Y17 -> 44975 | O17: =IFERROR(L17/N17*100,0) -> 110.13452 | P17: =IF(L17=MAX($L$7:$L$10,$L$12:$L$21),MAX($U$7:$U$21)+(100-SUM($U$7:$U$21)),U17) -> 0.2 | R17: 수송용(BIO) | T17: =ROUND(E17/$E$23*100,1) -> 0.3 | U17: =ROUND(L17/$L$23*100,1) -> 0.2 | V17: 32757 | W17: 875 | X17: 36979 | Y17: 33160
A18: 열병합용 | C18: 19528 | D18: =매출액표!D82/1000 -> 436.223 | E18: =ROUND(매출액표!E82/1000,0) -> 18612 | F18: =ROUND(E18/C18*100,1) -> 95.3 | G18: 22898 | H18: =E18/G18*100 -> 81.282208 | I18: =IF(E18=MAX($E$7:$E$10,$E$12:$E$21),MAX($T$7:$T$21)+(100-SUM($T$7:$T$21)),T18) -> 0.4 | J18: =C18+V18 -> 92084 | K18: =D18+W18 -> 2166.712 | L18: =E18+X18 -> 92370 | M18: =L18/J18*100 -> 100.31059 | N18: =G18+Y18 -> 100141 | O18: =L18/N18*100 -> 92.239942 | P18: =IF(L18=MAX($L$7:$L$10,$L$12:$L$21),MAX($U$7:$U$21)+(100-SUM($U$7:$U$21)),U18) -> 0.4 | R18: 열병합용 | T18: =ROUND(E18/$E$23*100,1) -> 0.4 | U18: =ROUND(L18/$L$23*100,1) -> 0.4 | V18: 72556 | W18: 1730.489 | X18: 73758 | Y18: 77243
A19: 연료전지용 | C19: 16627 | D19: =매출액표!D87/1000 -> 419.11853 | E19: =ROUND(매출액표!E87/1000,0) -> 17879 | F19: =ROUND(E19/C19*100,1) -> 107.5 | G19: 16604 | H19: =E19/G19*100 -> 107.67887 | I19: =IF(E19=MAX($E$7:$E$10,$E$12:$E$21),MAX($T$7:$T$21)+(100-SUM($T$7:$T$21)),T19) -> 0.4 | J19: =C19+V19 -> 68239 | K19: =D19+W19 -> 1676.5931 | L19: =E19+X19 -> 71486 | M19: =L19/J19*100 -> 104.75828 | N19: =G19+Y19 -> 69243 | O19: =L19/N19*100 -> 103.23932 | P19: =IF(L19=MAX($L$7:$L$10,$L$12:$L$21),MAX($U$7:$U$21)+(100-SUM($U$7:$U$21)),U19) -> 0.3 | R19: 연료전지용 | T19: =ROUND(E19/$E$23*100,1) -> 0.4 | U19: =ROUND(L19/$L$23*100,1) -> 0.3 | V19: 51612 | W19: 1257.4746 | X19: 53607 | Y19: 52639
A20: 열전용설비용 | C20: 598 | D20: =매출액표!D89/1000 -> 15.921 | E20: =ROUND(매출액표!E89/1000,0) -> 679 | F20: =ROUND(E20/C20*100,1) -> 113.5 | G20: 1199 | H20: =E20/G20*100 -> 56.630525 | I20: =IF(E20=MAX($E$7:$E$10,$E$12:$E$21),MAX($T$7:$T$21)+(100-SUM($T$7:$T$21)),T20) -> 0 | J20: =C20+V20 -> 2836 | K20: =D20+W20 -> 85.892 | L20: =E20+X20 -> 3661 | M20: =L20/J20*100 -> 129.09027 | N20: =G20+Y20 -> 3473 | O20: =L20/N20*100 -> 105.41319 | P20: =IF(L20=MAX($L$7:$L$10,$L$12:$L$21),MAX($U$7:$U$21)+(100-SUM($U$7:$U$21)),U20) -> 0 | R20: 열전용설비용 | T20: =ROUND(E20/$E$23*100,1) -> 0 | U20: =ROUND(L20/$L$23*100,1) -> 0 | V20: 2238 | W20: 69.971 | X20: 2982 | Y20: 2274
A21: 주한미군 | C21: 2522 | D21: =매출액표!D92/1000 -> 73.101049 | E21: =ROUND(매출액표!E92/1000,0) -> 3119 | F21: =ROUND(E21/C21*100,1) -> 123.7 | G21: 2521 | H21: =E21/G21*100 -> 123.72075 | I21: =IF(E21=MAX($E$7:$E$10,$E$12:$E$21),MAX($T$7:$T$21)+(100-SUM($T$7:$T$21)),T21) -> 0.1 | J21: =C21+V21 -> 31672 | K21: =D21+W21 -> 737.0173 | L21: =E21+X21 -> 31414 | M21: =L21/J21*100 -> 99.1854 | N21: =G21+Y21 -> 32235 | O21: =L21/N21*100 -> 97.453079 | P21: =IF(L21=MAX($L$7:$L$10,$L$12:$L$21),MAX($U$7:$U$21)+(100-SUM($U$7:$U$21)),U21) -> 0.1 | R21: 주한미군 | T21: =ROUND(E21/$E$23*100,1) -> 0.1 | U21: =ROUND(L21/$L$23*100,1) -> 0.1 | V21: 29150 | W21: 663.91625 | X21: 28295 | Y21: 29714
A22: 소 계 | C22: =SUM(C12:C21) -> 1552649 | D22: =SUM(D12:D21) -> 35990.139 | E22: =SUM(E12:E21) -> 1537800 | F22: =E22/C22*100 -> 99.043634 | G22: =SUM(G12:G21) -> 1569035 | H22: =E22/G22*100 -> 98.009286 | I22: =SUM(I12:I21) -> 34.2 | J22: =SUM(J12:J21) -> 6874821 | K22: =SUM(K12:K21) -> 161570.96 | L22: =SUM(L12:L21) -> 6896370 | M22: =L22/J22*100 -> 100.31345 | N22: =SUM(N12:N21) -> 7035426 | O22: =L22/N22*100 -> 98.023489 | P22: =P23-P11 -> 28.4 | R22: 소계 | V22: =SUM(V12:V21) -> 5322172 | W22: =SUM(W12:W21) -> 125580.82 | X22: =SUM(X12:X21) -> 5358570 | Y22: =SUM(Y12:Y21) -> 5466391
A23: 합 계 | C23: =C11+C22 -> 4621183 | D23: =D11+D22 -> 105287.68 | E23: =E22+E11 -> 4496393 | F23: =E23/C23*100 -> 97.299609 | G23: =G22+G11 -> 4589383 | H23: =E23/G23*100 -> 97.973802 | I23: =I11+I22 -> 100 | J23: =J11+J22 -> 24270239 | K23: =K22+K11 -> 571072.05 | L23: =L11+L22 -> 24339442 | M23: =L23/J23*100 -> 100.28514 | N23: =N11+N22 -> 25085954 | O23: =L23/N23*100 -> 97.024183 | P23: 100 | R23: 합계 | V23: =V11+V22 -> 19649056 | W23: =W11+W22 -> 465784.37 | X23: =X11+X22 -> 19843049 | Y23: =Y11+Y22 -> 20496571
A24: 공급량 | C24: 3035368 | D24: 65894831 | E24: 2811637.9 | F24: =E24/C24*100 -> 92.629226 | G24: 3033061 | H24: =$E$24/G24*100 -> 92.699682 | J24: =C24+V24 -> 20942066 | K24: =D24+W24 -> 490006346 | L24: =E24+X24 -> 20885652 | M24: =L24/J24*100 -> 99.73062 | N24: =G24+Y24 -> 21798392 | O24: =L24/N24*100 -> 95.812812 | R24: 공급량 | V24: 17906698 | W24: 424111515 | X24: 18074014 | Y24: 18765331
R27: 2.판매금액(단위:백만원)
A28: 2.판매금액 | P28: 단위 : 백만원 | V28: 전월기준 누계값으로 작성
A29: 구 분 | C29: 당 월 | J29: 누 계 | R29: 구분 | T29: 구성비 | V29: 판매금액(누계)
C30: 계획 | D30: 실적 | E30: 대비 (%) | F30: 전년 | G30: 대비 (%) | H30: 구성비 (%) | J30: 계획 | K30: 실적 | L30: 대비 (%) | M30: 전년 | N30: 대비 (%) | O30: 구성비 (%) | T30: 당월 | U30: 누계 | V30: 계획 | W30: 실적 | X30: 전년누계
A31: 주 택 용 | B31: 취사용 | C31: 691263.05 | D31: =ROUND((매출액표!G23+매출액표!H23)/1000,0) -> 523662 | F31: 555743 | H31: =IF(D31=MAX($D$31:$D$34,$D$36:$D$45),MAX($T$31:$T$45)+(100-SUM($T$31:$T$45)),T31) -> 0.6 | J31: =C31+V31 -> 2775029.6 | K31: =D31+W31 -> 2224622 | M31: =X31+F31-1 -> 2397489 | O31: =IF(K31=MAX($K$31:$K$34,$K$36:$K$45),MAX($U$31:$U$45)+(100-SUM($U$31:$U$45)),U31) -> 0.4 | R31: 가정용 | S31: 취사용 | T31: =ROUND(D31/$D$47*100,1) -> 0.6 | U31: =ROUND(K31/$K$47*100,1) -> 0.4 | V31: 2083766.6 | W31: 1700960 | X31: 1841747
B32: 개별난방용 | C32: 63870114 | D32: =ROUND((매출액표!G31+매출액표!H31+매출액표!G36+매출액표!H36)/1000,0) -> 61573915 | F32: 62823355 | H32: =IF(D32=MAX($D$31:$D$34,$D$36:$D$45),MAX($T$31:$T$45)+(100-SUM($T$31:$T$45)),T32) -> 65.2 | J32: =C32+V32 -> 3.6466448e+08 | K32: =D32+W32 -> 367135746 | M32: =X32+F32 -> 379548726 | O32: =IF(K32=MAX($K$31:$K$34,$K$36:$K$45),MAX($U$31:$U$45)+(100-SUM($U$31:$U$45)),U32) -> 71.1 | S32: 개별난방용 | T32: =ROUND(D32/$D$47*100,1) -> 65.4 | U32: =ROUND(K32/$K$47*100,1) -> 70.9 | V32: 3.0079437e+08 | W32: 305561831 | X32: 316725371
B33: 중앙난방용 | C33: 1098798 | D33: =ROUND((매출액표!G40+매출액표!H40)/1000,0) -> 989595 | F33: 1198960 | H33: =IF(D33=MAX($D$31:$D$34,$D$36:$D$45),MAX($T$31:$T$45)+(100-SUM($T$31:$T$45)),T33) -> 1.1 | J33: =C33+V33 -> 6977603 | K33: =D33+W33 -> 6246561 | M33: =X33+F33 -> 7334089.5 | O33: =IF(K33=MAX($K$31:$K$34,$K$36:$K$45),MAX($U$31:$U$45)+(100-SUM($U$31:$U$45)),U33) -> 1.2 | S33: 중앙난방용 | T33: =ROUND(D33/$D$47*100,1) -> 1.1 | U33: =ROUND(K33/$K$47*100,1) -> 1.2 | V33: 5878805 | W33: 5256966 | X33: 6135129.5
B34: 자가열전용 | C34: 516515 | D34: =ROUND((매출액표!G44+매출액표!H44)/1000,0) -> 419387 | F34: 454769 | H34: =IF(D34=MAX($D$31:$D$34,$D$36:$D$45),MAX($T$31:$T$45)+(100-SUM($T$31:$T$45)),T34) -> 0.4 | J34: =C34+V34 -> 4849267 | K34: =D34+W34 -> 4467837 | M34: =X34+F34 -> 4727378.2 | O34: =IF(K34=MAX($K$31:$K$34,$K$36:$K$45),MAX($U$31:$U$45)+(100-SUM($U$31:$U$45)),U34) -> 0.9 | S34: 자가열전용 | T34: =ROUND(D34/$D$47*100,1) -> 0.4 | U34: =ROUND(K34/$K$47*100,1) -> 0.9 | V34: 4332752 | W34: 4048450 | X34: 4272609.2
B35: 소 계 | C35: =SUM(C31:C34) -> 66176690 | D35: =SUM(D31:D34) -> 63506559 | E35: =D35/C35*100 -> 95.965149 | F35: =SUM(F31:F34) -> 65032827 | G35: =D35/F35*100 -> 97.653081 | H35: =SUM(H31:I34) -> 67.3 | J35: =C35+V35 -> 379266379 | K35: =SUM(K31:K34) -> 380074766 | L35: =K35/J35*100 -> 100.21314 | M35: =SUM(M31:M34) -> 3.9400768e+08 | N35: =K35/M35*100 -> 96.463796 | O35: =SUM(O31:P34) -> 73.6 | S35: 소계 | V35: =SUM(V31:V34) -> 313089689 | W35: =SUM(W31:W34) -> 316568207 | X35: =SUM(X31:X34) -> 3.2897486e+08
A36: 일반용 | C36: 7545660 | D36: =ROUNDDOWN((매출액표!G50+매출액표!G55)/1000,-3)+1000 -> 7426000 | F36: 7431000 | H36: =IF(D36=MAX($D$31:$D$34,$D$36:$D$45),MAX($T$31:$T$45)+(100-SUM($T$31:$T$45)),T36) -> 7.9 | J36: =C36+V36 -> 33043503 | K36: =D36+W36 -> 32355000 | M36: =X36+F36 -> 32557205 | O36: =IF(K36=MAX($K$31:$K$34,$K$36:$K$45),MAX($U$31:$U$45)+(100-SUM($U$31:$U$45)),U36) -> 6.3 | R36: 일반용 | T36: =ROUND(D36/$D$47*100,1) -> 7.9 | U36: =ROUND(K36/$K$47*100,1) -> 6.3 | V36: 25497843 | W36: 24929000 | X36: 25126205
A37: 업무난방용 | C37: 1698928 | D37: =ROUND((매출액표!G65+매출액표!H65)/1000,0) -> 1498332 | F37: 1701322 | H37: =IF(D37=MAX($D$31:$D$34,$D$36:$D$45),MAX($T$31:$T$45)+(100-SUM($T$31:$T$45)),T37) -> 1.6 | J37: =C37+V37 -> 9992150 | K37: =D37+W37 -> 9881982 | M37: =X37+F37 -> 11526765 | O37: =IF(K37=MAX($K$31:$K$34,$K$36:$K$45),MAX($U$31:$U$45)+(100-SUM($U$31:$U$45)),U37) -> 1.9 | R37: 업무난방용 | T37: =ROUND(D37/$D$47*100,1) -> 1.6 | U37: =ROUND(K37/$K$47*100,1) -> 1.9 | V37: 8293222 | W37: 8383650 | X37: 9825443.2
A38: 냉방용 | C38: 880629 | D38: =ROUND((매출액표!G73+매출액표!H73)/1000,0) -> 994569 | F38: 1267048 | H38: =IF(D38=MAX($D$31:$D$34,$D$36:$D$45),MAX($T$31:$T$45)+(100-SUM($T$31:$T$45)),T38) -> 1.1 | J38: =C38+V38 -> 10110372 | K38: =D38+W38 -> 10554988 | M38: =X38+F38 -> 12768584 | O38: =IF(K38=MAX($K$31:$K$34,$K$36:$K$45),MAX($U$31:$U$45)+(100-SUM($U$31:$U$45)),U38) -> 2 | R38: 냉방용 | T38: =ROUND(D38/$D$47*100,1) -> 1.1 | U38: =ROUND(K38/$K$47*100,1) -> 2 | V38: 9229743 | W38: 9560419 | X38: 11501536
A39: 산업용 | C39: 13643902 | D39: =ROUND((매출액표!G77+매출액표!H77)/1000,0) -> 14465043 | F39: 17251205 | H39: =IF(D39=MAX($D$31:$D$34,$D$36:$D$45),MAX($T$31:$T$45)+(100-SUM($T$31:$T$45)),T39) -> 15.4 | J39: =C39+V39 -> 57136987 | K39: =D39+W39 -> 59737670 | M39: =X39+F39+1 -> 71886716 | O39: =IF(K39=MAX($K$31:$K$34,$K$36:$K$45),MAX($U$31:$U$45)+(100-SUM($U$31:$U$45)),U39) -> 11.5 | R39: 산업용 | T39: =ROUND(D39/$D$47*100,1) -> 15.4 | U39: =ROUND(K39/$K$47*100,1) -> 11.5 | V39: 43493085 | W39: 45272627 | X39: 54635510
A40: 수송용(CNG) | C40: 4855785 | D40: =ROUND((매출액표!G57+매출액표!G59)/1000,0) -> 5231777 | F40: 6125700 | H40: =IF(D40=MAX($D$31:$D$34,$D$36:$D$45),MAX($T$31:$T$45)+(100-SUM($T$31:$T$45)),T40) -> 5.6 | J40: =C40+V40 -> 19029000 | K40: =D40+W40 -> 20340809 | M40: =X40+F40 -> 23593635 | O40: =IF(K40=MAX($K$31:$K$34,$K$36:$K$45),MAX($U$31:$U$45)+(100-SUM($U$31:$U$45)),U40) -> 3.9 | R40: 수송용(CNG) | T40: =ROUND(D40/$D$47*100,1) -> 5.6 | U40: =ROUND(K40/$K$47*100,1) -> 3.9 | V40: 14173215 | W40: 15109032 | X40: 17467935
A41: 수송용(BIO) | C41: 236487 | D41: =ROUND(매출액표!G58/1000,0) -> 268300 | F41: 288002 | H41: =IF(D41=MAX($D$31:$D$34,$D$36:$D$45),MAX($T$31:$T$45)+(100-SUM($T$31:$T$45)),T41) -> 0.3 | J41: =C41+V41 -> 900349 | K41: =D41+W41 -> 1043811 | M41: =X41+F41 -> 1077869 | O41: =IF(K41=MAX($K$31:$K$34,$K$36:$K$45),MAX($U$31:$U$45)+(100-SUM($U$31:$U$45)),U41) -> 0.2 | R41: 수송용(BIO) | T41: =ROUND(D41/$D$47*100,1) -> 0.3 | U41: =ROUND(K41/$K$47*100,1) -> 0.2 | V41: 663862 | W41: 775511 | X41: 789867
A42: 열병합용 | C42: 351730 | D42: =ROUND((매출액표!G82)/1000,0) -> 350254 | F42: 486631 | H42: =IF(D42=MAX($D$31:$D$34,$D$36:$D$45),MAX($T$31:$T$45)+(100-SUM($T$31:$T$45)),T42) -> 0.4 | J42: =C42+V42 -> 1658577 | K42: =D42+W42 -> 1715592 | M42: =X42+F42 -> 2155039.7 | O42: =IF(K42=MAX($K$31:$K$34,$K$36:$K$45),MAX($U$31:$U$45)+(100-SUM($U$31:$U$45)),U42) -> 0.3 | R42: 열병합용 | T42: =ROUND(D42/$D$47*100,1) -> 0.4 | U42: =ROUND(K42/$K$47*100,1) -> 0.3 | V42: 1306847 | W42: 1365338 | X42: 1668408.7
A43: 연료전지용 | C43: 243686 | D43: =ROUND((매출액표!G87+매출액표!H87)/1000,0) -> 275670 | F43: 299201 | H43: =IF(D43=MAX($D$31:$D$34,$D$36:$D$45),MAX($T$31:$T$45)+(100-SUM($T$31:$T$45)),T43) -> 0.3 | J43: =C43+V43 -> 1000115 | K43: =D43+W43 -> 1087659 | M43: =X43+F43 -> 1277690.4 | O43: =IF(K43=MAX($K$31:$K$34,$K$36:$K$45),MAX($U$31:$U$45)+(100-SUM($U$31:$U$45)),U43) -> 0.2 | R43: 연료전지용 | T43: =ROUND(D43/$D$47*100,1) -> 0.3 | U43: =ROUND(K43/$K$47*100,1) -> 0.2 | V43: 756429 | W43: 811989 | X43: 978489.41
A44: 열전용설비용 | C44: 12455 | D44: =ROUND((매출액표!G89+매출액표!H89)/1000,0) -> 14901 | F44: 29003 | H44: =IF(D44=MAX($D$31:$D$34,$D$36:$D$45),MAX($T$31:$T$45)+(100-SUM($T$31:$T$45)),T44) -> 0 | J44: =C44+V44 -> 59069 | K44: =D44+W44 -> 79199 | M44: =X44+F44 -> 84517.559 | O44: =IF(K44=MAX($K$31:$K$34,$K$36:$K$45),MAX($U$31:$U$45)+(100-SUM($U$31:$U$45)),U44) -> 0 | R44: 열전용설비용 | T44: =ROUND(D44/$D$47*100,1) -> 0 | U44: =ROUND(K44/$K$47*100,1) -> 0 | V44: 46614 | W44: 64298 | X44: 55514.559
...

Sheet 매출액표
A4: =LEFT(총괄표!A2,9)&" 매출액집계표" -> 2026년 4월 매출액집계표
A7: 구분 | B7: 적 요 | D7: 도시가스 | H7: 기본료 | I7: 계량기관리비 | J7: 보정기관리비 | K7: 가스부가세 | L7: 계량기부가세 | M7: 보정기부가세 | N7: 합계
D8: 수량(㎥) | E8: 수량(MJ) | F8: 단가 | G8: 공급가액
B9: 전월재고 | D9: 77024439 | E9: 3.2815828e+09
A10: 공 | B10: 당월생산(LNG)(+) | D10: 65825252 | E10: 2808668606
B11: 자가소모(LNG)(-) | D11: =ROUND(-자가소모!D12-D12,4) -> -2239.15 | E11: =ROUND(-자가소모!E12-E12,4) -> -95542.291
B12: 타계정대체(-) | D12: =ROUND(-SUM(자가소모!D6:D7),4) -> -217900 | E12: =ROUND(-SUM(자가소모!E6:E7),4) -> -9297575.1
B13: 계 | D13: =D9+D10+D12+D11 -> 1.4262955e+08 | E13: =E9+E10+E11+E12 -> 6.0808583e+09
B14: 전월재고 | D14: -21241.33 | E14: -964518.09
A15: 급 | B15: 당월생산(BIO)(+) | D15: 293130 | E15: 12372646
B16: 자가소모(BIO)(-)
B17: 계 | D17: =D14+D15+D16 -> 271888.67 | E17: =E14+E15+E16 -> 11408128
B18: 주 택 용 | C18: 취사용 변동전 | D18: 18.4901 | E18: 789.1569 | F18: =G18/E18 -> 23.215713 | G18: 18320.84 | H18: 12230 | I18: 1360 | N18: =SUM(G18:M18) -> 31910.84
C19: 취사용 변동후 | D19: 450167.01 | E19: 19223017 | F19: =G19/E19 -> 23.634437 | G19: 4.5432517e+08 | H19: 87251130 | I19: 14406820 | N19: =SUM(G19:M19) -> 5.5598312e+08
C20: 사회복지시설할인액 | G20: -71560 | N20: =SUM(G20:M20) -> -71560
C21: 사회적배려 할인액 | G21: -16069881 | N21: =SUM(G21:M21) -> -16069881
C22: 검침착오분조정 | D22: -1797.6638 | E22: -76506.057 | G22: -1803720 | N22: =SUM(G22:M22) -> -1803720
C23: 소계 | D23: =SUM(D18:D22) -> 448387.84 | E23: =SUM(E18:E22) -> 19147300 | F23: =G23/E23 -> 22.791638 | G23: =SUM(G18:G22) -> 4.3639833e+08 | H23: =SUM(H18:H22) -> 87263360 | I23: =SUM(I18:I22) -> 14408180 | J23: =SUM(J18:J22) -> 0 | K23: =SUM(K18:K22) -> 0 | L23: =SUM(L18:L22) -> 0 | M23: 0 | N23: =SUM(N18:N22) -> 538069873
C24: 취사난방용(취사)변동전 | D24: 58.9847 | E24: 2517.1279 | F24: =G24/E24 -> 22.904895 | G24: 57654.55 | H24: 14400 | N24: =SUM(G24:M24) -> 72054.55
C25: 취사난방용(취사)변동후 | D25: 4728786 | E25: 2.018854e+08 | F25: =G25/E25 -> 23.636013 | G25: 4.771766e+09 | H25: 372820500 | I25: 29852940 | N25: =SUM(G25:M25) -> 5.1744394e+09
C26: 취사난방용(난방)변동전 | D26: 62.615 | E26: 2672.156 | F26: =G26/E26 -> 22.879937 | G26: 61138.76 | N26: =SUM(G26:M26) -> 61138.76
C27: 취사난방용(난방)변동후 | D27: 24630351 | E27: 1.0515545e+09 | F27: =G27/E27 -> 23.635923 | G27: 2.4854461e+10 | N27: =SUM(G27:M27) -> 2.4854461e+10
C28: 사회복지시설할인액 | G28: -10498163 | N28: =SUM(G28:M28) -> -10498163
C29: 사회적배려 할인액 | G29: -7403757541 | N29: =SUM(G29:M29) -> -7403757541
C30: 검침착오분조정 | D30: -54762.568 | E30: -2337335.5 | G30: -55127937 | N30: =SUM(G30:M30) -> -55127937
A31: 검 | C31: 소계 | D31: =SUM(D24:D30) -> 29304496 | E31: =SUM(E24:E30) -> 1.2511078e+09 | F31: =G31/E31 -> 17.709875 | G31: =SUM(G24:G30) -> 22156962441 | H31: =SUM(H24:H30) -> 372834900 | I31: =SUM(I24:I30) -> 29852940 | J31: =SUM(J24:J30) -> 0 | K31: =SUM(K24:K30) -> 0 | L31: =SUM(L24:L30) -> 0 | M31: =SUM(M24:M30) -> 0 | N31: =SUM(N24:N30) -> 22559650281
C32: 개별난방용 변동전 | D32: 84.2814 | E32: 3597.4968 | F32: =G32/E32 -> 23.15105 | G32: 83285.83 | H32: 6300 | I32: 420 | N32: =SUM(G32:M32) -> 90005.83
C33: 개별난방용 변동후 | D33: 38158170 | E33: 1.6291582e+09 | F33: =G33/E33 -> 23.635901 | G33: 3.8506623e+10 | H33: 605933100 | I33: 138296220 | N33: =SUM(G33:M33) -> 3.9250852e+10
C34: 사회복지시설할인액 | G34: -3879105 | N34: =SUM(G34:M34) -> -3879105
C35: 검침착오분조정 | D35: -64082.435 | E35: -2735867.5 | G35: -64648444 | N35: =SUM(G35:M35) -> -64648444
C36: 소계 | D36: =SUM(D32:D35) -> 38094172 | E36: =SUM(E32:E35) -> 1.6264259e+09 | F36: =G36/E36 -> 23.633525 | G36: =SUM(G32:G35) -> 3.8438178e+10 | H36: =SUM(H32:H35) -> 605939400 | I36: =SUM(I32:I35) -> 138296640 | J36: 0 | K36: =SUM(K32:K35) -> 0 | L36: =SUM(L32:L35) -> 0 | M36: 0 | N36: =SUM(N32:N35) -> 3.9182414e+10
C37: 중앙난방용(중앙난방) | D37: 960251.35 | E37: 40953314 | F37: =G37/E37 -> 23.598099 | G37: 966420358 | I37: 1748800 | J37: 960800 | N37: =L37+K37+I37+H37+G37+J37 -> 969129958
C38: 냉난방용(주택)(중앙난방) | D38: 65182.522 | E38: 2779114.7 | F38: =G38/E38 -> 23.598095 | G38: 65581813 | I38: 270690 | J38: 98200 | N38: =L38+K38+I38+H38+G38+J38 -> 65950703
C39: 사회적배려 할인액 | G39: -42407621 | N39: =SUM(G39:M39) -> -42407621
C40: 소계 | D40: =SUM(D37:D39) -> 1025433.9 | E40: =SUM(E37:E39) -> 43732429 | F40: =G40/E40 -> 22.628392 | G40: =SUM(G37:G39) -> 989594550 | H40: =SUM(H39:H39) -> 0 | I40: =SUM(I37:I39) -> 2019490 | J40: =SUM(J37:J39) -> 1059000 | K40: =SUM(K37:K39) -> 0 | L40: =SUM(L37:L39) -> 0 | M40: 0 | N40: =SUM(N37:N39) -> 992673040
C41: 자가열전용 | D41: 426052 | E41: 18179827 | F41: =G41/E41 -> 23.5981 | G41: 429009378 | I41: 712570 | J41: 735000 | N41: =SUM(G41:M41) -> 430456948
C42: 자가열전용 변동후 | N42: =SUM(G42:M42) -> 0
C43: 사회적배려 할인액 | G43: -9622281 | N43: =SUM(G43:M43) -> -9622281
C44: 소계 | D44: =SUM(D41:D43) -> 426052 | E44: =SUM(E41:E43) -> 18179827 | F44: =G44/E44 -> 23.068816 | G44: =SUM(G41:G43) -> 419387097 | H44: =SUM(H41:H43) -> 0 | I44: =SUM(I41:I43) -> 712570 | J44: =SUM(J41:J43) -> 735000 | K44: =SUM(K41:K43) -> 0 | L44: =SUM(L41:L43) -> 0 | M44: 0 | N44: =SUM(N41:N43) -> 420834667
C45: 계 | D45: =D23+D31+D36+D44+D40 -> 69298542 | E45: =E23+E31+E36+E44+E40 -> 2.9585933e+09 | F45: =G45/E45 -> 21.1048 | G45: =G23+G31+G36+G44+G40 -> 6.2440521e+10 | H45: =H23+H31+H36+H44+H40 -> 1066037660 | I45: =I23+I31+I36+I44+I40 -> 185289820 | J45: =J23+J31+J36+J44+J40 -> 1794000 | K45: =K23+K31+K36+K44+K40 -> 0 | L45: =L23+L31+L36+L44+L40 -> 0 | M45: 0 | N45: =N23+N31+N36+N44+N40 -> 6.3693642e+10
...

Sheet 가스공사용(MJ)
B1: ="한국가스공사 제출용 구성비 ("&LEFT(총괄표!A2,9)&")" -> 한국가스공사 제출용 구성비 (2026년 4월 ) | S1: ※ 사회복지시설 정산('23.04.) 물량에서 3월 실사용분 제외 ※ 1. 복지시설에 대한 소급 정산(일반용 단가 적용) 소급 정산: '23.02. 완료 2. 소급대상청구년월: '22.12. ~ '23.01. - 참고사항: 청구월 기준 12월 물량 소급정산하는 대신 3월분 제외하기로 함 (4월 매출에 포함된 물량 일부 제외) ==> 신재홍 차장 (가스공사 전 담당자)와 사회복지시설 한시적할인 정산은 3월까지 하기로 함 ==> 김광연 주임 (가스공사 현 담당자)과도 해당 내용 확인 완료됨
B3: 구 분 | E3: 판 매 량 | F3: 개별소비세 | G3: 사회복지 | H3: 사회적배려 | I3: 차상위할인 | J3: 다자녀할인 | K3: 자가소모 | L3: 판 매 량 계 | M3: 구성비 | Q3: 자가소모
E4: (MJ) | F4: (MJ) | G4: (MJ) | H4: (MJ) | I4: (MJ) | J4: (MJ) | K4: (MJ) | L4: (MJ) | M4: (%) | Q4: (MJ)
B5: 주택용 | C5: 취사용 | E5: =ROUND((매출액표!E23-G5-H5-I5),0) -> 19134515 | G5: =ROUNDDOWN(('사회복지시설(MJ)'!D7),0) -> 12785 | L5: =ROUND((E5+G5+K5),0) -> 19147300 | M5: =ROUND(L5/$L$21*100,4) -> 0.4261
C6: 개별난방용 | E6: =ROUND((매출액표!E31+매출액표!E36-G6-H6-I6),0)+1 -> 2875037227 | G6: =ROUNDDOWN(('사회복지시설(MJ)'!D10),0) -> 2496488 | L6: =ROUND((E6+G6+K6),0) -> 2877533715 | M6: =ROUND(L6/$L$21*100,4) -> 64.0415 | T6: ※ 판매량+(개별소비세+사회복지+사회적배려+차상위할인)=매출액표 수량합계(자가소모포함되어있으므로 제외됨)
C7: 중앙난방용 | E7: =ROUND((매출액표!E40-G7-H7-I7),0) -> 43732429 | L7: =ROUND((E7+G7+K7),0) -> 43732429 | M7: =ROUND(L7/$L$21*100,4)-0.0002 -> 0.9731 | T7: ※ 업무난방과 냉방용은 구별요(5월~9월 냉방용적용)
C8: 자가열전용 | E8: =ROUND((매출액표!E44-G8-H8-I8),0) -> 18179827 | L8: =ROUND((E8+G8+K8),0) -> 18179827 | M8: =ROUND(L8/$L$21*100,4) -> 0.4046 | T8: ※ 매출내역서의 자가소모를 확인한다
C9: 소 계 | E9: =SUM(E5:E8) -> 2956083998 | F9: =SUM(F5:F8) -> 0 | G9: =SUM(G5:G8) -> 2509273 | H9: =SUM(H5:H8) -> 0 | I9: =SUM(I5:I8) -> 0 | J9: =SUM(J5:J8) -> 0 | L9: =SUM(L5:L8) -> 2958593271 | M9: =SUM(M5:M8) -> 65.8453 | Q9: =SUM(Q5:Q8) -> 0 | T9: ※ 개별소비세=특소세할인, 2022년 5월부터 판매량(MJ)에 포함 (가스공사 신재홍차장 확인 시, 구성비 공문으로 개소세 관련내용 확인사항 없음)
B10: 일반용 | C10: 일반용1 | E10: =ROUND((매출액표!E50-G10),0) -> 224872257 | G10: =ROUND(('사회복지시설(MJ)'!D21),0) -> 5564165 | K10: =ROUND(Q10,0) -> 19670 | L10: =ROUND((E10+F10+G10+K10+H10),0) -> 230456092 | M10: =ROUND(L10/$L$21*100,4) -> 5.129 | Q10: =Q12 -> 19670.409
C11: 일반용2 | E11: =ROUND((매출액표!E55-G11),0) -> 96655762 | L11: =ROUND((E11+F11+G11+K11+H11),0) -> 96655762 | M11: =ROUND(L11/$L$21*100,4) -> 2.1511 | Q11: 0
B12: 일 반 용 | E12: =SUM(E10:E11) -> 321528019 | G12: ='사회복지시설(MJ)'!D21 -> 5564164.5 | H12: =SUM(H10:H11) -> 0 | I12: =SUM(I10:I11) -> 0 | K12: =SUM(K10:K11) -> 19670 | L12: =SUM(E12:K12) -> 3.2711185e+08 | M12: =SUM(M10:M11) -> 7.2801 | Q12: =자가소모!E4 -> 19670.409
B13: 냉난방공조용 | E13: =ROUND((매출액표!E73-G13),0) -> 45309525 | G13: =('사회복지시설(MJ)'!D17) -> 835676.9 | K13: =ROUND(Q13,0) -> 70191 | L13: =ROUND((E13+G13+K13),0) -> 46215393 | M13: =ROUND(L13/$L$21*100,4) -> 1.0286 | Q13: =자가소모!E5 -> 70190.505
B14: 업무난방용 | E14: =ROUND((매출액표!E65-G14),0) -> 51267506 | G14: =('사회복지시설(MJ)'!D14) -> 18865234 | K14: =ROUNDDOWN(Q14,0) -> 5681 | L14: =ROUND((E14+G14+K14),0) -> 70138421 | M14: =ROUND(L14/$L$21*100,4) -> 1.561 | Q14: =자가소모!E3+자가소모!E8+자가소모!E9 -> 5681.3774
B15: 산 업 용 | E15: =ROUND((매출액표!E77-G15),0) -> 793600317 | K15: =ROUND(Q15,0) -> 0 | L15: =ROUND((E15+G15+K15),0) -> 793600317 | M15: =ROUND(L15/$L$21*100,4) -> 17.6621
B16: 수 송 용 | E16: =ROUND(((매출액표!E57+매출액표!E59)-G16),0) -> 247985958 | K16: =ROUND(Q16,0) -> 0 | L16: =ROUND((E16+G16+K16),0) -> 247985958 | M16: =ROUND(L16/$L$21*100,4) -> 5.5191
B17: 열 병 합 용 | E17: =ROUND((매출액표!E82-G17),0) -> 18612436 | K17: =ROUND(Q17,0) -> 103728 | L17: =ROUND((E17+G17+K17),0) -> 18716164 | M17: =ROUND(L17/$L$21*100,4) -> 0.4165 | Q17: =자가소모!E7 -> 103728.34
B18: 연료전지용 | E18: =ROUND((매출액표!E87-G18),0) -> 17878965 | K18: =ROUND(Q18,0) -> 0 | L18: =ROUND((E18+G18+K18),0) -> 17878965 | M18: =ROUND(L18/$L$21*100,4) -> 0.3979
B19: 열전용설비용 | E19: =ROUND((매출액표!E89-G19),0) -> 679333 | K19: =ROUNDDOWN(Q19,0) -> 9193846 | L19: =ROUND((E19+G19+K19),0) -> 9873179 | M19: =ROUND(L19/$L$21*100,4) -> 0.2197 | Q19: =자가소모!E6 -> 9193846.8
B20: 주한미군 | E20: =ROUND((매출액표!E92-G20),0) -> 3119149 | K20: =ROUND(Q20,0) -> 0 | L20: =ROUND((E20+G20+K20),0) -> 3119149 | M20: =ROUND(L20/$L$21*100,4) -> 0.0694
B21: 합 계 | E21: =SUM(E13:E20)+E12+E9 -> 4456065206 | F21: =F20+F17+F16+F15+F13+F12+F9+F14 -> 0 | G21: =ROUNDUP((G20+G17+G16+G15+G13+G12+G9+G14),0) -> 27774349 | H21: =H20+H17+H16+H15+H13+H12+H9+H14 -> 0 | I21: =I20+I17+I16+I15+I13+I12+I9+I14 -> 0 | J21: =J20+J19+J17+J16+J15+J14+J13+J12+J9 -> 0 | K21: =K20+K17+K16+K15+K13+K12+K9+K14+K19 -> 9393116 | L21: =ROUND((SUM(L13:L20)+L12+L9),0) -> 4493232671 | M21: =SUM(M5:M8,M12:M20) -> 99.9997 | Q21: =Q20+Q17+Q16+Q15+Q13+Q12+Q9+Q14+Q19 -> 9393117.4
E24: =ROUND(E21+G21,0) -> 4483839555 | K24: =ROUNDDOWN(Q21,0)=K21 -> FALSE | L24: =ROUND(L21-K21,0) -> 4483839555
E25: =ROUND(SUMIFS(매출액표!E:E,매출액표!$B:$B,"합계")-SUMIFS(매출액표!E:E,매출액표!$C:$C,"수송용(BIO)"),0) -> 4483839553 | L25: =ROUND(매출액표!E93-매출액표!E58,0) -> 4483839553
E26: =E24-E25 -> 2 | L26: =L24-L25 -> 2
B64: 구분 | E64: 판매열량(MJ) | H64: 5147 | I64: 4602
B65: 냉방물량(9월) | K65: ※ 관리납기와 일반납기의판매량전산실의뢰 (일반납기 청구작업이후)
B66: (월초) | C66: 관리납기(변동) | K66: - 9월판매실적 작성을 위한 냉방용 상품에대한 변동검침사용량 자료 요청
B67: (청구일) | C67: 일반납기(일수)
B68: 계 | K68: ※ 계절이 바뀌는 4월(기타)↔5월(하절기) 냉방집계 조정
K69: - 시기: 2022년 4월 매출분부터
K70: - 사유: 기존 9월, 10월만 물량조정했으나 가스공사 이의제기로 4월, 5월도 시행하게 됨
K71: - 방법: 5월 일반납기 청구작업 후 냉난방물량(업무, 주택) 일반납기(4/30까지 일할계산), 관리납기(변동검침 4/30까지) ==> 냉난방공조용에 4월 기타월 사용분 추가(+) , 5월 차감 (-)
K74: ※ 9월 판매량에 냉방용을 추가청구하여 10월 판매량에서 차감함
K75: ※ 매출건
K76: - 9월매출은일반납기의 경우 (8/1~8 부터9/1~8사용량)이므로 9월사용분(10월 청구분) 포함
K77: - 관리납기는 (8/16~9/16)까지이나 관리납기는 10월에 변동검침을 했으므로, 9/16~10초까지 변동검침 물량 포함
K79: ※ 사 유 : 냉난방의 경우 10월 하절기ㅡ> 기타 단가로 변동됨에 따라 도매요금인상이 많이 이루어지므로 보전차원에서 9월 정산
K80: [5월의 경우 (기타 ㅡ> 하절기 단가 변동)는 회사 손해가 없으므로 물량정산 안함.]
K82: ※ 9월 냉방용집계확인 할 것
K83: - 냉방용 (+), 10월매출(-) 변동검침확인할 것
K84: - 10/14청구작업후 자료요청할것
...

Sheet 사회복지시설(MJ)
A2: ="사회복지시설 용도별 판매량 ( "&LEFT(총괄표!A2,9)&")" -> 사회복지시설 용도별 판매량 ( 2026년 4월 )
A4: 구분 | C4: 세대수 | D4: 판매량(MJ) | E4: 금액(원) | G4: 차액
E5: 미적용 | F5: 적용
A6: 주 택 용 | B6: 취사용
D7: =SUMIFS(청구할인정산관리!$D:$D,청구할인정산관리!$B:$B,"취사용") -> 12785.735 | E7: =SUMIFS(청구할인정산관리!$E:$E,청구할인정산관리!$B:$B,"취사용") -> 302182 | F7: =SUMIFS(청구할인정산관리!$G:$G,청구할인정산관리!$B:$B,"취사용") -> 230622 | G7: =E7-F7 -> 71560 | H7: =G7/E7 -> 0.23681093
B9: 개 별 난방용
D10: =SUMIFS(청구할인정산관리!$D:$D,청구할인정산관리!$B:$B,"취사난방용")+SUMIFS(청구할인정산관리!$D:$D,청구할인정산관리!$B:$B,"개별난방용") -> 2496488.9 | E10: =SUMIFS(청구할인정산관리!$E:$E,청구할인정산관리!$B:$B,"취사난방용")+SUMIFS(청구할인정산관리!$E:$E,청구할인정산관리!$B:$B,"개별난방용") -> 59006759 | F10: =SUMIFS(청구할인정산관리!$G:$G,청구할인정산관리!$B:$B,"취사난방용")+SUMIFS(청구할인정산관리!$G:$G,청구할인정산관리!$B:$B,"개별난방용") -> 44629491 | G10: =E10-F10 -> 14377268 | H10: =G10/E10 -> 0.2436546
A12: 소 계 | D12: =D10+D7 -> 2509274.6 | E12: =E10+E7 -> 59308941 | F12: =F10+F7 -> 44860113 | G12: =G10+G7 -> 14448828 | H12: =G12/E12 -> 0.24361973
A13: 업 무 용 | B13: 업 무 난방용
D14: =SUMIFS(청구할인정산관리!$D:$D,청구할인정산관리!$B:$B,"업무난방용") -> 18865234 | E14: =SUMIFS(청구할인정산관리!$E:$E,청구할인정산관리!$B:$B,"업무난방용") -> 425494901 | F14: =SUMIFS(청구할인정산관리!$G:$G,청구할인정산관리!$B:$B,"업무난방용") -> 338110139 | G14: =E14-F14 -> 87384762 | H14: =G14/E14 -> 0.20537205
B16: 냉난방용 (업무)
D17: =SUMIFS(청구할인정산관리!$D:$D,청구할인정산관리!$B:$B,"냉난방용(업무)") -> 835676.9 | E17: =SUMIFS(청구할인정산관리!$E:$E,청구할인정산관리!$B:$B,"냉난방용(업무)") -> 18051049 | F17: =SUMIFS(청구할인정산관리!$G:$G,청구할인정산관리!$B:$B,"냉난방용(업무)") -> 15072795 | G17: =E17-F17 -> 2978254 | H17: =G17/E17 -> 0.16499063
A19: 소 계 | D19: =D14+D17 -> 19700911 | E19: =E14+E17 -> 443545950 | F19: =F14+F17 -> 353182934 | G19: =G14+G17 -> 90363016 | H19: =G19/E19 -> 0.20372865
A20: 일 반 용
D21: =SUMIFS(청구할인정산관리!$D:$D,청구할인정산관리!$B:$B,"일반용(1)")+SUMIFS(청구할인정산관리!$D:$D,청구할인정산관리!$B:$B,"일반용(2)") -> 5564164.5 | E21: =SUMIFS(청구할인정산관리!$E:$E,청구할인정산관리!$B:$B,"일반용(1)")+SUMIFS(청구할인정산관리!$E:$E,청구할인정산관리!$B:$B,"일반용(2)") -> 126774041 | F21: =SUMIFS(청구할인정산관리!$G:$G,청구할인정산관리!$B:$B,"일반용(1)")+SUMIFS(청구할인정산관리!$G:$G,청구할인정산관리!$B:$B,"일반용(2)") -> 100170326 | G21: =E21-F21 -> 26603715
A23: 소 계 | D23: =SUM(D20:D22) -> 5564164.5 | E23: =SUM(E20:E22) -> 126774041 | F23: =SUM(F20:F22) -> 100170326 | G23: =SUM(G20:G22) -> 26603715
A24: 연료전지용
G25: =E25-F25 -> 0
A27: 소 계 | D27: =SUM(D24:D26) -> 0 | E27: =SUM(E24:E26) -> 0 | F27: =SUM(F24:F26) -> 0 | G27: =SUM(G24:G26) -> 0
A28: 합 계 | D28: =D23+D12+D19+D27 -> 27774350 | E28: =E23+E12+E19+E27 -> 629628932 | F28: =F23+F12+F19+F27 -> 498213373 | G28: =G23+G12+G19+G27 -> 131415559 | H28: =G28/E28 -> 0.20871906
D39: 정산관리=>청구할인정산관리=>정산년월:마감월, 원가정산항목:사회적복지할인

Sheet 자가소모
B1: 3월
C2: 상품 | D2: 사용량(㎥) | E2: 사용열랑(MJ) | F2: 자가소모량 확인대장
B3: 자가소모 | C3: 업무난방용 | F3: 경산지사(업무난방-->냉난방용으로 상품변경)
B4: 자가소모 | C4: 일반용 | D4: 461 | E4: 19670.409 | F4: 본사 일반용
B5: 자가소모 | C5: 냉난방용 | D5: 1645 | E5: 70190.505 | F5: 본사 냉난방용+서부지사+수성안전팀
B6: 자가소모 | C6: 열전용설비용 | D6: 215469 | E6: 9193846.8 | F6: 1~3번 보일러 합계
B7: 자가소모 | C7: 열병합용1 | D7: 2431 | E7: 103728.34 | F7: 세너지 (1번 ~ 3번발전기) 계-보일러합계
B8: 자가소모 | C8: 퍼지량(CNG) | F8: 앞으로 없음. 다 없앰. 관리비가 더 많이 들어서?
B9: 자가소모 | C9: 퍼지량(업무난방) | D9: 133.15 | E9: 5681.3774 | F9: 퍼지량 계 | G9: 총무결재본
B10: 자가소모(LNG) 소계 | D10: =SUM(D3:D9) -> 220139.15 | E10: =SUM(E3:E9) -> 9393117.4
B11: 자가소모 | C11: 수송용 (BIO) | D11: 0 | E11: 0
B12: 자가소모 합계 | D12: =SUM(D3:D9) -> 220139.15 | E12: =SUM(E3:E9) -> 9393117.4 | F12: 총계와 같아야됨
A16: .
A17: (샘플참고)
F41: 왼쪽 자동 계산 됨

Sheet 판매량-월별추이
B1: 1. 2026년 판매량 현황
AI2: (단위:천MJ)
B3: 용 도 [판매전수] | C3: 판 매 실 적 | F3: 판 매 실 적 | N3: 판 매 실 적 | Q3: 판 매 실 적 | Y3: 판 매 실 적 | AB3: 판 매 실 적
C4: 판매량 | D4: 사업계획 | F4: 사업계획 | G4: 전월누계(1~11월) | I4: 전년동월 | K4: 전년동월 | M4: 구성비 | N4: 판매량 | O4: 사업계획 | Q4: 사업계획 | R4: =MID(총괄표!A2,7,3) -> 4월 | T4: 전년동월 | V4: 전년동월 | X4: 구성비 | Y4: 판매량 | Z4: 사업계획 | AB4: 사업계획 | AC4: 누 계 | AE4: 전년동월 | AG4: 전년동월 | AI4: 구성비
D5: 차이 | E5: 사용량 | G5: 차이 | H5: 사용량 | I5: 차이 | J5: 대비(%) | K5: 차이 | L5: 사용량 | O5: 차이 | P5: 사용량 | R5: 차이 | S5: 사용량 | T5: 차이 | U5: 대비(%) | V5: 차이 | W5: 사용량 | Z5: 차이 | AA5: 사용량 | AC5: 차이 | AD5: 사용량 | AE5: 차이 | AF5: 대비(%) | AG5: 차이 | AH5: 사용량
B6: 주 택 용 | C6: =총괄표!$X$11 -> 14484479 | E6: =총괄표!V11 -> 14326884 | F6: =E6 -> 14326884 | H6: =C6 -> 14484479 | I6: =K7 -> -545701 | J6: =L7 -> 0.96369298 | L6: =총괄표!Y11 -> 15030180 | M6: =C6/$C$18 -> 0.72995229 | N6: =총괄표!E11 -> 2958593 | P6: =총괄표!C11 -> 3068534 | Q6: =P6 -> 3068534 | R6: =O7 -> -109941 | S6: =N6 -> 2958593 | T6: =V7 -> -61755 | U6: =W7 -> 0.97955368 | W6: =총괄표!G11 -> 3020348 | X6: =총괄표!I11 -> 65.8 | Y6: =C6+N6 -> 17443072 | AA6: =E6+P6 -> 17395418 | AB6: =AA6 -> 17395418 | AC6: =Z7 -> 47654 | AD6: =Y6 -> 17443072 | AE6: =AG7 -> -607456 | AF6: =AH7 -> 0.96634691 | AH6: =L6+W6 -> 18050528 | AI6: =총괄표!P11 -> 71.6
B7: =VLOOKUP(B6,데이터!$D$33:$E$38,2,FALSE) -> 1151036 | D7: =C6-E6 -> 157595 | E7: =C6/E6 -> 1.0109999 | G7: =H6-F6 -> 157595 | H7: =H6/E6 -> 1.0109999 | K7: =C6-L6 -> -545701 | L7: =C6/L6 -> 0.96369298 | O7: =N6-P6 -> -109941 | P7: =N6/P6 -> 0.96417149 | R7: =(S7-1) -> -0.03582851 | S7: =P7 -> 0.96417149 | T7: =U6-1 -> -0.020446319 | V7: =N6-W6 -> -61755 | W7: =N6/W6 -> 0.97955368 | Z7: =Y6-AA6 -> 47654 | AA7: =Y6/AA6 -> 1.0027395 | AC7: =AD7-1 -> 0.002739457 | AD7: =AA7 -> 1.0027395 | AE7: =AF6-1 -> -0.033653088 | AG7: =Y6-AH6 -> -607456 | AH7: =Y6/AH6 -> 0.96634691
B8: 일 반 용 | C8: =총괄표!$X$12 -> 1098408 | E8: =총괄표!V12 -> 1119107 | F8: =E8 -> 1119107 | H8: =C8 -> 1098408 | I8: =K9 -> -14276 | J8: =L9 -> 0.98716976 | L8: =총괄표!Y12 -> 1112684 | M8: =C8/$C$18 -> 0.0553548 | N8: =총괄표!E12 -> 327092 | P8: =총괄표!C12 -> 331181 | Q8: =P8 -> 331181 | R8: =O9 -> -4089 | S8: =N8 -> 327092 | T8: =V9 -> -2057 | U8: =W9 -> 0.99375055 | W8: =총괄표!G12 -> 329149 | X8: =총괄표!I12 -> 7.3 | Y8: =C8+N8 -> 1425500 | AA8: =E8+P8 -> 1450288 | AB8: =AA8 -> 1450288 | AC8: =Z9 -> -24788 | AD8: =Y8 -> 1425500 | AE8: =AG9 -> -16333 | AF8: =AH9 -> 0.98867206 | AH8: =L8+W8 -> 1441833 | AI8: =총괄표!P12 -> 5.9
B9: =VLOOKUP(B8,데이터!$D$33:$E$38,2,FALSE) -> 21352 | D9: =C8-E8 -> -20699 | E9: =C8/E8 -> 0.981504 | G9: =H8-F8 -> -20699 | H9: =H8/E8 -> 0.981504 | K9: =C8-L8 -> -14276 | L9: =C8/L8 -> 0.98716976 | O9: =N8-P8 -> -4089 | P9: =N8/P8 -> 0.98765328 | R9: =S9-1 -> -0.012346723 | S9: =P9 -> 0.98765328 | T9: =U8-1 -> -0.0062494493 | V9: =N8-W8 -> -2057 | W9: =N8/W8 -> 0.99375055 | Z9: =Y8-AA8 -> -24788 | AA9: =Y8/AA8 -> 0.98290822 | AC9: =AD9-1 -> -0.017091778 | AD9: =AA9 -> 0.98290822 | AE9: =AF8-1 -> -0.011327942 | AG9: =Y8-AH8 -> -16333 | AH9: =Y8/AH8 -> 0.98867206
B10: 업무냉난방용 | C10: =총괄표!$X$13+총괄표!$X$14 -> 823283 | E10: =총괄표!V13+총괄표!V14 -> 809579 | F10: =E10 -> 809579 | H10: =C10 -> 823283 | I10: =K11 -> -30053 | J10: =L11 -> 0.96478175 | L10: =총괄표!Y13+총괄표!Y14 -> 853336 | M10: =C10/$C$18 -> 0.041489743 | N10: =총괄표!E13+총괄표!E14 -> 116278 | P10: =총괄표!C13+총괄표!C14 -> 144841 | Q10: =P10 -> 144841 | R10: =O11 -> -28563 | S10: =N10 -> 116278 | T10: =V11 -> -6213 | U10: =W11 -> 0.94927791 | W10: =총괄표!G13+총괄표!G14 -> 122491 | X10: =SUM(총괄표!I13:I14) -> 2.6 | Y10: =C10+N10 -> 939561 | AA10: =E10+P10 -> 954420 | AB10: =AA10 -> 954420 | AC10: =Z11 -> -14859 | AD10: =Y10 -> 939561 | AE10: =AG11 -> -36266 | AF10: =AH11 -> 0.96283563 | AH10: =L10+W10 -> 975827 | AI10: =SUM(총괄표!P13:P14) -> 3.9
B11: =VLOOKUP(B10,데이터!$D$33:$E$38,2,FALSE) -> 8625 | D11: =C10-E10 -> 13704 | E11: =C10/E10 -> 1.0169273 | G11: =H10-F10 -> 13704 | H11: =H10/E10 -> 1.0169273 | K11: =C10-L10 -> -30053 | L11: =C10/L10 -> 0.96478175 | O11: =N10-P10 -> -28563 | P11: =N10/P10 -> 0.80279755 | R11: =S11-1 -> -0.19720245 | S11: =P11 -> 0.80279755 | T11: =U10-1 -> -0.050722094 | V11: =N10-W10 -> -6213 | W11: =N10/W10 -> 0.94927791 | Z11: =Y10-AA10 -> -14859 | AA11: =Y10/AA10 -> 0.98443138 | AC11: =AD11-1 -> -0.015568618 | AD11: =AA11 -> 0.98443138 | AE11: =AF10-1 -> -0.037164374 | AG11: =Y10-AH10 -> -36266 | AH11: =Y10/AH10 -> 0.96283563
B12: 산 업 용 | C12: =총괄표!$X$15 -> 2511258 | E12: =총괄표!V15 -> 2505824 | F12: =E12 -> 2505824 | H12: =C12 -> 2511258 | I12: =K13 -> -60880 | J12: =L13 -> 0.97633097 | L12: =총괄표!Y15 -> 2572138 | M12: =C12/$C$18 -> 0.12655605 | N12: =총괄표!E15 -> 793601 | P12: =총괄표!C15 -> 786084 | Q12: =P12 -> 786084 | R12: =O13 -> 7517 | S12: =N12 -> 793601 | T12: =V13 -> -17459 | U12: =W13 -> 0.97847385 | W12: =총괄표!G15 -> 811060 | X12: =총괄표!I15 -> 17.6 | Y12: =C12+N12 -> 3304859 | AA12: =E12+P12 -> 3291908 | AB12: =AA12 -> 3291908 | AC12: =Z13 -> 12951 | AD12: =Y12 -> 3304859 | AE12: =AG13 -> -78339 | AF12: =AH13 -> 0.97684469 | AH12: =L12+W12 -> 3383198 | AI12: =총괄표!P15 -> 13.6
B13: =VLOOKUP(B12,데이터!$D$33:$E$38,2,FALSE) -> 1109 | D13: =C12-E12 -> 5434 | E13: =C12/E12 -> 1.0021685 | G13: =H12-F12 -> 5434 | H13: =H12/E12 -> 1.0021685 | K13: =C12-L12 -> -60880 | L13: =C12/L12 -> 0.97633097 | O13: =N12-P12 -> 7517 | P13: =N12/P12 -> 1.0095626 | R13: =S13-1 -> 0.0095625913 | S13: =P13 -> 1.0095626 | T13: =U12-1 -> -0.021526151 | V13: =N12-W12 -> -17459 | W13: =N12/W12 -> 0.97847385 | Z13: =Y12-AA12 -> 12951 | AA13: =Y12/AA12 -> 1.0039342 | AC13: =AD13-1 -> 0.0039341926 | AD13: =AA13 -> 1.0039342 | AE13: =AF12-1 -> -0.02315531 | AG13: =Y12-AH12 -> -78339 | AH13: =Y12/AH12 -> 0.97684469
B14: 수 송 용 | C14: =총괄표!$X$16+총괄표!$X$17 -> 766979 | E14: =총괄표!V16+총괄표!V17 -> 732106 | F14: =E14 -> 732106 | H14: =C14 -> 766979 | I14: =K15 -> 616 | J14: =L15 -> 1.0008038 | L14: =총괄표!Y16+총괄표!Y17 -> 766363 | M14: =C14/$C$18 -> 0.038652276 | N14: =총괄표!E16+총괄표!E17 -> 260540 | P14: =총괄표!C16+총괄표!C17 -> 251268 | Q14: =P14 -> 251268 | R14: =O15 -> 9272 | S14: =N14 -> 260540 | T14: =V15 -> -2573 | U14: =W15 -> 0.99022093 | W14: =총괄표!G16+총괄표!G17 -> 263113 | X14: =SUM(총괄표!I16:I17) -> 5.8 | Y14: =C14+N14 -> 1027519 | AA14: =E14+P14 -> 983374 | AB14: =AA14 -> 983374 | AC14: =Z15 -> 44145 | AD14: =Y14 -> 1027519 | AE14: =AG15 -> -1957 | AF14: =AH15 -> 0.99809903 | AH14: =L14+W14 -> 1029476 | AI14: =SUM(총괄표!P16:P17) -> 4.2
B15: =VLOOKUP(B14,데이터!$D$33:$E$38,2,FALSE) -> 98 | D15: =C14-E14 -> 34873 | E15: =C14/E14 -> 1.0476338 | G15: =H14-F14 -> 34873 | H15: =H14/E14 -> 1.0476338 | K15: =C14-L14 -> 616 | L15: =C14/L14 -> 1.0008038 | O15: =N14-P14 -> 9272 | P15: =N14/P14 -> 1.0369008 | R15: =S15-1 -> 0.036900839 | S15: =P15 -> 1.0369008 | T15: =U14-1 -> -0.0097790683 | V15: =N14-W14 -> -2573 | W15: =N14/W14 -> 0.99022093 | Z15: =Y14-AA14 -> 44145 | AA15: =Y14/AA14 -> 1.0448914 | AC15: =AD15-1 -> 0.044891364 | AD15: =AA15 -> 1.0448914 | AE15: =AF14-1 -> -0.0019009671 | AG15: =Y14-AH14 -> -1957 | AH15: =Y14/AH14 -> 0.99809903
B16: 기 타 | C16: =총괄표!X18+총괄표!X19+총괄표!X20+총괄표!X21 -> 158642 | E16: =총괄표!V18+총괄표!V19+총괄표!V20+총괄표!V21 -> 155556 | F16: =E16 -> 155556 | H16: =C16 -> 158642 | I16: =K17 -> -3228 | J16: =L17 -> 0.98005807 | L16: =총괄표!Y18+총괄표!Y19+총괄표!Y20+총괄표!Y21 -> 161870 | M16: =C16/$C$18 -> 0.0079948399 | N16: =총괄표!E18+총괄표!E19+총괄표!E20+총괄표!E21 -> 40289 | P16: =총괄표!C18+총괄표!C19+총괄표!C20+총괄표!C21 -> 39275 | Q16: =P16 -> 39275 | R16: =O17 -> 1014 | S16: =N16 -> 40289 | T16: =V17 -> -2933 | U16: =W17 -> 0.93214104 | W16: =총괄표!G18+총괄표!G19+총괄표!G20+총괄표!G21 -> 43222 | X16: =SUM(총괄표!I18:I21) -> 0.9 | Y16: =C16+N16 -> 198931 | AA16: =E16+P16 -> 194831 | AB16: =AA16 -> 194831 | AC16: =Z17 -> 4100 | AD16: =Y16 -> 198931 | AE16: =AG17 -> -6161 | AF16: =AH17 -> 0.96995982 | AH16: =L16+W16 -> 205092 | AI16: =SUM(총괄표!P18:P21) -> 0.8
B17: =VLOOKUP(B16,데이터!$D$33:$E$38,2,FALSE) -> 341 | D17: =C16-E16 -> 3086 | E17: =C16/E16 -> 1.0198385 | G17: =H16-F16 -> 3086 | H17: =H16/F16 -> 1.0198385 | K17: =C16-L16 -> -3228 | L17: =C16/L16 -> 0.98005807 | O17: =N16-P16 -> 1014 | P17: =N16/P16 -> 1.025818 | R17: =S17-1 -> 0.02581795 | S17: =P17 -> 1.025818 | T17: =U16-1 -> -0.067858961 | V17: =N16-W16 -> -2933 | W17: =N16/W16 -> 0.93214104 | Z17: =Y16-AA16 -> 4100 | AA17: =Y16/AA16 -> 1.0210439 | AC17: =AD17-1 -> 0.021043879 | AD17: =AA17 -> 1.0210439 | AE17: =AF16-1 -> -0.030040177 | AG17: =Y16-AH16 -> -6161 | AH17: =Y16/AH16 -> 0.96995982
B18: 총 합 계 | C18: =SUM(C6:C17) -> 19843049 | E18: =E6+E8+E10+E12+E14+E16 -> 19649056 | F18: =SUM(F6:F17) -> 19649056 | H18: =H6+H8+H10+H12+H14+H16 -> 19843049 | I18: =K19 -> -653522 | J18: =L19 -> 0.96811554 | L18: =L6+L8+L10+L12+L14+L16 -> 20496571 | N18: =SUM(N6:N17) -> 4496393 | P18: =P6+P8+P10+P12+P14+P16 -> 4621183 | Q18: =SUM(Q6:Q17) -> 4621183 | R18: =O19 -> -124790 | S18: =S6+'판매량-월별추이'!S8+S10+S12+S14+S16 -> 4496393 | T18: =V19 -> -92990 | U18: =W19 -> 0.97973802 | W18: =W6+W8+W10+W12+W14+W16 -> 4589383 | Y18: =SUM(Y6:Y17) -> 24339442 | AA18: =AA6+AA8+AA10+AA12+AA14+AA16 -> 24270239 | AB18: =SUM(AB6:AB17) -> 24270239 | AC18: =Z19 -> 69203 | AD18: =AD6+AD8+AD10+AD12+AD14+AD16 -> 24339442 | AE18: =AG19 -> -746512 | AF18: =AH19 -> 0.97024183 | AH18: =AH6+AH8+AH10+AH12+AH14+AH16 -> 25085954
B19: =IF(B7+B9+B11+B13+B15+B17=데이터!E39,B7+B9+B11+B13+B15+B17,"") -> 1182561 | D19: =C18-E18 -> 193993 | E19: =C18/E18 -> 1.0098729 | G19: =H18-F18 -> 193993 | H19: =H18/F18 -> 1.0098729 | K19: =C18-L18 -> -653522 | L19: =C18/L18 -> 0.96811554 | O19: =N18-P18 -> -124790 | P19: =N18/P18 -> 0.97299609 | R19: =S19-1 -> -0.027003908 | S19: =P19 -> 0.97299609 | T19: =U18-1 -> -0.020261983 | V19: =N18-W18 -> -92990 | W19: =N18/W18 -> 0.97973802 | Z19: =Y18-AA18 -> 69203 | AA19: =Y18/AA18 -> 1.0028514 | AC19: =AD19-1 -> 0.0028513522 | AD19: =AA19 -> 1.0028514 | AE19: =AF18-1 -> -0.029758167 | AG19: =Y18-AH18 -> -746512 | AH19: =Y18/AH18 -> 0.97024183
B21: ※ 기타 : 열병합용, 연료전지, 열전용설비(주택용외), 주한미군
B22: ※ 구성비는 판매량 정산서 기준으로 작성되었으며 한국가스공사 정산시 수송용(BIO)은 제외되고 자가소모분이 추가 됨 | AL22: =SUM(AD19) -> 1.0028514
AL23: =SUM(S19) -> 0.97299609

Sheet 판매금액-월별추이
B1: 2. 2024년 판매금액 현황
N2: (단위:백만원)
B3: 용 도 | C3: 판 매 금 액 | I3: 판 매 금 액
C4: 사업계획 | D4: ='판매량-월별추이'!R4 -> 4월 | F4: 전년동월 | H4: 구성비 | I4: 사업계획 | J4: 누 계 | L4: 전년동월 | N4: 구성비
D5: 차이 | E5: 금액 | F5: 차이 | G5: 대비(%) | J5: 차이 | K5: 금 액 | L5: 차이 | M5: 대비(%)
B6: 주 택 용 | C6: =총괄표!C35 -> 66176690 | D6: =E6-C6 -> -2670131 | E6: =총괄표!D35 -> 63506559 | F6: =총괄표!D35-총괄표!F35 -> -1526268 | G6: =E6/총괄표!F35 -> 0.97653081 | H6: =데이터!B24 -> 67.3 | I6: =총괄표!J35 -> 379266379 | J6: =K6-I6 -> 808387 | K6: =총괄표!K35 -> 380074766 | L6: =총괄표!K35-총괄표!M35 -> -13932917 | M6: =K6/총괄표!M35 -> 0.96463796 | N6: =데이터!D24 -> 73.6
D7: =E7-1 -> -0.040348512 | E7: =E6/C6 -> 0.95965149 | F7: =G6-1 -> -0.023469193 | J7: =K7-1 -> 0.0021314491 | K7: =K6/I6 -> 1.0021314 | L7: =M6-1 -> -0.035362043
B8: 일 반 용 | C8: =총괄표!C36 -> 7545660 | D8: =E8-C8 -> -119660 | E8: =총괄표!D36 -> 7426000 | F8: =총괄표!D36-총괄표!F36 -> -5000 | G8: =E8/총괄표!F36 -> 0.99932714 | H8: =데이터!B25 -> 7.9 | I8: =총괄표!J36 -> 33043503 | J8: =K8-I8 -> -688503 | K8: =총괄표!K36 -> 32355000 | L8: =총괄표!K36-총괄표!M36 -> -202204.86 | M8: =K8/총괄표!M36 -> 0.99378924 | N8: =데이터!D25 -> 6.3
D9: =E9-1 -> -0.015858122 | E9: =E8/C8 -> 0.98414188 | F9: =G8-1 -> -0.00067285695 | J9: =K9-1 -> -0.020836259 | K9: =K8/I8 -> 0.97916374 | L9: =M8-1 -> -0.0062107562
B10: 업무냉난방용 | C10: =총괄표!C37+총괄표!C38 -> 2579557 | D10: =E10-C10 -> -86656 | E10: =총괄표!D37+총괄표!D38 -> 2492901 | F10: =(총괄표!D37+총괄표!D38)-(총괄표!F37+총괄표!F38) -> -475469 | G10: =E10/(총괄표!F37+총괄표!F38) -> 0.83982152 | H10: =데이터!B26 -> 2.7 | I10: =총괄표!J37+총괄표!J38 -> 20102522 | J10: =K10-I10 -> 334448 | K10: =총괄표!K37+총괄표!K38 -> 20436970 | L10: =(총괄표!K37+총괄표!K38)-(총괄표!M37+총괄표!M38) -> -3858378.8 | M10: =K10/(총괄표!M37+총괄표!M38) -> 0.84118858 | N10: =데이터!D26 -> 3.9
D11: =E11-1 -> -0.033593365 | E11: =E10/C10 -> 0.96640663 | F11: =G10-1 -> -0.16017848 | J11: =K11-1 -> 0.016637116 | K11: =K10/I10 -> 1.0166371 | L11: =M10-1 -> -0.15881142
B12: 산 업 용 | C12: =총괄표!C39 -> 13643902 | D12: =E12-C12 -> 821141 | E12: =총괄표!D39 -> 14465043 | F12: =총괄표!D39-총괄표!F39 -> -2786162 | G12: =E12/총괄표!F39 -> 0.83849464 | H12: =데이터!B27 -> 15.4 | I12: =총괄표!J39 -> 57136987 | J12: =K12-I12 -> 2600683 | K12: =총괄표!K39 -> 59737670 | L12: =총괄표!K39-총괄표!M39 -> -12149046 | M12: =K12/총괄표!M39 -> 0.83099734 | N12: =데이터!D27 -> 11.5
D13: =E13-1 -> 0.060183736 | E13: =E12/C12 -> 1.0601837 | F13: =G12-1 -> -0.16150536 | J13: =K13-1 -> 0.045516628 | K13: =K12/I12 -> 1.0455166 | L13: =M12-1 -> -0.16900266
B14: 수 송 용 | C14: =SUM(총괄표!C40:C41) -> 5092272 | D14: =E14-C14 -> 407805 | E14: =SUM(총괄표!D40:D41) -> 5500077 | F14: =(총괄표!D40+총괄표!D41)-(총괄표!F40+총괄표!F41) -> -913625 | G14: =E14/(총괄표!F40+총괄표!F41) -> 0.85755107 | H14: =데이터!B28 -> 5.9 | I14: =SUM(총괄표!J40:J41) -> 19929349 | J14: =K14-I14 -> 1455271 | K14: =SUM(총괄표!K40:K41) -> 21384620 | L14: =(총괄표!K40+총괄표!K41)-(총괄표!M40+총괄표!M41) -> -3286883.8 | M14: =K14/(총괄표!M40+총괄표!M41) -> 0.86677408 | N14: =데이터!D28 -> 4.1
D15: =E15-1 -> 0.080083114 | E15: =E14/C14 -> 1.0800831 | F15: =G14-1 -> -0.14244893 | J15: =K15-1 -> 0.073021502 | K15: =K14/I14 -> 1.0730215 | L15: =M14-1 -> -0.13322592
B16: 기 타 | C16: =총괄표!C42+총괄표!C43+총괄표!C44+총괄표!C45 -> 663700 | D16: =E16-C16 -> 49864 | E16: =총괄표!D42+총괄표!D43+총괄표!D44+총괄표!D45 -> 713564 | F16: =(총괄표!D42+총괄표!D43+총괄표!D44+총괄표!D45)-(총괄표!F42+총괄표!F43+총괄표!F44+총괄표!F45) -> -151765 | G16: =E16/(총괄표!F42+총괄표!F43+총괄표!F44+총괄표!F45) -> 0.82461584 | H16: =100-SUM(H6:H15) -> 0.8 | I16: =총괄표!J42+총괄표!J43+총괄표!J44+총괄표!J45 -> 3418879 | J16: =K16-I16 -> 123053 | K16: =총괄표!K42+총괄표!K43+총괄표!K44+총괄표!K45 -> 3541932 | L16: =(총괄표!K42+총괄표!K43+총괄표!K44+총괄표!K45)-(총괄표!M42+총괄표!M43+총괄표!M44+총괄표!M45) -> -714269.39 | M16: =K16/(총괄표!M42+총괄표!M43+총괄표!M44+총괄표!M45) -> 0.83218149 | N16: =100-SUM(N6:N15) -> 0.6
D17: =E17-1 -> 0.07513033 | E17: =E16/C16 -> 1.0751303 | F17: =G16-1 -> -0.17538416 | J17: =K17-1 -> 0.035992207 | K17: =K16/I16 -> 1.0359922 | L17: =M16-1 -> -0.16781851
B18: 총 합 계 | C18: =SUM(C6:C17) -> 95701781 | D18: =E18-C18 -> -1597637 | E18: =E6+E8+E10+E12+E14+E16 -> 94104144 | F18: =F6+F8+F10+F12+F14+F16 -> -5858289 | G18: =(E18/총괄표!F47) -> 0.94139509 | I18: =SUM(I6:I17) -> 512897619 | J18: =K18-I18 -> 4633339 | K18: =K6+K8+K10+K12+K14+K16 -> 517530958 | L18: =L6+L8+L10+L12+L14+L16 -> -34143700 | M18: =(K18/총괄표!M47) -> 0.93810899
D19: =D18/C18 -> -0.016693911 | E19: =E18/C18 -> 0.98330609 | F19: =G18-1 -> -0.058604906 | J19: =J18/I18 -> 0.0090336528 | K19: =K18/I18 -> 1.0090337 | L19: =M18-1 -> -0.061891006

Sheet 데이터
A2: 판매량
A3: ='판매량-월별추이'!R4 -> 4월 | C3: ='판매량-월별추이'!AC4 -> 누 계 | F3: 계획 | G3: 실적
A4: 계획 | B4: 실적 | C4: 계획 | D4: 실적 | E4: 당월 | F4: =A5 -> 4621183 | G4: =B5 -> 4496393
A5: =총괄표!C23 -> 4621183 | B5: =총괄표!E23 -> 4496393 | C5: =총괄표!J23 -> 24270239 | D5: =총괄표!L23 -> 24339442 | E5: 누계 | F5: =C5 -> 24270239 | G5: =D5 -> 24339442
A9: 구성비
A10: =A3 -> 4월 | B10: 구성비 | C10: =C3 -> 누 계 | D10: 구성비
A11: 주 택 용 | B11: =총괄표!I11 -> 65.8 | C11: 주 택 용 | D11: =총괄표!P11 -> 71.6
A12: 일 반 용 | B12: =총괄표!I12 -> 7.3 | C12: 일 반 용 | D12: =총괄표!P12 -> 5.9
A13: 업무냉방용 | B13: =총괄표!I13+총괄표!I14 -> 2.6 | C13: 업무냉방용 | D13: =총괄표!P13+총괄표!P14 -> 3.9
A14: 산 업 용 | B14: =총괄표!I15 -> 17.6 | C14: 산 업 용 | D14: =총괄표!P15 -> 13.6
A15: 수 송 용 | B15: =총괄표!I16+총괄표!I17 -> 5.8 | C15: 수 송 용 | D15: =총괄표!P16+총괄표!P17 -> 4.2
A16: 기 타 | B16: =총괄표!I18+총괄표!I19+총괄표!I20+총괄표!I21 -> 0.9 | C16: 기 타 | D16: =총괄표!P18+총괄표!P19+총괄표!P20+총괄표!P21 -> 0.8
A17: 판매금액
A18: =A3 -> 4월 | C18: =C3 -> 누 계 | F18: 계획 | G18: 실적
A19: 계획 | B19: 실적 | C19: 계획 | D19: 실적 | E19: 당월 | F19: =A20 -> 95701781 | G19: =B20 -> 94104144
A20: =총괄표!C47 -> 95701781 | B20: =총괄표!D47 -> 94104144 | C20: =총괄표!J47 -> 512897619 | D20: =총괄표!K47 -> 517530958 | E20: 누계 | F20: =C20 -> 512897619 | G20: =D20 -> 517530958
A22: 판매금액 구성비
A23: =A18 -> 4월 | B23: 구성비 | C23: =C18 -> 누 계 | D23: 구성비
A24: 주 택 용 | B24: =총괄표!H35 -> 67.3 | C24: 주 택 용 | D24: =총괄표!O35 -> 73.6
A25: 일 반 용 | B25: =총괄표!H36 -> 7.9 | C25: 일 반 용 | D25: =총괄표!O36 -> 6.3
A26: 업무냉방용 | B26: =총괄표!H37+총괄표!H38 -> 2.7 | C26: 업무냉방용 | D26: =총괄표!O37+총괄표!O38 -> 3.9
A27: 산 업 용 | B27: =총괄표!H39 -> 15.4 | C27: 산 업 용 | D27: =총괄표!O39 -> 11.5
A28: 수 송 용 | B28: =총괄표!H40+총괄표!H41 -> 5.9 | C28: 수 송 용 | D28: =총괄표!O40+총괄표!O41 -> 4.1
A29: 기 타 | B29: =총괄표!H42+총괄표!H43+총괄표!H44+총괄표!H45 -> 0.8 | C29: 기 타 | D29: =총괄표!O42+총괄표!O43+총괄표!O44+총괄표!O45 -> 0.6
A31: 상품별 건수 (전산요청, 파일입력 후 => 판매량월별추이 상품별 전수 입력할 것)
A32: 상품 | B32: 공급전수 | D32: 용도 | E32: 검수
A33: 취사용 | B33: 59677 | D33: 주 택 용 | E33: =SUM(B33:B35,B37,B47) -> 1151036
A34: 취사난방용 | B34: 414450 | D34: 일 반 용 | E34: =SUM(B38:B39) -> 21352
A35: 중앙난방용 | B35: 101 | D35: 업무냉난방용 | E35: =SUM(B43,B45:B46) -> 8625
A36: 주한미군 | B36: 268 | D36: 산 업 용 | E36: =SUM(B44) -> 1109
A37: 자가열전용 | B37: 26 | D37: 수 송 용 | E37: =SUM(B48:B50) -> 98
A38: 일반용(2) | B38: 1067 | D38: 기 타 | E38: =SUM(B36,B40,B41,B42) -> 341
A39: 일반용(1) | B39: 20285 | D39: 합 계 | E39: =SUM(E33:E38) -> 1182561
A40: 열전용설비용 | B40: 5
A41: 열병합용 | B41: 17
A42: 연료전지 | B42: 51
A43: 업무난방용 | B43: 7547
A44: 산업용 | B44: 1109
A45: 냉난방용(주택) | B45: 30
A46: 냉난방용(업무) | B46: 1048
...

Sheet 매출관리(월)
A2: 매 출 내 역
A4: 매출년월 : | B4: 45413 | U4: 정상매출
A5: 적용일 | B5: 매출구분 | C5: 상품 | D5: 서비스 | E5: 단가 | F5: 사용량 | G5: 사용열량 | H5: 사용료 | I5: 기본료 | J5: 관리비(계) | K5: 관리비(보) | L5: 사용료(할인전) | M5: 사회복지 | N5: 배려할인 | O5: 차상위 | P5: 다자녀 | Q5: 안전관리비 | R5: 수입부과금 | S5: 특소세 | U5: 상품 | V5: 서비스 | W5: 단가변동갯수 | X5: 변동 후 단가
A6: 43654 | B6: 정상매출 | C6: 취사난방용 | D6: 개별난방(취사) | E6: 16.9367 | F6: 0.0781 | G6: 3.3403 | H6: 56.57 | I6: 900 | L6: 56.57 | R6: 0 | U6: 취사용 | V6: 취사용 | W6: =COUNTIFS($B:$B,$U$4,$C:$C,U6) -> 3 | X6: {=MAX(IF($D:$D=V6,$A:$A))} -> 45139
A7: 44013 | B7: 정상매출 | C7: 취사난방용 | D7: 개별난방(취사) | E7: 15.1523 | F7: 2.4291 | G7: 103.8789 | H7: 1574 | I7: 900 | L7: 1574 | R7: 0 | U7: 개별난방용 | V7: 개별난방 | W7: =COUNTIFS($B:$B,$U$4,$C:$C,U7) -> 7 | X7: {=MAX(IF($D:$D=V7,$A:$A))} -> 45139
A8: 44378 | B8: 정상매출 | C8: 개별난방용 | D8: 개별난방 | E8: 15.1392 | F8: 3.8915 | G8: 166.6285 | H8: 2522.61 | I8: 1800 | L8: 2522.61 | R8: 0 | U8: 취사난방용 | V8: 개별난방 | W8: =COUNTIFS($B:$B,$U$4,$C:$C,U8) -> 13 | X8: {=MAX(IF($D:$D=V8,$A:$A))} -> 45139
A9: 44378 | B9: 정상매출 | C9: 취사난방용 | D9: 개별난방(취사) | E9: 15.1392 | F9: 2.4038 | G9: 102.7997 | H9: 1556.29 | L9: 1556.29 | R9: 0 | U9: 취사난방용 | V9: 개별난방(취사) | W9: =COUNTIFS($B:$B,$U$4,$C:$C,U9) -> 13 | X9: {=MAX(IF($D:$D=V9,$A:$A))} -> 45139
A10: 44652 | B10: 정상매출 | C10: 개별난방용 | D10: 개별난방 | E10: 15.5692 | F10: 0.7134 | G10: 30.5486 | H10: 475.6 | L10: 475.6 | R10: 0 | U10: 일반용(1) | V10: 일반용(1)(동절기) | W10: =COUNTIFS($B:$B,$U$4,$C:$C,U10) -> 3 | X10: {=MAX(IF($D:$D=V10,$A:$A))} -> 45139
A11: 44652 | B11: 정상매출 | C11: 취사난방용 | D11: 개별난방(취사) | E11: 15.5692 | F11: 0.2632 | G11: 11.2554 | H11: 175.23 | L11: 175.23 | R11: 0 | U11: 일반용(1) | V11: 일반용(1)(기타) | W11: =COUNTIFS($B:$B,$U$4,$C:$C,U11) -> 3 | X11: {=MAX(IF($D:$D=V11,$A:$A))} -> 45139 | Y11: 매출관리(월)'!$A:$A,VLOOKUP("일반용(1)(하절기)",변동후단가표,3,FALSE))+SUMIFS('매출관리(월)'!$F:$F,'매출관리(월)'!$B:$B,"정상매출",'매출관리(월)'!$C:$C,LEFT($C53,6),'매출관리(월)'!$D:$D,"XXXXXX")
A12: 44682 | B12: 정상매출 | C12: 개별난방용 | D12: 개별난방 | E12: 16.7959 | F12: 1.4506 | G12: 62.1155 | H12: 1043.27 | L12: 1043.27 | R12: 0 | U12: 일반용(1) | V12: 일반용(1)(하절기) | W12: =COUNTIFS($B:$B,$U$4,$C:$C,U12) -> 3 | X12: {=MAX(IF($D:$D=V12,$A:$A))} -> 45139
A13: 44682 | B13: 정상매출 | C13: 취사난방용 | D13: 개별난방(취사) | E13: 16.7959 | F13: 0.5352 | G13: 22.8861 | H13: 384.38 | L13: 384.38 | R13: 0 | U13: 주한미군 | V13: 주한미군 | W13: =COUNTIFS($B:$B,$U$4,$C:$C,U13) -> 1 | X13: {=MAX(IF($D:$D=V13,$A:$A))} -> 45352
A14: 44743 | B14: 정상매출 | C14: 개별난방용 | D14: 개별난방 | E14: 17.9547 | F14: 2.1878 | G14: 93.6824 | H14: 1682.03 | L14: 1682.03 | R14: 0 | U14: 업무난방용 | V14: 업무난방 | W14: =COUNTIFS($B:$B,$U$4,$C:$C,U14) -> 5 | X14: {=MAX(IF($D:$D=V14,$A:$A))} -> 45444
A15: 44743 | B15: 정상매출 | C15: 취사난방용 | D15: 개별난방(취사) | E15: 17.9547 | F15: 0.8071 | G15: 34.5167 | H15: 619.72 | L15: 619.72 | R15: 0 | U15: 중앙난방용 | V15: 중앙난방 | W15: =COUNTIFS($B:$B,$U$4,$C:$C,U15) -> 1 | X15: {=MAX(IF($D:$D=V15,$A:$A))} -> 45139
A16: 44835 | B16: 정상매출 | C16: 취사용 | D16: 취사용 | E16: 20.6547 | F16: 5.9035 | G16: 252.6116 | H16: 5217.58 | I16: 8940 | J16: 1160 | L16: 5217.58 | R16: 0 | U16: 일반용(2) | V16: 일반용(2)(동절기) | W16: =COUNTIFS($B:$B,$U$4,$C:$C,U16) -> 2 | X16: {=MAX(IF($D:$D=V16,$A:$A))} -> 0
A17: 44835 | B17: 정상매출 | C17: 개별난방용 | D17: 개별난방 | E17: 20.6547 | F17: 24.2009 | G17: 1034.3156 | H17: 21363.45 | I17: 2700 | J17: 580 | L17: 21363.45 | R17: 0 | U17: 일반용(2) | V17: 일반용(2)(기타) | W17: =COUNTIFS($B:$B,$U$4,$C:$C,U17) -> 2 | X17: {=MAX(IF($D:$D=V17,$A:$A))} -> 45139
A18: 44835 | B18: 정상매출 | C18: 취사난방용 | D18: 개별난방(취사) | E18: 20.6547 | F18: 15.146 | G18: 647.4868 | H18: 13373.59 | I18: 6300 | L18: 13373.59 | R18: 0 | U18: 일반용(2) | V18: 일반용(2)(하절기) | W18: =COUNTIFS($B:$B,$U$4,$C:$C,U18) -> 2 | X18: {=MAX(IF($D:$D=V18,$A:$A))} -> 45139
A19: 44835 | B19: 정상매출 | C19: 취사난방용 | D19: 개별난방 | E19: 20.6547 | F19: 76.333 | G19: 3264.5569 | H19: 67428.42 | L19: 67428.42 | R19: 0 | U19: 자가열전용 | V19: 자가열전용 | W19: =COUNTIFS($B:$B,$U$4,$C:$C,U19) -> 1 | X19: {=MAX(IF($D:$D=V19,$A:$A))} -> 45139
A20: 45062 | B20: 정상매출 | C20: 취사용 | D20: 취사용 | E20: 21.6991 | F20: 8.8399 | G20: 377.5479 | H20: 8192.39 | I20: 8350 | J20: 1160 | L20: 8192.39 | R20: 0 | U20: 산업용 | V20: 산업용(동절기) | W20: =COUNTIFS($B:$B,$U$4,$C:$C,U20) -> 2 | X20: {=MAX(IF($D:$D=V20,$A:$A))} -> 0
A21: 45062 | B21: 정상매출 | C21: 개별난방용 | D21: 개별난방 | E21: 21.6991 | F21: 23.0577 | G21: 985.015 | H21: 21373.9 | L21: 21373.9 | R21: 0 | U21: 산업용 | V21: 산업용(기타) | W21: =COUNTIFS($B:$B,$U$4,$C:$C,U21) -> 2 | X21: {=MAX(IF($D:$D=V21,$A:$A))} -> 45413
A22: 45062 | B22: 정상매출 | C22: 취사난방용 | D22: 개별난방(취사) | E22: 21.6991 | F22: 13.9899 | G22: 597.6859 | H22: 12969.19 | I22: 2700 | L22: 12969.19 | R22: 0 | U22: 산업용 | V22: 산업용(하절기) | W22: =COUNTIFS($B:$B,$U$4,$C:$C,U22) -> 2 | X22: {=MAX(IF($D:$D=V22,$A:$A))} -> 45444
A23: 45062 | B23: 정상매출 | C23: 취사난방용 | D23: 개별난방 | E23: 21.6991 | F23: 49.7608 | G23: 2127.2721 | H23: 46159.87 | L23: 46159.87 | R23: 0 | U23: 냉난방용(업무) | V23: 냉난방(동절기) | W23: =COUNTIFS($B:$B,$U$4,$C:$C,U23) -> 3 | X23: {=MAX(IF($D:$D=V23,$A:$A))} -> 0
A24: 45139 | B24: 정상매출 | C24: 취사용 | D24: 취사용 | E24: 21.8472 | F24: 480547.55 | G24: 20505703 | H24: 4.4793194e+08 | I24: 92691770 | J24: 17135370 | L24: 4.4796404e+08 | M24: 32105 | R24: 0 | U24: 냉난방용(업무) | V24: 냉난방(기타) | W24: =COUNTIFS($B:$B,$U$4,$C:$C,U24) -> 3 | X24: {=MAX(IF($D:$D=V24,$A:$A))} -> 0
A25: 45139 | B25: 정상매출 | C25: 개별난방용 | D25: 개별난방 | E25: 21.8472 | F25: 10846906 | G25: 4.6203551e+08 | H25: 1.009365e+10 | I25: 526008600 | J25: 119152980 | L25: 1.0093901e+10 | M25: 251663 | R25: 0 | U25: 냉난방용(업무) | V25: 냉난방(하절기) | W25: =COUNTIFS($B:$B,$U$4,$C:$C,U25) -> 3 | X25: {=MAX(IF($D:$D=V25,$A:$A))} -> 45444
A26: 45139 | B26: 정상매출 | C26: 취사난방용 | D26: 개별난방(취사) | E26: 21.8472 | F26: 4795920.8 | G26: 2.0428957e+08 | H26: 4.4628248e+09 | I26: 417552300 | J26: 37963000 | L26: 4.4630846e+09 | M26: 259746.18 | R26: 0 | U26: 냉난방용(업무) | V26: 중앙난방 | W26: =COUNTIFS($B:$B,$U$4,$C:$C,U26) -> 3 | X26: {=MAX(IF($D:$D=V26,$A:$A))} -> 45139
A27: 45139 | B27: 정상매출 | C27: 취사난방용 | D27: 개별난방 | E27: 21.8472 | F27: 6119621.4 | G27: 2.6067845e+08 | H27: 5.6943698e+09 | L27: 5.6949365e+09 | M27: 566772.82 | R27: 0 | U27: 열전용설비용 | V27: 열전용설비용 | W27: =COUNTIFS($B:$B,$U$4,$C:$C,U27) -> 1 | X27: {=MAX(IF($D:$D=V27,$A:$A))} -> 45444
A28: 45139 | B28: 정상매출 | C28: 중앙난방용 | D28: 중앙난방 | E28: 21.8144 | F28: 469114.53 | G28: 19916008 | H28: 434455731 | J28: 1804180 | K28: 1049000 | L28: 434455731 | R28: 0 | U28: 냉난방용(주택) | V28: 냉난방(하절기) | W28: =COUNTIFS($B:$B,$U$4,$C:$C,U28) -> 2 | X28: {=MAX(IF($D:$D=V28,$A:$A))} -> 45444
A29: 45139 | B29: 정상매출 | C29: 일반용(1) | D29: 일반용(1)(동절기) | E29: 21.1877 | F29: 47.5751 | G29: 2036.4354 | H29: 43147.36 | J29: 1300 | L29: 43147.36 | R29: 0 | U29: 냉난방용(주택) | V29: 냉난방(기타) | W29: =COUNTIFS($B:$B,$U$4,$C:$C,U29) -> 2 | X29: {=MAX(IF($D:$D=V29,$A:$A))} -> 0
A30: 45139 | B30: 정상매출 | C30: 일반용(1) | D30: 일반용(1)(하절기) | E30: 20.9808 | F30: 1131902.4 | G30: 48106659 | H30: 1.0084343e+09 | J30: 618880 | K30: 117600 | L30: 1.0093064e+09 | M30: 872144.69 | R30: 0 | U30: 냉난방용(주택) | V30: 중앙난방 | W30: =COUNTIFS($B:$B,$U$4,$C:$C,U30) -> 2 | X30: {=MAX(IF($D:$D=V30,$A:$A))} -> 45139
A31: 45139 | B31: 정상매출 | C31: 일반용(1) | D31: 일반용(1)(기타) | E31: 20.9934 | F31: 3695365 | G31: 1.5733697e+08 | H31: 3.3019727e+09 | J31: 38016940 | K31: 1168900 | L31: 3.3030378e+09 | M31: 1065083.3 | R31: 0 | U31: 열병합용 | V31: 열병합용(동절기) | W31: =COUNTIFS($B:$B,$U$4,$C:$C,U31) -> 3 | X31: {=MAX(IF($C:$C=U31,$A:$A))} -> 45444
A32: 45139 | B32: 정상매출 | C32: 일반용(2) | D32: 일반용(2)(하절기) | E32: 20.9808 | F32: 841753.16 | G32: 35745418 | H32: 7.4910574e+08 | J32: 186700 | K32: 29400 | L32: 7.4996702e+08 | M32: 861283.42 | R32: 0 | U32: 열병합용 | V32: 열병합용(기타) | W32: =COUNTIFS($B:$B,$U$4,$C:$C,U32) -> 3 | X32: {=MAX(IF($C:$C=U32,$A:$A))} -> 45444
A33: 45139 | B33: 정상매출 | C33: 일반용(2) | D33: 일반용(2)(기타) | E33: 20.9934 | F33: 709236.7 | G33: 30144216 | H33: 6.3230675e+08 | J33: 10158960 | K33: 2578400 | L33: 6.3282958e+08 | M33: 522836.58 | R33: 0 | U33: 열병합용 | V33: 열병합용(하절기) | W33: =COUNTIFS($B:$B,$U$4,$C:$C,U33) -> 3 | X33: {=MAX(IF($C:$C=U33,$A:$A))} -> 45444
A34: 45139 | B34: 정상매출 | C34: 자가열전용 | D34: 자가열전용 | E34: 21.8144 | F34: 126655 | G34: 5375871.5 | H34: 117271403 | J34: 712570 | K34: 735000 | L34: 117271403 | R34: 0 | U34: 연료전지 | V34: 연료전지(하절기) | W34: =COUNTIFS($B:$B,$U$4,$C:$C,U34) -> 3 | X34: {=MAX(IF($D:$D=V34,$A:$A))} -> 45444
A35: 45323 | B35: 정상매출 | C35: 업무난방용 | D35: 업무난방 | E35: 24.6278 | F35: 0.3956 | G35: 16.937 | H35: 417.12 | J35: 320 | L35: 417.12 | R35: 0 | U35: 연료전지 | V35: 연료전지(기타) | W35: =COUNTIFS($B:$B,$U$4,$C:$C,U35) -> 3 | X35: {=MAX(IF($D:$D=V35,$A:$A))} -> 45413
