Workbook
Name _25년공급전수: '[1]분석(공급량및판매량))'!$B$406:$N$413
Name _25년예상판매량: '[2]분석(공급량및판매량))'!$C$422:$N$439
Name 매출년월: '[3](전산)집계'!$A$2:$A$24
Name 변동후단가표: '매출관리(월)'!$V$5:$X$285
Name 사용량: '[3](전산)집계'!$D$2:$D$24
Name 사용열량: '[3](전산)집계'!$E$2:$E$24
Name 상품: '[3](전산)집계'!$C$2:$C$24

Sheet 총괄표
A2: 2025년 5월 매출현황 | R2: (누계-집계용도)
A3: 1.판매량 | R3: 1.판매량(단위:GJ) | V3: 1번 )전월기준 누계값으로 작성
A5: 구 분 | C5: 당 월 | J5: 누 계 | R5: 구분 | T5: 구성비 | V5: 판매량(누계)
C6: 계획 (천MJ) | D6: 실적 (천N㎥) | E6: 실적 (천MJ) | F6: 대비 (%) | G6: 전년 (천MJ) | H6: 대비 (%) | I6: 구성비 (%) | J6: 계획 (천MJ) | K6: 실적 (천N㎥) | L6: 실적 (천MJ) | M6: 대비 (%) | N6: 전년 (천MJ) | O6: 대비 (%) | P6: 구성비 (%) | T6: 당월 | U6: 누계 | V6: 계획(GJ) | W6: 실적(천N㎥) | X6: 실적(GJ) | Y6: 전년(GJ)
A7: 주 택 용 | B7: 취사용 | C7: 17291 | D7: =(매출액표!D23)/1000 -> 479.53625 | E7: =ROUND((매출액표!E23)/1000,0) -> 20514 | F7: =ROUND(E7/C7*100,1) -> 118.6 | G7: 21626 | H7: =E7/G7*100 -> 94.858041 | I7: =IF(E7=MAX($E$7:$E$10,$E$12:$E$21),MAX($T$7:$T$21)+(100-SUM($T$7:$T$21)),T7) -> 0.7 | J7: =C7+V7 -> 107636 | K7: =D7+W7 -> 2555.6042 | L7: =E7+X7 -> 109579 | M7: =L7/J7*100 -> 101.80516 | N7: =G7+Y7 -> 115989 | O7: =L7/N7*100 -> 94.473614 | P7: =IF(L7=MAX($L$7:$L$10,$L$12:$L$21),MAX($U$7:$U$21)+(100-SUM($U$7:$U$21)),U7) -> 0.4 | R7: 가정용 | S7: 취사용 | T7: =ROUND(E7/$E$23*100,1) -> 0.7 | U7: =ROUND(L7/$L$23*100,1) -> 0.4 | V7: 90345 | W7: 2076.0679 | X7: 89065 | Y7: 94363
B8: 개별난방용 | C8: 1551370 | D8: =(매출액표!D31+매출액표!D36)/1000 -> 36789.914 | E8: =ROUND((매출액표!E31+매출액표!E36)/1000,0)-1 -> 1565946 | F8: =ROUND(E8/C8*100,1) -> 100.9 | G8: 1386865 | H8: =E8/G8*100 -> 112.91265 | I8: =IF(E8=MAX($E$7:$E$10,$E$12:$E$21),MAX($T$7:$T$21)+(100-SUM($T$7:$T$21)),T8) -> 52.1 | J8: =C8+V8 -> 18563796 | K8: =D8+W8 -> 442361.68 | L8: =E8+X8 -> 18973747 | M8: =L8/J8*100 -> 102.20834 | N8: =G8+Y8 -> 17937817 | O8: =L8/N8*100 -> 105.77512 | P8: =IF(L8=MAX($L$7:$L$10,$L$12:$L$21),MAX($U$7:$U$21)+(100-SUM($U$7:$U$21)),U8) -> 67.6 | S8: 개별난방용 | T8: =ROUND(E8/$E$23*100,1) -> 52 | U8: =ROUND(L8/$L$23*100,1) -> 67.5 | V8: 17012426 | W8: 405571.76 | X8: 17407801 | Y8: 16550952
B9: 중앙난방용 | C9: 27108 | D9: =매출액표!D40/1000 -> 612.43205 | E9: =ROUND(매출액표!E40/1000,0) -> 26084 | F9: =ROUND(E9/C9*100,1) -> 96.2 | G9: 25664 | H9: =E9/G9*100 -> 101.63653 | I9: =IF(E9=MAX($E$7:$E$10,$E$12:$E$21),MAX($T$7:$T$21)+(100-SUM($T$7:$T$21)),T9) -> 0.9 | J9: =C9+V9 -> 344476 | K9: =D9+W9 -> 8693.0149 | L9: =E9+X9 -> 372837 | M9: =L9/J9*100 -> 108.23308 | N9: =G9+Y9 -> 355514 | O9: =L9/N9*100 -> 104.87266 | P9: =IF(L9=MAX($L$7:$L$10,$L$12:$L$21),MAX($U$7:$U$21)+(100-SUM($U$7:$U$21)),U9) -> 1.3 | S9: 중앙난방용 | T9: =ROUND(E9/$E$23*100,1) -> 0.9 | U9: =ROUND(L9/$L$23*100,1) -> 1.3 | V9: 317368 | W9: 8080.5828 | X9: 346753 | Y9: 329850
B10: 자가열전용 | C10: 11990 | D10: =(매출액표!D43)/1000 -> 246.294 | E10: =ROUND((매출액표!E43)/1000,0) -> 10497 | F10: =ROUND(E10/C10*100,1) -> 87.5 | G10: 9216 | H10: =E10/G10*100 -> 113.89974 | I10: =IF(E10=MAX($E$7:$E$10,$E$12:$E$21),MAX($T$7:$T$21)+(100-SUM($T$7:$T$21)),T10) -> 0.3 | J10: =C10+V10 -> 230960 | K10: =D10+W10 -> 5066.866 | L10: =E10+X10 -> 217406 | M10: =L10/J10*100 -> 94.131451 | N10: =G10+Y10 -> 210827 | O10: =L10/N10*100 -> 103.12057 | P10: =IF(L10=MAX($L$7:$L$10,$L$12:$L$21),MAX($U$7:$U$21)+(100-SUM($U$7:$U$21)),U10) -> 0.8 | S10: 자가열전용 | T10: =ROUND(E10/$E$23*100,1) -> 0.3 | U10: =ROUND(L10/$L$23*100,1) -> 0.8 | V10: 218970 | W10: 4820.572 | X10: 206909 | Y10: 201611
B11: 소 계 | C11: =ROUND(SUM(C7:C10),0) -> 1607759 | D11: =SUM(D7:D10) -> 38128.176 | E11: =SUM(E7:E10) -> 1623041 | F11: =E11/C11*100 -> 100.95052 | G11: =SUM(G7:G10) -> 1443371 | H11: =E11/G11*100 -> 112.44794 | I11: =SUM(I7:I10) -> 54 | J11: =ROUNDUP(SUM(J7:J10),0) -> 19246868 | K11: =SUM(K7:K10) -> 458677.16 | L11: =SUM(L7:L10) -> 19673569 | M11: =L11/J11*100 -> 102.21699 | N11: =SUM(N7:N10) -> 18620147 | O11: =L11/N11*100 -> 105.65743 | P11: =SUM(P7:P10) -> 70.1 | S11: 소계 | V11: =ROUNDUP(SUM(V7:V10),0) -> 17639109 | W11: =SUM(W7:W10) -> 420548.98 | X11: =SUM(X7:X10) -> 18050528 | Y11: =SUM(Y7:Y10) -> 17176776
A12: 일반용 | C12: 280557 | D12: =매출액표!D54/1000 -> 6791.0177 | E12: =ROUND(매출액표!E54/1000,0) -> 289022 | F12: =ROUND(E12/C12*100,1) -> 103 | G12: 285280.6 | H12: =E12/G12*100 -> 101.31148 | I12: =IF(E12=MAX($E$7:$E$10,$E$12:$E$21),MAX($T$7:$T$21)+(100-SUM($T$7:$T$21)),T12) -> 9.6 | J12: =C12+V12 -> 1759015 | K12: =D12+W12 -> 40387.042 | L12: =E12+X12 -> 1730855 | M12: =L12/J12*100 -> 98.399104 | N12: =G12+Y12 -> 1738824.9 | O12: =L12/N12*100 -> 99.541652 | P12: =IF(L12=MAX($L$7:$L$10,$L$12:$L$21),MAX($U$7:$U$21)+(100-SUM($U$7:$U$21)),U12) -> 6.2 | R12: 일반용 | T12: =ROUND(E12/$E$23*100,1) -> 9.6 | U12: =ROUND(L12/$L$23*100,1) -> 6.2 | V12: 1478458 | W12: 33596.024 | X12: 1441833 | Y12: 1453544.3
A13: 업무난방용 | C13: 36693 | D13: =매출액표!D62/1000 -> 885.63498 | E13: =ROUND(매출액표!E62/1000,0) -> 37690 | F13: =ROUND(E13/C13*100,1) -> 102.7 | G13: 35392 | H13: =E13/G13*100 -> 106.49299 | I13: =IF(E13=MAX($E$7:$E$10,$E$12:$E$21),MAX($T$7:$T$21)+(100-SUM($T$7:$T$21)),T13) -> 1.3 | J13: =C13+V13 -> 482058 | K13: =D13+W13 -> 11756.378 | L13: =E13+X13 -> 504313 | M13: =L13/J13*100 -> 104.61666 | N13: =G13+Y13 -> 481588 | O13: =L13/N13*100 -> 104.71876 | P13: =IF(L13=MAX($L$7:$L$10,$L$12:$L$21),MAX($U$7:$U$21)+(100-SUM($U$7:$U$21)),U13) -> 1.8 | R13: 업무난방용 | T13: =ROUND(E13/$E$23*100,1) -> 1.3 | U13: =ROUND(L13/$L$23*100,1) -> 1.8 | V13: 445365 | W13: 10870.743 | X13: 466623 | Y13: 446196
A14: 냉방용 | C14: 49877 | D14: =매출액표!D69/1000 -> 724.84469 | E14: =ROUND(매출액표!E69/1000,0) -> 30852 | F14: =ROUND(E14/C14*100,1) -> 61.9 | G14: 30066 | H14: =E14/G14*100 -> 102.61425 | I14: =IF(E14=MAX($E$7:$E$10,$E$12:$E$21),MAX($T$7:$T$21)+(100-SUM($T$7:$T$21)),T14) -> 1 | J14: =C14+V14 -> 514016 | K14: =D14+W14 -> 12585.384 | L14: =E14+X14 -> 540056 | M14: =L14/J14*100 -> 105.06599 | N14: =G14+Y14 -> 505401 | O14: =L14/N14*100 -> 106.85693 | P14: =IF(L14=MAX($L$7:$L$10,$L$12:$L$21),MAX($U$7:$U$21)+(100-SUM($U$7:$U$21)),U14) -> 1.9 | R14: 냉방용 | T14: =ROUND(E14/$E$23*100,1) -> 1 | U14: =ROUND(L14/$L$23*100,1) -> 1.9 | V14: 464139 | W14: 11860.54 | X14: 509204 | Y14: 475335
A15: 산업용 | C15: 818098 | D15: =매출액표!D73/1000 -> 16853.112 | E15: =ROUND(매출액표!E73/1000,0)-1 -> 717448 | F15: =ROUND(E15/C15*100,1) -> 87.7 | G15: 805815 | H15: =E15/G15*100 -> 89.033835 | I15: =IF(E15=MAX($E$7:$E$10,$E$12:$E$21),MAX($T$7:$T$21)+(100-SUM($T$7:$T$21)),T15) -> 23.8 | J15: =C15+V15 -> 4278567 | K15: =D15+W15 -> 95727.615 | L15: =E15+X15 -> 4100646 | M15: =L15/J15*100 -> 95.841575 | N15: =G15+Y15 -> 4380432 | O15: =L15/N15*100 -> 93.612822 | P15: =IF(L15=MAX($L$7:$L$10,$L$12:$L$21),MAX($U$7:$U$21)+(100-SUM($U$7:$U$21)),U15) -> 14.6 | R15: 산업용 | T15: =ROUND(E15/$E$23*100,1) -> 23.8 | U15: =ROUND(L15/$L$23*100,1) -> 14.6 | V15: 3460469 | W15: 78874.503 | X15: 3383198 | Y15: 3574617
A16: 수송용(CNG) | C16: 256799 | D16: =ROUND((매출액표!D55)/1000,0) -> 6074 | E16: =ROUND((매출액표!E55)/1000,0) -> 262403 | F16: =ROUND(E16/C16*100,1) -> 102.2 | G16: 264610 | H16: =E16/G16*100 -> 99.165942 | I16: =IF(E16=MAX($E$7:$E$10,$E$12:$E$21),MAX($T$7:$T$21)+(100-SUM($T$7:$T$21)),T16) -> 8.7 | J16: =C16+V16 -> 1235930 | K16: =D16+W16 -> 28881 | L16: =E16+X16 -> 1246904 | M16: =L16/J16*100 -> 100.88791 | N16: =G16+Y16 -> 1268707 | O16: =L16/N16*100 -> 98.281479 | P16: =IF(L16=MAX($L$7:$L$10,$L$12:$L$21),MAX($U$7:$U$21)+(100-SUM($U$7:$U$21)),U16) -> 4.4 | R16: 수송용(CNG) | T16: =ROUND(E16/$E$23*100,1) -> 8.7 | U16: =ROUND(L16/$L$23*100,1) -> 4.4 | V16: 979131 | W16: 22807 | X16: 984501 | Y16: 1004097
A17: 수송용(BIO) | C17: 13030 | D17: =ROUND((매출액표!D56)/1000,0) -> 283 | E17: =ROUND((매출액표!E56)/1000,0) -> 11964 | F17: =ROUND(E17/C17*100,1) -> 91.8 | G17: 13430 | H17: =IFERROR(E17/G17*100,0) -> 89.08414 | I17: =IF(E17=MAX($E$7:$E$10,$E$12:$E$21),MAX($T$7:$T$21)+(100-SUM($T$7:$T$21)),T17) -> 0.4 | J17: =C17+V17 -> 62710 | K17: =D17+W17 -> 1345 | L17: =E17+X17 -> 56939 | M17: =L17/J17*100 -> 90.797321 | N17: =G17+Y17 -> 62738 | O17: =IFERROR(L17/N17*100,0) -> 90.756798 | P17: =IF(L17=MAX($L$7:$L$10,$L$12:$L$21),MAX($U$7:$U$21)+(100-SUM($U$7:$U$21)),U17) -> 0.2 | R17: 수송용(BIO) | T17: =ROUND(E17/$E$23*100,1) -> 0.4 | U17: =ROUND(L17/$L$23*100,1) -> 0.2 | V17: 49680 | W17: 1062 | X17: 44975 | Y17: 49308
A18: 열병합용 | C18: 19593 | D18: =매출액표!D78/1000 -> 420.998 | E18: =ROUND(매출액표!E78/1000,0) -> 17947 | F18: =ROUND(E18/C18*100,1) -> 91.6 | G18: 19779 | H18: =E18/G18*100 -> 90.737651 | I18: =IF(E18=MAX($E$7:$E$10,$E$12:$E$21),MAX($T$7:$T$21)+(100-SUM($T$7:$T$21)),T18) -> 0.6 | J18: =C18+V18 -> 101341 | K18: =D18+W18 -> 2756.727 | L18: =E18+X18 -> 118088 | M18: =L18/J18*100 -> 116.52539 | N18: =G18+Y18 -> 104574 | O18: =L18/N18*100 -> 112.92291 | P18: =IF(L18=MAX($L$7:$L$10,$L$12:$L$21),MAX($U$7:$U$21)+(100-SUM($U$7:$U$21)),U18) -> 0.4 | R18: 열병합용 | T18: =ROUND(E18/$E$23*100,1) -> 0.6 | U18: =ROUND(L18/$L$23*100,1) -> 0.4 | V18: 81748 | W18: 2335.729 | X18: 100141 | Y18: 84795
A19: 연료전지용 | C19: 19144 | D19: =매출액표!D83/1000 -> 385.14072 | E19: =ROUND(매출액표!E83/1000,0) -> 16412 | F19: =ROUND(E19/C19*100,1) -> 85.7 | G19: 18601 | H19: =E19/G19*100 -> 88.231815 | I19: =IF(E19=MAX($E$7:$E$10,$E$12:$E$21),MAX($T$7:$T$21)+(100-SUM($T$7:$T$21)),T19) -> 0.5 | J19: =C19+V19 -> 93672 | K19: =D19+W19 -> 2000.0431 | L19: =E19+X19 -> 85655 | M19: =L19/J19*100 -> 91.441413 | N19: =G19+Y19 -> 91299 | O19: =L19/N19*100 -> 93.818114 | P19: =IF(L19=MAX($L$7:$L$10,$L$12:$L$21),MAX($U$7:$U$21)+(100-SUM($U$7:$U$21)),U19) -> 0.3 | R19: 연료전지용 | T19: =ROUND(E19/$E$23*100,1) -> 0.5 | U19: =ROUND(L19/$L$23*100,1) -> 0.3 | V19: 74528 | W19: 1614.9024 | X19: 69243 | Y19: 72698
A20: 열전용설비용 | C20: 459 | D20: =매출액표!D85/1000 -> 10.899 | E20: =ROUND(매출액표!E85/1000,0) -> 465 | F20: =ROUND(E20/C20*100,1) -> 101.3 | G20: 9397 | H20: =E20/G20*100 -> 4.9483878 | I20: =IF(E20=MAX($E$7:$E$10,$E$12:$E$21),MAX($T$7:$T$21)+(100-SUM($T$7:$T$21)),T20) -> 0 | J20: =C20+V20 -> 12264 | K20: =D20+W20 -> 92.005 | L20: =E20+X20 -> 3938 | M20: =L20/J20*100 -> 32.110241 | N20: =G20+Y20 -> 100345 | O20: =L20/N20*100 -> 3.9244606 | P20: =IF(L20=MAX($L$7:$L$10,$L$12:$L$21),MAX($U$7:$U$21)+(100-SUM($U$7:$U$21)),U20) -> 0 | R20: 열전용설비용 | T20: =ROUND(E20/$E$23*100,1) -> 0 | U20: =ROUND(L20/$L$23*100,1) -> 0 | V20: 11805 | W20: 81.106 | X20: 3473 | Y20: 90948
A21: 주한미군 | C21: 3309 | D21: =매출액표!D88/1000 -> 52.229372 | E21: =ROUND(매출액표!E88/1000,0) -> 2227 | F21: =ROUND(E21/C21*100,1) -> 67.3 | G21: 4058 | H21: =E21/G21*100 -> 54.879251 | I21: =IF(E21=MAX($E$7:$E$10,$E$12:$E$21),MAX($T$7:$T$21)+(100-SUM($T$7:$T$21)),T21) -> 0.1 | J21: =C21+V21 -> 35822 | K21: =D21+W21 -> 803.19539 | L21: =E21+X21 -> 34462 | M21: =L21/J21*100 -> 96.20345 | N21: =G21+Y21 -> 38271 | O21: =L21/N21*100 -> 90.047294 | P21: =IF(L21=MAX($L$7:$L$10,$L$12:$L$21),MAX($U$7:$U$21)+(100-SUM($U$7:$U$21)),U21) -> 0.1 | R21: 주한미군 | T21: =ROUND(E21/$E$23*100,1) -> 0.1 | U21: =ROUND(L21/$L$23*100,1) -> 0.1 | V21: 32513 | W21: 750.96602 | X21: 32235 | Y21: 34213
A22: 소 계 | C22: =SUM(C12:C21) -> 1497559 | D22: =SUM(D12:D21) -> 32480.877 | E22: =SUM(E12:E21) -> 1386430 | F22: =E22/C22*100 -> 92.579324 | G22: =SUM(G12:G21) -> 1486428.6 | H22: =E22/G22*100 -> 93.272559 | I22: =SUM(I12:I21) -> 46 | J22: =SUM(J12:J21) -> 8575395 | K22: =SUM(K12:K21) -> 196334.39 | L22: =SUM(L12:L21) -> 8421856 | M22: =L22/J22*100 -> 98.20954 | N22: =SUM(N12:N21) -> 8772179.9 | O22: =L22/N22*100 -> 96.006422 | P22: =P23-P11 -> 29.9 | R22: 소계 | V22: =SUM(V12:V21) -> 7077836 | W22: =SUM(W12:W21) -> 163853.51 | X22: =SUM(X12:X21) -> 7035426 | Y22: =SUM(Y12:Y21) -> 7285751.3
A23: 합 계 | C23: =C11+C22 -> 3105318 | D23: =D11+D22 -> 70609.053 | E23: =E22+E11 -> 3009471 | F23: =E23/C23*100 -> 96.913456 | G23: =G22+G11 -> 2929799.6 | H23: =E23/G23*100 -> 102.71935 | I23: =I11+I22 -> 100 | J23: =J11+J22 -> 27822263 | K23: =K22+K11 -> 655011.55 | L23: =L11+L22 -> 28095425 | M23: =L23/J23*100 -> 100.98181 | N23: =N11+N22 -> 27392327 | O23: =L23/N23*100 -> 102.56677 | P23: 100 | R23: 합계 | V23: =V11+V22 -> 24716945 | W23: =W11+W22 -> 584402.5 | X23: =X11+X22 -> 25085954 | Y23: =Y11+Y22 -> 24462527
A24: 공급량 | C24: 2471083 | D24: 55536662 | E24: 2367845 | F24: =E24/C24*100 -> 95.822156 | G24: 2399132 | H24: =$E$24/G24*100 -> 98.695903 | J24: =C24+V24 -> 23436510 | K24: =D24+W24 -> 563686662 | L24: =E24+X24 -> 24166235 | M24: =L24/J24*100 -> 103.11362 | N24: =G24+Y24 -> 23335063 | O24: =L24/N24*100 -> 103.5619 | R24: 공급량 | V24: 20965427 | W24: 508150000 | X24: 21798390 | Y24: 20935931
R27: 2.판매금액(단위:백만원)
A28: 2.판매금액 | P28: 단위 : 백만원 | V28: 전월기준 누계값으로 작성
A29: 구 분 | C29: 당 월 | J29: 누 계 | R29: 구분 | T29: 구성비 | V29: 판매금액(누계)
C30: 계획 | D30: 실적 | E30: 대비 (%) | F30: 전년 | G30: 대비 (%) | H30: 구성비 (%) | J30: 계획 | K30: 실적 | L30: 대비 (%) | M30: 전년 | N30: 대비 (%) | O30: 구성비 (%) | T30: 당월 | U30: 누계 | V30: 계획 | W30: 실적 | X30: 전년누계
A31: 주 택 용 | B31: 취사용 | C31: 562629.8 | D31: =ROUND((매출액표!G23+매출액표!H23)/1000,0) -> 558589 | F31: 552076 | H31: =IF(D31=MAX($D$31:$D$34,$D$36:$D$45),MAX($T$31:$T$45)+(100-SUM($T$31:$T$45)),T31) -> 0.8 | J31: =C31+V31 -> 3309956.6 | K31: =D31+W31 -> 2956082 | M31: =X31+F31-1 -> 2931613.6 | O31: =IF(K31=MAX($K$31:$K$34,$K$36:$K$45),MAX($U$31:$U$45)+(100-SUM($U$31:$U$45)),U31) -> 0.5 | R31: 가정용 | S31: 취사용 | T31: =ROUND(D31/$D$47*100,1) -> 0.8 | U31: =ROUND(K31/$K$47*100,1) -> 0.5 | V31: 2747326.8 | W31: 2397493 | X31: 2379538.6
B32: 개별난방용 | C32: 36413139 | D32: =ROUND((매출액표!G31+매출액표!H31+매출액표!G36+매출액표!H36)/1000,0) -> 36836821 | F32: 30360785 | H32: =IF(D32=MAX($D$31:$D$34,$D$36:$D$45),MAX($T$31:$T$45)+(100-SUM($T$31:$T$45)),T32) -> 54.1 | J32: =C32+V32 -> 4.0956535e+08 | K32: =D32+W32 -> 416385547 | M32: =X32+F32 -> 3.6561478e+08 | O32: =IF(K32=MAX($K$31:$K$34,$K$36:$K$45),MAX($U$31:$U$45)+(100-SUM($U$31:$U$45)),U32) -> 67.1 | S32: 개별난방용 | T32: =ROUND(D32/$D$47*100,1) -> 54.2 | U32: =ROUND(K32/$K$47*100,1) -> 67.2 | V32: 3.7315221e+08 | W32: 379548726 | X32: 3.35254e+08
B33: 중앙난방용 | C33: 636192 | D33: =ROUND((매출액표!G40+매출액표!H40)/1000,0) -> 574989 | F33: 523312 | H33: =IF(D33=MAX($D$31:$D$34,$D$36:$D$45),MAX($T$31:$T$45)+(100-SUM($T$31:$T$45)),T33) -> 0.8 | J33: =C33+V33 -> 8084436 | K33: =D33+W33 -> 7909079 | M33: =X33+F33 -> 6969939.4 | O33: =IF(K33=MAX($K$31:$K$34,$K$36:$K$45),MAX($U$31:$U$45)+(100-SUM($U$31:$U$45)),U33) -> 1.3 | S33: 중앙난방용 | T33: =ROUND(D33/$D$47*100,1) -> 0.8 | U33: =ROUND(K33/$K$47*100,1) -> 1.3 | V33: 7448244 | W33: 7334090 | X33: 6446627.4
B34: 자가열전용 | C34: 281390 | D34: =ROUND((매출액표!G43+매출액표!H43)/1000,0) -> 242437 | F34: 197119 | H34: =IF(D34=MAX($D$31:$D$34,$D$36:$D$45),MAX($T$31:$T$45)+(100-SUM($T$31:$T$45)),T34) -> 0.4 | J34: =C34+V34 -> 5420351 | K34: =D34+W34 -> 4969815 | M34: =X34+F34 -> 4472432.6 | O34: =IF(K34=MAX($K$31:$K$34,$K$36:$K$45),MAX($U$31:$U$45)+(100-SUM($U$31:$U$45)),U34) -> 0.8 | S34: 자가열전용 | T34: =ROUND(D34/$D$47*100,1) -> 0.4 | U34: =ROUND(K34/$K$47*100,1) -> 0.8 | V34: 5138961 | W34: 4727378 | X34: 4275313.6
B35: 소 계 | C35: =SUM(C31:C34) -> 37893351 | D35: =SUM(D31:D34) -> 38212836 | E35: =D35/C35*100 -> 100.84312 | F35: =SUM(F31:F34) -> 31633292 | G35: =D35/F35*100 -> 120.79943 | H35: =SUM(H31:I34) -> 56.1 | J35: =C35+V35 -> 4.2638009e+08 | K35: =SUM(K31:K34) -> 432220523 | L35: =K35/J35*100 -> 101.36977 | M35: =SUM(M31:M34) -> 3.7998877e+08 | N35: =K35/M35*100 -> 113.74561 | O35: =SUM(O31:P34) -> 69.7 | S35: 소계 | V35: =SUM(V31:V34) -> 3.8848674e+08 | W35: =SUM(W31:W34) -> 394007687 | X35: =SUM(X31:X34) -> 3.4835548e+08
A36: 일반용 | C36: 6343505 | D36: =ROUNDDOWN((매출액표!G49+매출액표!G53)/1000,-3) -> 6527000 | F36: 5982830 | H36: =IF(D36=MAX($D$31:$D$34,$D$36:$D$45),MAX($T$31:$T$45)+(100-SUM($T$31:$T$45)),T36) -> 9.6 | J36: =C36+V36 -> 39772028 | K36: =D36+W36 -> 39084000 | M36: =X36+F36 -> 36754313 | O36: =IF(K36=MAX($K$31:$K$34,$K$36:$K$45),MAX($U$31:$U$45)+(100-SUM($U$31:$U$45)),U36) -> 6.3 | R36: 일반용 | T36: =ROUND(D36/$D$47*100,1) -> 9.6 | U36: =ROUND(K36/$K$47*100,1) -> 6.3 | V36: 33428523 | W36: 32557000 | X36: 30771483
A37: 업무난방용 | C37: 941021 | D37: =ROUND((매출액표!G62+매출액표!H62)/1000,0) -> 919890 | F37: 818127 | H37: =IF(D37=MAX($D$31:$D$34,$D$36:$D$45),MAX($T$31:$T$45)+(100-SUM($T$31:$T$45)),T37) -> 1.4 | J37: =C37+V37 -> 12362760 | K37: =D37+W37 -> 12446655 | M37: =X37+F37 -> 11721274 | O37: =IF(K37=MAX($K$31:$K$34,$K$36:$K$45),MAX($U$31:$U$45)+(100-SUM($U$31:$U$45)),U37) -> 2 | R37: 업무난방용 | T37: =ROUND(D37/$D$47*100,1) -> 1.4 | U37: =ROUND(K37/$K$47*100,1) -> 2 | V37: 11421739 | W37: 11526765 | X37: 10903147
A38: 냉방용 | C38: 762778 | D38: =ROUND((매출액표!G69+매출액표!H69)/1000,0) -> 599269 | F38: 539705 | H38: =IF(D38=MAX($D$31:$D$34,$D$36:$D$45),MAX($T$31:$T$45)+(100-SUM($T$31:$T$45)),T38) -> 0.9 | J38: =C38+V38 -> 12374676 | K38: =D38+W38 -> 13367853 | M38: =X38+F38 -> 12467986 | O38: =IF(K38=MAX($K$31:$K$34,$K$36:$K$45),MAX($U$31:$U$45)+(100-SUM($U$31:$U$45)),U38) -> 2.2 | R38: 냉방용 | T38: =ROUND(D38/$D$47*100,1) -> 0.9 | U38: =ROUND(K38/$K$47*100,1) -> 2.2 | V38: 11611898 | W38: 12768584 | X38: 11928281
A39: 산업용 | C39: 17423360 | D39: =ROUND((매출액표!G73+매출액표!H73)/1000,0) -> 14807698 | F39: 16196722 | H39: =IF(D39=MAX($D$31:$D$34,$D$36:$D$45),MAX($T$31:$T$45)+(100-SUM($T$31:$T$45)),T39) -> 21.8 | J39: =C39+V39 -> 91122350 | K39: =D39+W39 -> 86694410 | M39: =X39+F39+1 -> 93645774 | O39: =IF(K39=MAX($K$31:$K$34,$K$36:$K$45),MAX($U$31:$U$45)+(100-SUM($U$31:$U$45)),U39) -> 14 | R39: 산업용 | T39: =ROUND(D39/$D$47*100,1) -> 21.8 | U39: =ROUND(K39/$K$47*100,1) -> 14 | V39: 73698990 | W39: 71886712 | X39: 77449051
A40: 수송용(CNG) | C40: 6176067 | D40: =ROUND(매출액표!G55/1000,0) -> 5976262 | F40: 6143566 | H40: =IF(D40=MAX($D$31:$D$34,$D$36:$D$45),MAX($T$31:$T$45)+(100-SUM($T$31:$T$45)),T40) -> 8.8 | J40: =C40+V40 -> 29724362 | K40: =D40+W40 -> 29569897 | M40: =X40+F40 -> 29874702 | O40: =IF(K40=MAX($K$31:$K$34,$K$36:$K$45),MAX($U$31:$U$45)+(100-SUM($U$31:$U$45)),U40) -> 4.8 | R40: 수송용(CNG) | T40: =ROUND(D40/$D$47*100,1) -> 8.8 | U40: =ROUND(K40/$K$47*100,1) -> 4.8 | V40: 23548295 | W40: 23593635 | X40: 23731136
A41: 수송용(BIO) | C41: 313374 | D41: =ROUND(매출액표!G56/1000,0) -> 272490 | F41: 311817 | H41: =IF(D41=MAX($D$31:$D$34,$D$36:$D$45),MAX($T$31:$T$45)+(100-SUM($T$31:$T$45)),T41) -> 0.4 | J41: =C41+V41 -> 1508187 | K41: =D41+W41 -> 1350359 | M41: =X41+F41 -> 1473997 | O41: =IF(K41=MAX($K$31:$K$34,$K$36:$K$45),MAX($U$31:$U$45)+(100-SUM($U$31:$U$45)),U41) -> 0.2 | R41: 수송용(BIO) | T41: =ROUND(D41/$D$47*100,1) -> 0.4 | U41: =ROUND(K41/$K$47*100,1) -> 0.2 | V41: 1194813 | W41: 1077869 | X41: 1162180
A42: 열병합용 | C42: 456154 | D42: =ROUND((매출액표!G78)/1000,0) -> 368602 | F42: 440711 | H42: =IF(D42=MAX($D$31:$D$34,$D$36:$D$45),MAX($T$31:$T$45)+(100-SUM($T$31:$T$45)),T42) -> 0.5 | J42: =C42+V42 -> 2359368 | K42: =D42+W42 -> 2523642 | M42: =X42+F42 -> 2214559 | O42: =IF(K42=MAX($K$31:$K$34,$K$36:$K$45),MAX($U$31:$U$45)+(100-SUM($U$31:$U$45)),U42) -> 0.4 | R42: 열병합용 | T42: =ROUND(D42/$D$47*100,1) -> 0.5 | U42: =ROUND(K42/$K$47*100,1) -> 0.4 | V42: 1903214 | W42: 2155040 | X42: 1773848
A43: 연료전지용 | C43: 385083 | D43: =ROUND((매출액표!G83+매출액표!H83)/1000,0) -> 284389 | F43: 354461 | H43: =IF(D43=MAX($D$31:$D$34,$D$36:$D$45),MAX($T$31:$T$45)+(100-SUM($T$31:$T$45)),T43) -> 0.4 | J43: =C43+V43 -> 1884220 | K43: =D43+W43 -> 1562079 | M43: =X43+F43 -> 1687643 | O43: =IF(K43=MAX($K$31:$K$34,$K$36:$K$45),MAX($U$31:$U$45)+(100-SUM($U$31:$U$45)),U43) -> 0.3 | R43: 연료전지용 | T43: =ROUND(D43/$D$47*100,1) -> 0.4 | U43: =ROUND(K43/$K$47*100,1) -> 0.3 | V43: 1499137 | W43: 1277690 | X43: 1333182
A44: 열전용설비용 | C44: 11928 | D44: =ROUND((매출액표!G85+매출액표!H85)/1000,0) -> 10902 | F44: 238190 | H44: =IF(D44=MAX($D$31:$D$34,$D$36:$D$45),MAX($T$31:$T$45)+(100-SUM($T$31:$T$45)),T44) -> 0 | J44: =C44+V44 -> 318725 | K44: =D44+W44 -> 95420 | M44: =X44+F44 -> 2463693 | O44: =IF(K44=MAX($K$31:$K$34,$K$36:$K$45),MAX($U$31:$U$45)+(100-SUM($U$31:$U$45)),U44) -> 0 | R44: 열전용설비용 | T44: =ROUND(D44/$D$47*100,1) -> 0 | U44: =ROUND(K44/$K$47*100,1) -> 0 | V44: 306797 | W44: 84518 | X44: 2225503
...

Sheet 매출액표
A4: =LEFT(총괄표!A2,9)&" 매출액집계표" -> 2025년 5월 매출액집계표
A7: 구분 | B7: 적 요 | D7: 도시가스 | H7: 기본료 | I7: 계량기관리비 | J7: 보정기관리비 | K7: 가스부가세 | L7: 계량기부가세 | M7: 보정기부가세 | N7: 합계
D8: 수량(㎥) | E8: 수량(MJ) | F8: 단가 | G8: 공급가액
B9: 전월재고 | D9: 41002738 | E9: 1.7392749e+09
A10: 공 | B10: 당월생산(LNG)(+) | D10: 55265100 | E10: 2356255726
B11: 자가소모(LNG)(-) | D11: =ROUND(-자가소모!D12-D12,4) -> -1677.9 | E11: =ROUND(-자가소모!E12-E12,4) -> -71537.266
B12: 타계정대체(-) | D12: =ROUND(-SUM(자가소모!D6:D7),4) -> 0 | E12: =ROUND(-SUM(자가소모!E6:E7),4) -> 0
B13: 계 | D13: =D9+D10+D12+D11 -> 96266160 | E13: =E9+E10+E11+E12 -> 4.095459e+09
B14: 전월재고 | D14: -18733.2 | E14: -871537.83
A15: 급 | B15: 당월생산(BIO)(+) | D15: 277800 | E15: 11725237
B16: 자가소모(BIO)(-)
B17: 계 | D17: =D14+D15+D16 -> 259066.8 | E17: =E14+E15+E16 -> 10853699
B18: 주 택 용 | C18: 취사용 변동전 | D18: 34.8097 | E18: 1489.5116 | F18: =G18/E18 -> 21.104361 | G18: 31435.19 | H18: 16110 | I18: 0 | N18: =SUM(G18:M18) -> 47545.19
C19: 취사용 변동후 | D19: 481872.69 | E19: 20613682 | F19: =G19/E19 -> 23.503616 | G19: 4.8449606e+08 | H19: 89626610 | I19: 10931200 | N19: =SUM(G19:M19) -> 5.8505387e+08
C20: 사회복지시설할인액 | G20: -41749 | N20: =SUM(G20:M20) -> -41749
C21: 사회적배려 할인액 | G21: -13218200 | N21: =SUM(G21:M21) -> -13218200
C22: 검침착오분조정 | D22: -2371.2566 | E22: -101649.24 | G22: -2321218 | N22: =SUM(G22:M22) -> -2321218
C23: 소계 | D23: =SUM(D18:D22) -> 479536.25 | E23: =SUM(E18:E22) -> 20513522 | F23: =G23/E23 -> 22.860352 | G23: =SUM(G18:G22) -> 468946326 | H23: =SUM(H18:H22) -> 89642720 | I23: =SUM(I18:I22) -> 10931200 | J23: =SUM(J18:J22) -> 0 | K23: =SUM(K18:K22) -> 0 | L23: =SUM(L18:L22) -> 0 | M23: 0 | N23: =SUM(N18:N22) -> 569520246
C24: 취사난방용(취사)변동전 | D24: 37.2016 | E24: 1591.3595 | F24: =G24/E24 -> 20.487633 | G24: 32603.19 | H24: 5400 | N24: =SUM(G24:M24) -> 38003.19
C25: 취사난방용(취사)변동후 | D25: 4820099 | E25: 2.0516701e+08 | F25: =G25/E25 -> 23.504852 | G25: 4.8224202e+09 | H25: 392784300 | I25: 34591230 | N25: =SUM(G25:M25) -> 5.2497958e+09
C26: 취사난방용(난방)변동전 | D26: 41.0139 | E26: 1754.3124 | F26: =G26/E26 -> 21.141411 | G26: 37088.64 | N26: =SUM(G26:M26) -> 37088.64
C27: 취사난방용(난방)변동후 | D27: 12576009 | E27: 5.3530278e+08 | F27: =G27/E27 -> 23.504669 | G27: 1.2582115e+10 | N27: =SUM(G27:M27) -> 1.2582115e+10
C28: 사회복지시설할인액 | G28: -2134285 | N28: =SUM(G28:M28) -> -2134285
C29: 사회적배려 할인액 | G29: -929826245 | N29: =SUM(G29:M29) -> -929826245
C30: 검침착오분조정 | D30: -75598.026 | E30: -3243429.8 | G30: -75374458 | N30: =SUM(G30:M30) -> -75374458
A31: 검 | C31: 소계 | D31: =SUM(D24:D30) -> 17320588 | E31: =SUM(E24:E30) -> 7.3722971e+08 | F31: =G31/E31 -> 22.241738 | G31: =SUM(G24:G30) -> 16397269653 | H31: =SUM(H24:H30) -> 392789700 | I31: =SUM(I24:I30) -> 34591230 | J31: =SUM(J24:J30) -> 0 | K31: =SUM(K24:K30) -> 0 | L31: =SUM(L24:L30) -> 0 | M31: =SUM(M24:M30) -> 0 | N31: =SUM(N24:N30) -> 16824650583
C32: 개별난방용 변동전 | D32: 72.3089 | E32: 3094.1785 | F32: =G32/E32 -> 21.582869 | G32: 66781.25 | H32: 3600 | N32: =SUM(G32:M32) -> 70381.25
C33: 개별난방용 변동후 | D33: 19546282 | E33: 8.3201957e+08 | F33: =G33/E33 -> 23.504646 | G33: 1.9556326e+10 | H33: 568692000 | I33: 136521250 | N33: =SUM(G33:M33) -> 2.0261539e+10
C34: 사회복지시설할인액 | G34: -654346 | N34: =SUM(G34:M34) -> -654346
C35: 검침착오분조정 | D35: -77028.82 | E35: -3305631.4 | G35: -77671500 | N35: =SUM(G35:M35) -> -77671500
C36: 소계 | D36: =SUM(D32:D35) -> 19469326 | E36: =SUM(E32:E35) -> 8.2871704e+08 | F36: =G36/E36 -> 23.503881 | G36: =SUM(G32:G35) -> 19478066467 | H36: =SUM(H32:H35) -> 568695600 | I36: =SUM(I32:I35) -> 136521250 | J36: 0 | K36: =SUM(K32:K35) -> 0 | L36: =SUM(L32:L35) -> 0 | M36: 0 | N36: =SUM(N32:N35) -> 20183283317
C37: 중앙난방용(중앙난방) | D37: 602509.1 | E37: 25661608 | F37: =G37/E37 -> 23.468798 | G37: 602247099 | I37: 1868290 | J37: 1049000 | N37: =L37+K37+I37+H37+G37+J37 -> 605164389
C38: 냉난방용(주택)(중앙난방) | D38: 9922.9476 | E38: 422227.53 | F38: =G38/E38 -> 23.4688 | G38: 9909173.4 | I38: 270690 | J38: 98200 | N38: =L38+K38+I38+H38+G38+J38 -> 10278063
C39: 사회적배려 할인액 | G39: -37167423 | N39: =SUM(G39:M39) -> -37167423
C40: 소계 | D40: =SUM(D37:D39) -> 612432.05 | E40: =SUM(E37:E39) -> 26083835 | F40: =G40/E40 -> 22.043877 | G40: =SUM(G37:G39) -> 5.7498885e+08 | H40: =SUM(H39:H39) -> 0 | I40: =SUM(I37:I39) -> 2138980 | J40: =SUM(J37:J39) -> 1147200 | K40: =SUM(K37:K39) -> 0 | L40: =SUM(L37:L39) -> 0 | M40: 0 | N40: =SUM(N37:N39) -> 5.7827503e+08
C41: 자가열전용 | D41: 246294 | E41: 10496608 | F41: =G41/E41 -> 23.468799 | G41: 246342777 | I41: 712570 | J41: 735000 | N41: =SUM(G41:M41) -> 247790347
C42: 사회적배려 할인액 | G42: -3905671 | N42: =SUM(G42:M42) -> -3905671
C43: 소계 | D43: =SUM(D41:D42) -> 246294 | E43: =SUM(E41:E42) -> 10496608 | F43: =G43/E43 -> 23.09671 | G43: =SUM(G41:G42) -> 242437106 | H43: =SUM(H41:H42) -> 0 | I43: =SUM(I41:I42) -> 712570 | J43: =SUM(J41:J42) -> 735000 | K43: =SUM(K41:K42) -> 0 | L43: =SUM(L41:L42) -> 0 | M43: 0 | N43: =SUM(N41:N42) -> 243884676
C44: 계 | D44: =D23+D31+D36+D43+D40 -> 38128176 | E44: =E23+E31+E36+E43+E40 -> 1.6230407e+09 | F44: =G44/E44 -> 22.89635 | G44: =G23+G31+G36+G43+G40 -> 3.7161708e+10 | H44: =H23+H31+H36+H43+H40 -> 1051128020 | I44: =I23+I31+I36+I43+I40 -> 184895230 | J44: =J23+J31+J36+J43+J40 -> 1882200 | K44: =K23+K31+K36+K43+K40 -> 0 | L44: =L23+L31+L36+L43+L40 -> 0 | M44: 0 | N44: =N23+N31+N36+N43+N40 -> 3.8399614e+10
B45: 일 반용 | C45: 일반용(1) 변동전 | F45: =G45/E45 -> #DIV/0! | N45: =L45+K45+I45+H45+G45+J45 -> 0
...

Sheet 가스공사용(MJ)
B1: ="한국가스공사 제출용 구성비 ("&LEFT(총괄표!A2,9)&")" -> 한국가스공사 제출용 구성비 (2025년 5월 ) | S1: ※ 사회복지시설 정산('23.04.) 물량에서 3월 실사용분 제외 ※ 1. 복지시설에 대한 소급 정산(일반용 단가 적용) 소급 정산: '23.02. 완료 2. 소급대상청구년월: '22.12. ~ '23.01. - 참고사항: 청구월 기준 12월 물량 소급정산하는 대신 3월분 제외하기로 함 (4월 매출에 포함된 물량 일부 제외) ==> 신재홍 차장 (가스공사 전 담당자)와 사회복지시설 한시적할인 정산은 3월까지 하기로 함 ==> 김광연 주임 (가스공사 현 담당자)과도 해당 내용 확인 완료됨
B3: 구 분 | E3: 판 매 량 | F3: 개별소비세 | G3: 사회복지 | H3: 사회적배려 | I3: 차상위할인 | J3: 다자녀할인 | K3: 자가소모 | L3: 판 매 량 계 | M3: 구성비 | Q3: 자가소모
E4: (MJ) | F4: (MJ) | G4: (MJ) | H4: (MJ) | I4: (MJ) | J4: (MJ) | K4: (MJ) | L4: (MJ) | M4: (%) | Q4: (MJ)
B5: 주택용 | C5: 취사용 | E5: =ROUND((매출액표!E23-G5-H5-I5),0) -> 20495201 | G5: =ROUNDDOWN(('사회복지시설(MJ)'!D7),0) -> 18321 | L5: =ROUND((E5+G5+K5),0) -> 20513522 | M5: =ROUND(L5/$L$21*100,4) -> 0.6843
C6: 개별난방용 | E6: =ROUND((매출액표!E31+매출액표!E36-G6-H6-I6),0) -> 1564578125 | G6: =ROUNDDOWN(('사회복지시설(MJ)'!D10),0) -> 1368619 | L6: =ROUND((E6+G6+K6),0) -> 1565946744 | M6: =ROUND(L6/$L$21*100,4)+0.0001 -> 52.2405 | T6: ※ 판매량+(개별소비세+사회복지+사회적배려+차상위할인)=매출액표 수량합계(자가소모포함되어있으므로 제외됨)
C7: 중앙난방용 | E7: =ROUND((매출액표!E40-G7-H7-I7),0) -> 26083835 | L7: =ROUND((E7+G7+K7),0) -> 26083835 | M7: =ROUND(L7/$L$21*100,4) -> 0.8702 | T7: ※ 업무난방과 냉방용은 구별요(5월~9월 냉방용적용)
C8: 자가열전용 | E8: =ROUND((매출액표!E43-G8-H8-I8),0) -> 10496608 | L8: =ROUND((E8+G8+K8),0) -> 10496608 | M8: =ROUND(L8/$L$21*100,4) -> 0.3502 | T8: ※ 매출내역서의 자가소모를 확인한다
C9: 소 계 | E9: =SUM(E5:E8) -> 1621653769 | F9: =SUM(F5:F8) -> 0 | G9: =SUM(G5:G8) -> 1386940 | H9: =SUM(H5:H8) -> 0 | I9: =SUM(I5:I8) -> 0 | J9: =SUM(J5:J8) -> 0 | L9: =SUM(L5:L8) -> 1623040709 | M9: =SUM(M5:M8) -> 54.1452 | Q9: =SUM(Q5:Q8) -> 0 | T9: ※ 개별소비세=특소세할인, 2022년 5월부터 판매량(MJ)에 포함 (가스공사 신재홍차장 확인 시, 구성비 공문으로 개소세 관련내용 확인사항 없음)
B10: 일반용 | C10: 일반용1 | E10: =ROUND((매출액표!E49-G10),0) -> 207239913 | G10: =ROUND(('사회복지시설(MJ)'!D21),0) -> 4918215 | K10: =ROUND(Q10,0) -> 6310 | L10: =ROUND((E10+F10+G10+K10+H10),0) -> 212164438 | M10: =ROUND(L10/$L$21*100,4) -> 7.0779 | Q10: =Q12 -> 6309.98
C11: 일반용2 | E11: =ROUND((매출액표!E53-G11),0) -> 76864293 | L11: =ROUND((E11+F11+G11+K11+H11),0) -> 76864293 | M11: =ROUND(L11/$L$21*100,4) -> 2.5642 | Q11: 0
B12: 일 반 용 | E12: =SUM(E10:E11) -> 284104206 | G12: ='사회복지시설(MJ)'!D21 -> 4918215.1 | H12: =SUM(H10:H11) -> 0 | I12: =SUM(I10:I11) -> 0 | K12: =SUM(K10:K11) -> 6310 | L12: =SUM(E12:K12)+1 -> 2.8902873e+08 | M12: =SUM(M10:M11) -> 9.6421 | Q12: =자가소모!E4 -> 6309.98
B13: 냉난방공조용 | E13: =ROUND((매출액표!E69-G13),0)+E68 -> 30658225 | G13: =('사회복지시설(MJ)'!D17) -> 193936.93 | K13: =ROUND(Q13,0) -> 53038 | L13: =ROUND((E13+G13+K13),0) -> 30905200 | M13: =ROUND(L13/$L$21*100,4) -> 1.031 | Q13: =자가소모!E5 -> 53037.94
B14: 업무난방용 | E14: =ROUND((매출액표!E62-G14),0) -> 28044532 | G14: =('사회복지시설(MJ)'!D14) -> 9645073.2 | K14: =ROUND(Q14,0) -> 12189 | L14: =ROUND((E14+G14+K14),0) -> 37701794 | M14: =ROUND(L14/$L$21*100,4) -> 1.2577 | Q14: =자가소모!E3+자가소모!E8+자가소모!E9 -> 12189.346
B15: 산 업 용 | E15: =ROUND((매출액표!E73-G15),0) -> 717448666 | K15: =ROUND(Q15,0) -> 0 | L15: =ROUND((E15+G15+K15),0) -> 717448666 | M15: =ROUND(L15/$L$21*100,4)-0.0001 -> 23.9342
B16: 수 송 용 | E16: =ROUND((매출액표!E55-G16),0) -> 262403159 | K16: =ROUND(Q16,0) -> 0 | L16: =ROUND((E16+G16+K16),0) -> 262403159 | M16: =ROUND(L16/$L$21*100,4) -> 8.7538
B17: 열 병 합 용 | E17: =ROUND((매출액표!E78-G17),0) -> 17947084 | K17: =ROUND(Q17,0) -> 0 | L17: =ROUND((E17+G17+K17),0) -> 17947084 | M17: =ROUND(L17/$L$21*100,4) -> 0.5987 | Q17: =자가소모!E7 -> 0
B18: 연료전지용 | E18: =ROUND((매출액표!E83-G18),0) -> 16411802 | K18: =ROUND(Q18,0) -> 0 | L18: =ROUND((E18+G18+K18),0) -> 16411802 | M18: =ROUND(L18/$L$21*100,4) -> 0.5475
B19: 열전용설비용 | E19: =ROUND((매출액표!E85-G19),0) -> 464679 | K19: =ROUND(Q19,0) -> 0 | L19: =ROUND((E19+G19+K19),0) -> 464679 | M19: =ROUND(L19/$L$21*100,4) -> 0.0155 | Q19: =자가소모!E6 -> 0
B20: 주한미군 | E20: =ROUND((매출액표!E88-G20),0) -> 2226799 | K20: =ROUND(Q20,0) -> 0 | L20: =ROUND((E20+G20+K20),0) -> 2226799 | M20: =ROUND(L20/$L$21*100,4) -> 0.0743
B21: 합 계 | E21: =SUM(E13:E20)+E12+E9 -> 2981362921 | F21: =F20+F17+F16+F15+F13+F12+F9+F14 -> 0 | G21: =ROUNDUP((G20+G17+G16+G15+G13+G12+G9+G14),0) -> 16144166 | H21: =H20+H17+H16+H15+H13+H12+H9+H14 -> 0 | I21: =I20+I17+I16+I15+I13+I12+I9+I14 -> 0 | J21: =J20+J19+J17+J16+J15+J14+J13+J12+J9 -> 0 | K21: =K20+K17+K16+K15+K13+K12+K9+K14+K19 -> 71537 | L21: =ROUND((SUM(L13:L20)+L12+L9),0) -> 2997578624 | M21: =SUM(M5:M8,M12:M20) -> 100 | Q21: =Q20+Q17+Q16+Q15+Q13+Q12+Q9+Q14+Q19 -> 71537.266
E24: =ROUND(E21+G21,0) -> 2997507087 | K24: =ROUNDDOWN(Q21,0)=K21 -> TRUE | L24: =ROUND(L21-K21,0) -> 2997507087
E25: =ROUND(SUMIFS(매출액표!E:E,매출액표!$B:$B,"합계")-SUMIFS(매출액표!E:E,매출액표!$C:$C,"수송용(BIO)"),0) -> 2997507087 | L25: =ROUND(매출액표!E89-매출액표!E56,0) -> 2997507087
E26: =E24-E25 -> 0 | L26: =L24-L25 -> 0
B64: 구분 | E64: 판매열량(MJ) | H64: 5147 | I64: 4602
B65: 냉방물량(9월) | K65: ※ 관리납기와 일반납기의판매량전산실의뢰 (일반납기 청구작업이후)
B66: (월초) | C66: 관리납기(변동) | K66: - 9월판매실적 작성을 위한 냉방용 상품에대한 변동검침사용량 자료 요청
B67: (청구일) | C67: 일반납기(일수)
B68: 계 | K68: ※ 계절이 바뀌는 4월(기타)↔5월(하절기) 냉방집계 조정
K69: - 시기: 2022년 4월 매출분부터
K70: - 사유: 기존 9월, 10월만 물량조정했으나 가스공사 이의제기로 4월, 5월도 시행하게 됨
K71: - 방법: 5월 일반납기 청구작업 후 냉난방물량(업무, 주택) 일반납기(4/30까지 일할계산), 관리납기(변동검침 4/30까지) ==> 냉난방공조용에 4월 기타월 사용분 추가(+) , 5월 차감 (-)
K74: ※ 9월 판매량에 냉방용을 추가청구하여 10월 판매량에서 차감함
K75: ※ 매출건
K76: - 9월매출은일반납기의 경우 (8/1~8 부터9/1~8사용량)이므로 9월사용분(10월 청구분) 포함
K77: - 관리납기는 (8/16~9/16)까지이나 관리납기는 10월에 변동검침을 했으므로, 9/16~10초까지 변동검침 물량 포함
K79: ※ 사 유 : 냉난방의 경우 10월 하절기ㅡ> 기타 단가로 변동됨에 따라 도매요금인상이 많이 이루어지므로 보전차원에서 9월 정산
K80: [5월의 경우 (기타 ㅡ> 하절기 단가 변동)는 회사 손해가 없으므로 물량정산 안함.]
K82: ※ 9월 냉방용집계확인 할 것
K83: - 냉방용 (+), 10월매출(-) 변동검침확인할 것
K84: - 10/14청구작업후 자료요청할것
...

Sheet 사회복지시설(MJ)
A2: ="사회복지시설 용도별 판매량 ( "&LEFT(총괄표!A2,9)&")" -> 사회복지시설 용도별 판매량 ( 2025년 5월 )
A4: 구분 | C4: 세대수 | D4: 판매량(MJ) | E4: 금액(원) | G4: 차액
E5: 미적용 | F5: 적용
A6: 주 택 용 | B6: 취사용
D7: =SUMIFS(청구할인정산관리!$D:$D,청구할인정산관리!$B:$B,"취사용") -> 18321.957 | E7: =SUMIFS(청구할인정산관리!$E:$E,청구할인정산관리!$B:$B,"취사용") -> 430638 | F7: =SUMIFS(청구할인정산관리!$G:$G,청구할인정산관리!$B:$B,"취사용") -> 388889 | G7: =E7-F7 -> 41749 | H7: =G7/E7 -> 0.096946856
B9: 개 별 난방용
D10: =SUMIFS(청구할인정산관리!$D:$D,청구할인정산관리!$B:$B,"취사난방용")+SUMIFS(청구할인정산관리!$D:$D,청구할인정산관리!$B:$B,"개별난방용") -> 1368619.5 | E10: =SUMIFS(청구할인정산관리!$E:$E,청구할인정산관리!$B:$B,"취사난방용")+SUMIFS(청구할인정산관리!$E:$E,청구할인정산관리!$B:$B,"개별난방용") -> 32168931 | F10: =SUMIFS(청구할인정산관리!$G:$G,청구할인정산관리!$B:$B,"취사난방용")+SUMIFS(청구할인정산관리!$G:$G,청구할인정산관리!$B:$B,"개별난방용") -> 29380300 | G10: =E10-F10 -> 2788631 | H10: =G10/E10 -> 0.086687089
A12: 소 계 | D12: =D10+D7 -> 1386941.5 | E12: =E10+E7 -> 32599569 | F12: =F10+F7 -> 29769189 | G12: =G10+G7 -> 2830380 | H12: =G12/E12 -> 0.08682262
A13: 업 무 용 | B13: 업 무 난방용
D14: =SUMIFS(청구할인정산관리!$D:$D,청구할인정산관리!$B:$B,"업무난방용") -> 9645073.2 | E14: =SUMIFS(청구할인정산관리!$E:$E,청구할인정산관리!$B:$B,"업무난방용") -> 247824991 | F14: =SUMIFS(청구할인정산관리!$G:$G,청구할인정산관리!$B:$B,"업무난방용") -> 205552206 | G14: =E14-F14 -> 42272785 | H14: =G14/E14 -> 0.17057515
B16: 냉난방용 (업무)
D17: =SUMIFS(청구할인정산관리!$D:$D,청구할인정산관리!$B:$B,"냉난방용(업무)") -> 193936.93 | E17: =SUMIFS(청구할인정산관리!$E:$E,청구할인정산관리!$B:$B,"냉난방용(업무)") -> 4722449 | F17: =SUMIFS(청구할인정산관리!$G:$G,청구할인정산관리!$B:$B,"냉난방용(업무)") -> 4193735 | G17: =E17-F17 -> 528714 | H17: =G17/E17 -> 0.11195759
A19: 소 계 | D19: =D14+D17 -> 9839010.1 | E19: =E14+E17 -> 252547440 | F19: =F14+F17 -> 209745941 | G19: =G14+G17 -> 42801499 | H19: =G19/E19 -> 0.16947905
A20: 일 반 용
D21: =SUMIFS(청구할인정산관리!$D:$D,청구할인정산관리!$B:$B,"일반용(1)")+SUMIFS(청구할인정산관리!$D:$D,청구할인정산관리!$B:$B,"일반용(2)") -> 4918215.1 | E21: =SUMIFS(청구할인정산관리!$E:$E,청구할인정산관리!$B:$B,"일반용(1)")+SUMIFS(청구할인정산관리!$E:$E,청구할인정산관리!$B:$B,"일반용(2)") -> 111202258 | F21: =SUMIFS(청구할인정산관리!$G:$G,청구할인정산관리!$B:$B,"일반용(1)")+SUMIFS(청구할인정산관리!$G:$G,청구할인정산관리!$B:$B,"일반용(2)") -> 103944409 | G21: =E21-F21 -> 7257849
A23: 소 계 | D23: =SUM(D20:D22) -> 4918215.1 | E23: =SUM(E20:E22) -> 111202258 | F23: =SUM(F20:F22) -> 103944409 | G23: =SUM(G20:G22) -> 7257849
A24: 연료전지용
G25: =E25-F25 -> 0
A27: 소 계 | D27: =SUM(D24:D26) -> 0 | E27: =SUM(E24:E26) -> 0 | F27: =SUM(F24:F26) -> 0 | G27: =SUM(G24:G26) -> 0
A28: 합 계 | D28: =D23+D12+D19+D27 -> 16144167 | E28: =E23+E12+E19+E27 -> 396349267 | F28: =F23+F12+F19+F27 -> 343459539 | G28: =G23+G12+G19+G27 -> 52889728 | H28: =G28/E28 -> 0.13344222
D39: 정산관리=>청구할인정산관리=>정산년월:마감월, 원가정산항목:사회적복지할인

Sheet 자가소모
B1: 5월
C2: 상품 | D2: 사용량(㎥) | E2: 사용열랑(MJ) | F2: 자가소모량 확인대장
B3: 자가소모 | C3: 업무난방용 | D3: 192 | E3: 8185.92 | F3: 경산지사
B4: 자가소모 | C4: 일반용 | D4: 148 | E4: 6309.98 | F4: 본사 취사용
B5: 자가소모 | C5: 냉난방용 | D5: 1244 | E5: 53037.94 | F5: 냉난방용+서부지사+수성안전팀
B6: 자가소모 | C6: 열전용설비용 | D6: 0 | E6: 0 | F6: 1~3번 보일러 합계
B7: 자가소모 | C7: 열병합용1 | D7: 0 | E7: 0 | F7: 세너지 (1번 ~ 3번발전기) 계-보일러합계
B8: 자가소모 | C8: 퍼지량(CNG) | D8: 0 | E8: 0 | F8: 앞으로 없음. 다 없앰. 관리비가 더 많이 들어서?
B9: 자가소모 | C9: 퍼지량(업무난방) | D9: 93.9 | E9: 4003.4265 | F9: 퍼지량 계 | G9: 총무결재본
B10: 자가소모(LNG) 소계 | D10: =SUM(D3:D9) -> 1677.9 | E10: =SUM(E3:E9) -> 71537.266
B11: 자가소모 | C11: 수송용 (BIO) | D11: 0 | E11: 0
B12: 자가소모 합계 | D12: =SUM(D3:D9) -> 1677.9 | E12: =SUM(E3:E9) -> 71537.266 | F12: 총계와 같아야됨
A16: .
A17: (샘플참고)
F41: 왼쪽 자동 계산 됨

Sheet 판매량-월별추이
B1: 1. 2025년 판매량 현황
AI2: (단위:천MJ)
B3: 용 도 [판매전수] | C3: 판 매 실 적 | F3: 판 매 실 적 | N3: 판 매 실 적 | Q3: 판 매 실 적 | Y3: 판 매 실 적 | AB3: 판 매 실 적
C4: 판매량 | D4: 사업계획 | F4: 사업계획 | G4: 전월누계(1~11월) | I4: 전년동월 | K4: 전년동월 | M4: 구성비 | N4: 판매량 | O4: 사업계획 | Q4: 사업계획 | R4: =MID(총괄표!A2,7,3) -> 5월 | T4: 전년동월 | V4: 전년동월 | X4: 구성비 | Y4: 판매량 | Z4: 사업계획 | AB4: 사업계획 | AC4: 누 계 | AE4: 전년동월 | AG4: 전년동월 | AI4: 구성비
D5: 차이 | E5: 사용량 | G5: 차이 | H5: 사용량 | I5: 차이 | J5: 대비(%) | K5: 차이 | L5: 사용량 | O5: 차이 | P5: 사용량 | R5: 차이 | S5: 사용량 | T5: 차이 | U5: 대비(%) | V5: 차이 | W5: 사용량 | Z5: 차이 | AA5: 사용량 | AC5: 차이 | AD5: 사용량 | AE5: 차이 | AF5: 대비(%) | AG5: 차이 | AH5: 사용량
B6: 주 택 용 | C6: =총괄표!$X$11 -> 18050528 | E6: =총괄표!V11 -> 17639109 | F6: =E6 -> 17639109 | H6: =C6 -> 18050528 | I6: =K7 -> 873752 | J6: =L7 -> 1.0508682 | L6: =총괄표!Y11 -> 17176776 | M6: =C6/$C$18 -> 0.7195472 | N6: =총괄표!E11 -> 1623041 | P6: =총괄표!C11 -> 1607759 | Q6: =P6 -> 1607759 | R6: =O7 -> 15282 | S6: =N6 -> 1623041 | T6: =V7 -> 179670 | U6: =W7 -> 1.1244794 | W6: =총괄표!G11 -> 1443371 | X6: =총괄표!I11 -> 54 | Y6: =C6+N6 -> 19673569 | AA6: =E6+P6 -> 19246868 | AB6: =AA6 -> 19246868 | AC6: =Z7 -> 426701 | AD6: =Y6 -> 19673569 | AE6: =AG7 -> 1053422 | AF6: =AH7 -> 1.0565743 | AH6: =L6+W6 -> 18620147 | AI6: =총괄표!P11 -> 70.1
B7: =VLOOKUP(B6,데이터!$D$33:$E$38,2,FALSE) -> 1134028 | D7: =C6-E6 -> 411419 | E7: =C6/E6 -> 1.0233243 | G7: =H6-F6 -> 411419 | H7: =H6/E6 -> 1.0233243 | K7: =C6-L6 -> 873752 | L7: =C6/L6 -> 1.0508682 | O7: =N6-P6 -> 15282 | P7: =N6/P6 -> 1.0095052 | R7: =(S7-1) -> 0.0095051559 | S7: =P7 -> 1.0095052 | T7: =U6-1 -> 0.12447943 | V7: =N6-W6 -> 179670 | W7: =N6/W6 -> 1.1244794 | Z7: =Y6-AA6 -> 426701 | AA7: =Y6/AA6 -> 1.0221699 | AC7: =AD7-1 -> 0.022169893 | AD7: =AA7 -> 1.0221699 | AE7: =AF6-1 -> 0.056574312 | AG7: =Y6-AH6 -> 1053422 | AH7: =Y6/AH6 -> 1.0565743
B8: 일 반 용 | C8: =총괄표!$X$12 -> 1441833 | E8: =총괄표!V12 -> 1478458 | F8: =E8 -> 1478458 | H8: =C8 -> 1441833 | I8: =K9 -> -11711.271 | J8: =L9 -> 0.99194296 | L8: =총괄표!Y12 -> 1453544.3 | M8: =C8/$C$18 -> 0.057475709 | N8: =총괄표!E12 -> 289022 | P8: =총괄표!C12 -> 280557 | Q8: =P8 -> 280557 | R8: =O9 -> 8465 | S8: =N8 -> 289022 | T8: =V9 -> 3741.398 | U8: =W9 -> 1.0131148 | W8: =총괄표!G12 -> 285280.6 | X8: =총괄표!I12 -> 9.6 | Y8: =C8+N8 -> 1730855 | AA8: =E8+P8 -> 1759015 | AB8: =AA8 -> 1759015 | AC8: =Z9 -> -28160 | AD8: =Y8 -> 1730855 | AE8: =AG9 -> -7969.8729 | AF8: =AH9 -> 0.99541652 | AH8: =L8+W8 -> 1738824.9 | AI8: =총괄표!P12 -> 6.2
B9: =VLOOKUP(B8,데이터!$D$33:$E$38,2,FALSE) -> 21972 | D9: =C8-E8 -> -36625 | E9: =C8/E8 -> 0.97522757 | G9: =H8-F8 -> -36625 | H9: =H8/E8 -> 0.97522757 | K9: =C8-L8 -> -11711.271 | L9: =C8/L8 -> 0.99194296 | O9: =N8-P8 -> 8465 | P9: =N8/P8 -> 1.0301721 | R9: =S9-1 -> 0.030172122 | S9: =P9 -> 1.0301721 | T9: =U8-1 -> 0.0131148 | V9: =N8-W8 -> 3741.398 | W9: =N8/W8 -> 1.0131148 | Z9: =Y8-AA8 -> -28160 | AA9: =Y8/AA8 -> 0.98399104 | AC9: =AD9-1 -> -0.01600896 | AD9: =AA9 -> 0.98399104 | AE9: =AF8-1 -> -0.0045834822 | AG9: =Y8-AH8 -> -7969.8729 | AH9: =Y8/AH8 -> 0.99541652
B10: 업무냉난방용 | C10: =총괄표!$X$13+총괄표!$X$14 -> 975827 | E10: =총괄표!V13+총괄표!V14 -> 909504 | F10: =E10 -> 909504 | H10: =C10 -> 975827 | I10: =K11 -> 54296 | J10: =L11 -> 1.0589193 | L10: =총괄표!Y13+총괄표!Y14 -> 921531 | M10: =C10/$C$18 -> 0.038899338 | N10: =총괄표!E13+총괄표!E14 -> 68542 | P10: =총괄표!C13+총괄표!C14 -> 86570 | Q10: =P10 -> 86570 | R10: =O11 -> -18028 | S10: =N10 -> 68542 | T10: =V11 -> 3084 | U10: =W11 -> 1.0471142 | W10: =총괄표!G13+총괄표!G14 -> 65458 | X10: =SUM(총괄표!I13:I14) -> 2.3 | Y10: =C10+N10 -> 1044369 | AA10: =E10+P10 -> 996074 | AB10: =AA10 -> 996074 | AC10: =Z11 -> 48295 | AD10: =Y10 -> 1044369 | AE10: =AG11 -> 57380 | AF10: =AH11 -> 1.0581364 | AH10: =L10+W10 -> 986989 | AI10: =SUM(총괄표!P13:P14) -> 3.7
B11: =VLOOKUP(B10,데이터!$D$33:$E$38,2,FALSE) -> 7907 | D11: =C10-E10 -> 66323 | E11: =C10/E10 -> 1.0729222 | G11: =H10-F10 -> 66323 | H11: =H10/E10 -> 1.0729222 | K11: =C10-L10 -> 54296 | L11: =C10/L10 -> 1.0589193 | O11: =N10-P10 -> -18028 | P11: =N10/P10 -> 0.79175234 | R11: =S11-1 -> -0.20824766 | S11: =P11 -> 0.79175234 | T11: =U10-1 -> 0.04711418 | V11: =N10-W10 -> 3084 | W11: =N10/W10 -> 1.0471142 | Z11: =Y10-AA10 -> 48295 | AA11: =Y10/AA10 -> 1.0484854 | AC11: =AD11-1 -> 0.048485353 | AD11: =AA11 -> 1.0484854 | AE11: =AF10-1 -> 0.058136413 | AG11: =Y10-AH10 -> 57380 | AH11: =Y10/AH10 -> 1.0581364
B12: 산 업 용 | C12: =총괄표!$X$15 -> 3383198 | E12: =총괄표!V15 -> 3460469 | F12: =E12 -> 3460469 | H12: =C12 -> 3383198 | I12: =K13 -> -191419 | J12: =L13 -> 0.94645049 | L12: =총괄표!Y15 -> 3574617 | M12: =C12/$C$18 -> 0.13486424 | N12: =총괄표!E15 -> 717448 | P12: =총괄표!C15 -> 818098 | Q12: =P12 -> 818098 | R12: =O13 -> -100650 | S12: =N12 -> 717448 | T12: =V13 -> -88367 | U12: =W13 -> 0.89033835 | W12: =총괄표!G15 -> 805815 | X12: =총괄표!I15 -> 23.8 | Y12: =C12+N12 -> 4100646 | AA12: =E12+P12 -> 4278567 | AB12: =AA12 -> 4278567 | AC12: =Z13 -> -177921 | AD12: =Y12 -> 4100646 | AE12: =AG13 -> -279786 | AF12: =AH13 -> 0.93612822 | AH12: =L12+W12 -> 4380432 | AI12: =총괄표!P15 -> 14.6
B13: =VLOOKUP(B12,데이터!$D$33:$E$38,2,FALSE) -> 1124 | D13: =C12-E12 -> -77271 | E13: =C12/E12 -> 0.97767037 | G13: =H12-F12 -> -77271 | H13: =H12/E12 -> 0.97767037 | K13: =C12-L12 -> -191419 | L13: =C12/L12 -> 0.94645049 | O13: =N12-P12 -> -100650 | P13: =N12/P12 -> 0.87697073 | R13: =S13-1 -> -0.12302927 | S13: =P13 -> 0.87697073 | T13: =U12-1 -> -0.10966165 | V13: =N12-W12 -> -88367 | W13: =N12/W12 -> 0.89033835 | Z13: =Y12-AA12 -> -177921 | AA13: =Y12/AA12 -> 0.95841575 | AC13: =AD13-1 -> -0.04158425 | AD13: =AA13 -> 0.95841575 | AE13: =AF12-1 -> -0.063871783 | AG13: =Y12-AH12 -> -279786 | AH13: =Y12/AH12 -> 0.93612822
B14: 수 송 용 | C14: =총괄표!$X$16+총괄표!$X$17 -> 1029476 | E14: =총괄표!V16+총괄표!V17 -> 1028811 | F14: =E14 -> 1028811 | H14: =C14 -> 1029476 | I14: =K15 -> -23929 | J14: =L15 -> 0.97728414 | L14: =총괄표!Y16+총괄표!Y17 -> 1053405 | M14: =C14/$C$18 -> 0.041037945 | N14: =총괄표!E16+총괄표!E17 -> 274367 | P14: =총괄표!C16+총괄표!C17 -> 269829 | Q14: =P14 -> 269829 | R14: =O15 -> 4538 | S14: =N14 -> 274367 | T14: =V15 -> -3673 | U14: =W15 -> 0.98678967 | W14: =총괄표!G16+총괄표!G17 -> 278040 | X14: =SUM(총괄표!I16:I17) -> 9.1 | Y14: =C14+N14 -> 1303843 | AA14: =E14+P14 -> 1298640 | AB14: =AA14 -> 1298640 | AC14: =Z15 -> 5203 | AD14: =Y14 -> 1303843 | AE14: =AG15 -> -27602 | AF14: =AH15 -> 0.97926914 | AH14: =L14+W14 -> 1331445 | AI14: =SUM(총괄표!P16:P17) -> 4.6
B15: =VLOOKUP(B14,데이터!$D$33:$E$38,2,FALSE) -> 103 | D15: =C14-E14 -> 665 | E15: =C14/E14 -> 1.0006464 | G15: =H14-F14 -> 665 | H15: =H14/E14 -> 1.0006464 | K15: =C14-L14 -> -23929 | L15: =C14/L14 -> 0.97728414 | O15: =N14-P14 -> 4538 | P15: =N14/P14 -> 1.0168181 | R15: =S15-1 -> 0.016818059 | S15: =P15 -> 1.0168181 | T15: =U14-1 -> -0.013210329 | V15: =N14-W14 -> -3673 | W15: =N14/W14 -> 0.98678967 | Z15: =Y14-AA14 -> 5203 | AA15: =Y14/AA14 -> 1.0040065 | AC15: =AD15-1 -> 0.0040064991 | AD15: =AA15 -> 1.0040065 | AE15: =AF14-1 -> -0.02073086 | AG15: =Y14-AH14 -> -27602 | AH15: =Y14/AH14 -> 0.97926914
B16: 기 타 | C16: =총괄표!X18+총괄표!X19+총괄표!X20+총괄표!X21 -> 205092 | E16: =총괄표!V18+총괄표!V19+총괄표!V20+총괄표!V21 -> 200594 | F16: =E16 -> 200594 | H16: =C16 -> 205092 | I16: =K17 -> -77562 | J16: =L17 -> 0.72559384 | L16: =총괄표!Y18+총괄표!Y19+총괄표!Y20+총괄표!Y21 -> 282654 | M16: =C16/$C$18 -> 0.0081755711 | N16: =총괄표!E18+총괄표!E19+총괄표!E20+총괄표!E21 -> 37051 | P16: =총괄표!C18+총괄표!C19+총괄표!C20+총괄표!C21 -> 42505 | Q16: =P16 -> 42505 | R16: =O17 -> -5454 | S16: =N16 -> 37051 | T16: =V17 -> -14784 | U16: =W17 -> 0.71478731 | W16: =총괄표!G18+총괄표!G19+총괄표!G20+총괄표!G21 -> 51835 | X16: =SUM(총괄표!I18:I21) -> 1.2 | Y16: =C16+N16 -> 242143 | AA16: =E16+P16 -> 243099 | AB16: =AA16 -> 243099 | AC16: =Z17 -> -956 | AD16: =Y16 -> 242143 | AE16: =AG17 -> -92346 | AF16: =AH17 -> 0.72391917 | AH16: =L16+W16 -> 334489 | AI16: =SUM(총괄표!P18:P21) -> 0.8
B17: =VLOOKUP(B16,데이터!$D$33:$E$38,2,FALSE) -> 343 | D17: =C16-E16 -> 4498 | E17: =C16/E16 -> 1.0224234 | G17: =H16-F16 -> 4498 | H17: =H16/F16 -> 1.0224234 | K17: =C16-L16 -> -77562 | L17: =C16/L16 -> 0.72559384 | O17: =N16-P16 -> -5454 | P17: =N16/P16 -> 0.87168568 | R17: =S17-1 -> -0.12831432 | S17: =P17 -> 0.87168568 | T17: =U16-1 -> -0.28521269 | V17: =N16-W16 -> -14784 | W17: =N16/W16 -> 0.71478731 | Z17: =Y16-AA16 -> -956 | AA17: =Y16/AA16 -> 0.99606745 | AC17: =AD17-1 -> -0.0039325542 | AD17: =AA17 -> 0.99606745 | AE17: =AF16-1 -> -0.27608083 | AG17: =Y16-AH16 -> -92346 | AH17: =Y16/AH16 -> 0.72391917
B18: 총 합 계 | C18: =SUM(C6:C17) -> 25085954 | E18: =E6+E8+E10+E12+E14+E16 -> 24716945 | F18: =SUM(F6:F17) -> 24716945 | H18: =H6+H8+H10+H12+H14+H16 -> 25085954 | I18: =K19 -> 623426.73 | J18: =L19 -> 1.025485 | L18: =L6+L8+L10+L12+L14+L16 -> 24462527 | N18: =SUM(N6:N17) -> 3009471 | P18: =P6+P8+P10+P12+P14+P16 -> 3105318 | Q18: =SUM(Q6:Q17) -> 3105318 | R18: =O19 -> -95847 | S18: =S6+'판매량-월별추이'!S8+S10+S12+S14+S16 -> 3009471 | T18: =V19 -> 79671.398 | U18: =W19 -> 1.0271935 | W18: =W6+W8+W10+W12+W14+W16 -> 2929799.6 | Y18: =SUM(Y6:Y17) -> 28095425 | AA18: =AA6+AA8+AA10+AA12+AA14+AA16 -> 27822263 | AB18: =SUM(AB6:AB17) -> 27822263 | AC18: =Z19 -> 273162 | AD18: =AD6+AD8+AD10+AD12+AD14+AD16 -> 28095425 | AE18: =AG19 -> 703098.13 | AF18: =AH19 -> 1.0256677 | AH18: =AH6+AH8+AH10+AH12+AH14+AH16 -> 27392327
B19: =IF(B7+B9+B11+B13+B15+B17=데이터!E39,B7+B9+B11+B13+B15+B17,"") -> 1165477 | D19: =C18-E18 -> 369009 | E19: =C18/E18 -> 1.0149294 | G19: =H18-F18 -> 369009 | H19: =H18/F18 -> 1.0149294 | K19: =C18-L18 -> 623426.73 | L19: =C18/L18 -> 1.025485 | O19: =N18-P18 -> -95847 | P19: =N18/P18 -> 0.96913456 | R19: =S19-1 -> -0.030865438 | S19: =P19 -> 0.96913456 | T19: =U18-1 -> 0.027193463 | V19: =N18-W18 -> 79671.398 | W19: =N18/W18 -> 1.0271935 | Z19: =Y18-AA18 -> 273162 | AA19: =Y18/AA18 -> 1.0098181 | AC19: =AD19-1 -> 0.0098181086 | AD19: =AA19 -> 1.0098181 | AE19: =AF18-1 -> 0.025667704 | AG19: =Y18-AH18 -> 703098.13 | AH19: =Y18/AH18 -> 1.0256677
B21: ※ 기타 : 열병합용, 연료전지, 열전용설비(주택용외), 주한미군
B22: ※ 구성비는 판매량 정산서 기준으로 작성되었으며 한국가스공사 정산시 수송용(BIO)은 제외되고 자가소모분이 추가 됨 | AL22: =SUM(AD19) -> 1.0098181
AL23: =SUM(S19) -> 0.96913456

Sheet 판매금액-월별추이
B1: 2. 2024년 판매금액 현황
N2: (단위:백만원)
B3: 용 도 | C3: 판 매 금 액 | I3: 판 매 금 액
C4: 사업계획 | D4: ='판매량-월별추이'!R4 -> 5월 | F4: 전년동월 | H4: 구성비 | I4: 사업계획 | J4: 누 계 | L4: 전년동월 | N4: 구성비
D5: 차이 | E5: 금액 | F5: 차이 | G5: 대비(%) | J5: 차이 | K5: 금 액 | L5: 차이 | M5: 대비(%)
B6: 주 택 용 | C6: =총괄표!C35 -> 37893351 | D6: =E6-C6 -> 319485 | E6: =총괄표!D35 -> 38212836 | F6: =총괄표!D35-총괄표!F35 -> 6579544 | G6: =E6/총괄표!F35 -> 1.2079943 | H6: =데이터!B24 -> 56.1 | I6: =총괄표!J35 -> 4.2638009e+08 | J6: =K6-I6 -> 5840434.2 | K6: =총괄표!K35 -> 432220523 | L6: =총괄표!K35-총괄표!M35 -> 52231755 | M6: =K6/총괄표!M35 -> 1.1374561 | N6: =데이터!D24 -> 69.7
D7: =E7-1 -> 0.0084311625 | E7: =E6/C6 -> 1.0084312 | F7: =G6-1 -> 0.20799429 | J7: =K7-1 -> 0.013697718 | K7: =K6/I6 -> 1.0136977 | L7: =M6-1 -> 0.13745605
B8: 일 반 용 | C8: =총괄표!C36 -> 6343505 | D8: =E8-C8 -> 183495 | E8: =총괄표!D36 -> 6527000 | F8: =총괄표!D36-총괄표!F36 -> 544170 | G8: =E8/총괄표!F36 -> 1.0909553 | H8: =데이터!B25 -> 9.6 | I8: =총괄표!J36 -> 39772028 | J8: =K8-I8 -> -688028 | K8: =총괄표!K36 -> 39084000 | L8: =총괄표!K36-총괄표!M36 -> 2329687 | M8: =K8/총괄표!M36 -> 1.0633854 | N8: =데이터!D25 -> 6.3
D9: =E9-1 -> 0.028926437 | E9: =E8/C8 -> 1.0289264 | F9: =G8-1 -> 0.090955284 | J9: =K9-1 -> -0.017299294 | K9: =K8/I8 -> 0.98270071 | L9: =M8-1 -> 0.063385404
B10: 업무냉난방용 | C10: =총괄표!C37+총괄표!C38 -> 1703799 | D10: =E10-C10 -> -184640 | E10: =총괄표!D37+총괄표!D38 -> 1519159 | F10: =(총괄표!D37+총괄표!D38)-(총괄표!F37+총괄표!F38) -> 161327 | G10: =E10/(총괄표!F37+총괄표!F38) -> 1.1188122 | H10: =데이터!B26 -> 2.3 | I10: =총괄표!J37+총괄표!J38 -> 24737436 | J10: =K10-I10 -> 1077072 | K10: =총괄표!K37+총괄표!K38 -> 25814508 | L10: =(총괄표!K37+총괄표!K38)-(총괄표!M37+총괄표!M38) -> 1625248 | M10: =K10/(총괄표!M37+총괄표!M38) -> 1.0671888 | N10: =데이터!D26 -> 4.2
D11: =E11-1 -> -0.10836959 | E11: =E10/C10 -> 0.89163041 | F11: =G10-1 -> 0.11881219 | J11: =K11-1 -> 0.043540163 | K11: =K10/I10 -> 1.0435402 | L11: =M10-1 -> 0.067188827
B12: 산 업 용 | C12: =총괄표!C39 -> 17423360 | D12: =E12-C12 -> -2615662 | E12: =총괄표!D39 -> 14807698 | F12: =총괄표!D39-총괄표!F39 -> -1389024 | G12: =E12/총괄표!F39 -> 0.91424042 | H12: =데이터!B27 -> 21.8 | I12: =총괄표!J39 -> 91122350 | J12: =K12-I12 -> -4427940 | K12: =총괄표!K39 -> 86694410 | L12: =총괄표!K39-총괄표!M39 -> -6951364 | M12: =K12/총괄표!M39 -> 0.92576959 | N12: =데이터!D27 -> 14
D13: =E13-1 -> -0.15012386 | E13: =E12/C12 -> 0.84987614 | F13: =G12-1 -> -0.085759575 | J13: =K13-1 -> -0.048593347 | K13: =K12/I12 -> 0.95140665 | L13: =M12-1 -> -0.074230408
B14: 수 송 용 | C14: =SUM(총괄표!C40:C41) -> 6489441 | D14: =E14-C14 -> -240689 | E14: =SUM(총괄표!D40:D41) -> 6248752 | F14: =(총괄표!D40+총괄표!D41)-(총괄표!F40+총괄표!F41) -> -206631 | G14: =E14/(총괄표!F40+총괄표!F41) -> 0.9679909 | H14: =데이터!B28 -> 9.2 | I14: =SUM(총괄표!J40:J41) -> 31232549 | J14: =K14-I14 -> -312293 | K14: =SUM(총괄표!K40:K41) -> 30920256 | L14: =(총괄표!K40+총괄표!K41)-(총괄표!M40+총괄표!M41) -> -428443 | M14: =K14/(총괄표!M40+총괄표!M41) -> 0.98633299 | N14: =데이터!D28 -> 5
D15: =E15-1 -> -0.037089327 | E15: =E14/C14 -> 0.96291067 | F15: =G14-1 -> -0.0320091 | J15: =K15-1 -> -0.0099989597 | K15: =K14/I14 -> 0.99000104 | L15: =M14-1 -> -0.013667011
B16: 기 타 | C16: =총괄표!C42+총괄표!C43+총괄표!C44+총괄표!C45 -> 929254 | D16: =E16-C16 -> -219909 | E16: =총괄표!D42+총괄표!D43+총괄표!D44+총괄표!D45 -> 709345 | F16: =(총괄표!D42+총괄표!D43+총괄표!D44+총괄표!D45)-(총괄표!F42+총괄표!F43+총괄표!F44+총괄표!F45) -> -391066 | G16: =E16/(총괄표!F42+총괄표!F43+총괄표!F44+총괄표!F45) -> 0.64461824 | H16: =100-SUM(H6:H15) -> 1 | I16: =총괄표!J42+총괄표!J43+총괄표!J44+총괄표!J45 -> 5386030 | J16: =K16-I16 -> -420483 | K16: =총괄표!K42+총괄표!K43+총괄표!K44+총괄표!K45 -> 4965547 | L16: =(총괄표!K42+총괄표!K43+총괄표!K44+총괄표!K45)-(총괄표!M42+총괄표!M43+총괄표!M44+총괄표!M45) -> -2239600 | M16: =K16/(총괄표!M42+총괄표!M43+총괄표!M44+총괄표!M45) -> 0.68916665 | N16: =100-SUM(N6:N15) -> 0.8
D17: =E17-1 -> -0.23665112 | E17: =E16/C16 -> 0.76334888 | F17: =G16-1 -> -0.35538176 | J17: =K17-1 -> -0.07806919 | K17: =K16/I16 -> 0.92193081 | L17: =M16-1 -> -0.31083335
B18: 총 합 계 | C18: =SUM(C6:C17) -> 70782710 | D18: =E18-C18 -> -2757920 | E18: =E6+E8+E10+E12+E14+E16 -> 68024790 | F18: =F6+F8+F10+F12+F14+F16 -> 5298320 | G18: =(E18/총괄표!F47) -> 1.0844671 | I18: =SUM(I6:I17) -> 6.1863048e+08 | J18: =K18-I18 -> 1068762.2 | K18: =K6+K8+K10+K12+K14+K16 -> 619699244 | L18: =L6+L8+L10+L12+L14+L16 -> 46567283 | M18: =(K18/총괄표!M47) -> 1.0812505
D19: =D18/C18 -> -0.038963187 | E19: =E18/C18 -> 0.96103681 | F19: =G18-1 -> 0.084467052 | J19: =J18/I18 -> 0.0017276262 | K19: =K18/I18 -> 1.0017276 | L19: =M18-1 -> 0.081250543

Sheet 데이터
A2: 판매량
A3: ='판매량-월별추이'!R4 -> 5월 | C3: ='판매량-월별추이'!AC4 -> 누 계 | F3: 계획 | G3: 실적
A4: 계획 | B4: 실적 | C4: 계획 | D4: 실적 | E4: 당월 | F4: =A5 -> 3105318 | G4: =B5 -> 3009471
A5: =총괄표!C23 -> 3105318 | B5: =총괄표!E23 -> 3009471 | C5: =총괄표!J23 -> 27822263 | D5: =총괄표!L23 -> 28095425 | E5: 누계 | F5: =C5 -> 27822263 | G5: =D5 -> 28095425
A9: 구성비
A10: =A3 -> 5월 | B10: 구성비 | C10: =C3 -> 누 계 | D10: 구성비
A11: 주 택 용 | B11: =총괄표!I11 -> 54 | C11: 주 택 용 | D11: =총괄표!P11 -> 70.1
A12: 일 반 용 | B12: =총괄표!I12 -> 9.6 | C12: 일 반 용 | D12: =총괄표!P12 -> 6.2
A13: 업무냉방용 | B13: =총괄표!I13+총괄표!I14 -> 2.3 | C13: 업무냉방용 | D13: =총괄표!P13+총괄표!P14 -> 3.7
A14: 산 업 용 | B14: =총괄표!I15 -> 23.8 | C14: 산 업 용 | D14: =총괄표!P15 -> 14.6
A15: 수 송 용 | B15: =총괄표!I16+총괄표!I17 -> 9.1 | C15: 수 송 용 | D15: =총괄표!P16+총괄표!P17 -> 4.6
A16: 기 타 | B16: =총괄표!I18+총괄표!I19+총괄표!I20+총괄표!I21 -> 1.2 | C16: 기 타 | D16: =총괄표!P18+총괄표!P19+총괄표!P20+총괄표!P21 -> 0.8
A17: 판매금액
A18: =A3 -> 5월 | C18: =C3 -> 누 계 | F18: 계획 | G18: 실적
A19: 계획 | B19: 실적 | C19: 계획 | D19: 실적 | E19: 당월 | F19: =A20 -> 70782710 | G19: =B20 -> 68024790
A20: =총괄표!C47 -> 70782710 | B20: =총괄표!D47 -> 68024790 | C20: =총괄표!J47 -> 6.1863048e+08 | D20: =총괄표!K47 -> 619699244 | E20: 누계 | F20: =C20 -> 6.1863048e+08 | G20: =D20 -> 619699244
A22: 판매금액 구성비
A23: =A18 -> 5월 | B23: 구성비 | C23: =C18 -> 누 계 | D23: 구성비
A24: 주 택 용 | B24: =총괄표!H35 -> 56.1 | C24: 주 택 용 | D24: =총괄표!O35 -> 69.7
A25: 일 반 용 | B25: =총괄표!H36 -> 9.6 | C25: 일 반 용 | D25: =총괄표!O36 -> 6.3
A26: 업무냉방용 | B26: =총괄표!H37+총괄표!H38 -> 2.3 | C26: 업무냉방용 | D26: =총괄표!O37+총괄표!O38 -> 4.2
A27: 산 업 용 | B27: =총괄표!H39 -> 21.8 | C27: 산 업 용 | D27: =총괄표!O39 -> 14
A28: 수 송 용 | B28: =총괄표!H40+총괄표!H41 -> 9.2 | C28: 수 송 용 | D28: =총괄표!O40+총괄표!O41 -> 5
A29: 기 타 | B29: =총괄표!H42+총괄표!H43+총괄표!H44+총괄표!H45 -> 1 | C29: 기 타 | D29: =총괄표!O42+총괄표!O43+총괄표!O44+총괄표!O45 -> 0.8
A31: 상품별 건수 (전산요청, 파일입력 후 => 판매량월별추이 상품별 전수 입력할 것)
A32: 상품 | B32: 공급전수 | D32: 용도 | E32: 검수
A33: 취사용 | B33: 61282 | D33: 주 택 용 | E33: =SUM(B33:B35,B37,B47) -> 1134028
A34: 취사난방용 | B34: 436781 | D34: 일 반 용 | E34: =SUM(B38:B39) -> 21972
A35: 중앙난방용 | B35: 106 | D35: 업무냉난방용 | E35: =SUM(B43,B45:B46) -> 7907
A36: 주한미군 | B36: 266 | D36: 산 업 용 | E36: =SUM(B44) -> 1124
A37: 자가열전용 | B37: 26 | D37: 수 송 용 | E37: =SUM(B48:B49) -> 103
A38: 일반용(2) | B38: 1066 | D38: 기 타 | E38: =SUM(B36,B40,B41,B42) -> 343
A39: 일반용(1) | B39: 20906 | D39: 합 계 | E39: =SUM(E33:E38) -> 1165477
A40: 열전용설비용 | B40: 5
A41: 열병합용 | B41: 17
A42: 연료전지 | B42: 55
A43: 업무난방용 | B43: 6822
A44: 산업용 | B44: 1124
A45: 냉난방용(주택) | B45: 30
A46: 냉난방용(업무) | B46: 1055
...

Sheet 매출관리(월)
A2: 매 출 내 역
A4: 매출년월 : | B4: 45413 | U4: 정상매출
A5: 적용일 | B5: 매출구분 | C5: 상품 | D5: 서비스 | E5: 단가 | F5: 사용량 | G5: 사용열량 | H5: 사용료 | I5: 기본료 | J5: 관리비(계) | K5: 관리비(보) | L5: 사용료(할인전) | M5: 사회복지 | N5: 배려할인 | O5: 차상위 | P5: 다자녀 | Q5: 안전관리비 | R5: 수입부과금 | S5: 특소세 | U5: 상품 | V5: 서비스 | W5: 단가변동갯수 | X5: 변동 후 단가
A6: 43654 | B6: 정상매출 | C6: 취사난방용 | D6: 개별난방(취사) | E6: 16.9367 | F6: 0.0781 | G6: 3.3403 | H6: 56.57 | I6: 900 | L6: 56.57 | R6: 0 | U6: 취사용 | V6: 취사용 | W6: =COUNTIFS($B:$B,$U$4,$C:$C,U6) -> 3 | X6: {=MAX(IF($D:$D=V6,$A:$A))} -> 45139
A7: 44013 | B7: 정상매출 | C7: 취사난방용 | D7: 개별난방(취사) | E7: 15.1523 | F7: 2.4291 | G7: 103.8789 | H7: 1574 | I7: 900 | L7: 1574 | R7: 0 | U7: 개별난방용 | V7: 개별난방 | W7: =COUNTIFS($B:$B,$U$4,$C:$C,U7) -> 7 | X7: {=MAX(IF($D:$D=V7,$A:$A))} -> 45139
A8: 44378 | B8: 정상매출 | C8: 개별난방용 | D8: 개별난방 | E8: 15.1392 | F8: 3.8915 | G8: 166.6285 | H8: 2522.61 | I8: 1800 | L8: 2522.61 | R8: 0 | U8: 취사난방용 | V8: 개별난방 | W8: =COUNTIFS($B:$B,$U$4,$C:$C,U8) -> 13 | X8: {=MAX(IF($D:$D=V8,$A:$A))} -> 45139
A9: 44378 | B9: 정상매출 | C9: 취사난방용 | D9: 개별난방(취사) | E9: 15.1392 | F9: 2.4038 | G9: 102.7997 | H9: 1556.29 | L9: 1556.29 | R9: 0 | U9: 취사난방용 | V9: 개별난방(취사) | W9: =COUNTIFS($B:$B,$U$4,$C:$C,U9) -> 13 | X9: {=MAX(IF($D:$D=V9,$A:$A))} -> 45139
A10: 44652 | B10: 정상매출 | C10: 개별난방용 | D10: 개별난방 | E10: 15.5692 | F10: 0.7134 | G10: 30.5486 | H10: 475.6 | L10: 475.6 | R10: 0 | U10: 일반용(1) | V10: 일반용(1)(동절기) | W10: =COUNTIFS($B:$B,$U$4,$C:$C,U10) -> 3 | X10: {=MAX(IF($D:$D=V10,$A:$A))} -> 45139
A11: 44652 | B11: 정상매출 | C11: 취사난방용 | D11: 개별난방(취사) | E11: 15.5692 | F11: 0.2632 | G11: 11.2554 | H11: 175.23 | L11: 175.23 | R11: 0 | U11: 일반용(1) | V11: 일반용(1)(기타) | W11: =COUNTIFS($B:$B,$U$4,$C:$C,U11) -> 3 | X11: {=MAX(IF($D:$D=V11,$A:$A))} -> 45139 | Y11: 매출관리(월)'!$A:$A,VLOOKUP("일반용(1)(하절기)",변동후단가표,3,FALSE))+SUMIFS('매출관리(월)'!$F:$F,'매출관리(월)'!$B:$B,"정상매출",'매출관리(월)'!$C:$C,LEFT($C53,6),'매출관리(월)'!$D:$D,"XXXXXX")
A12: 44682 | B12: 정상매출 | C12: 개별난방용 | D12: 개별난방 | E12: 16.7959 | F12: 1.4506 | G12: 62.1155 | H12: 1043.27 | L12: 1043.27 | R12: 0 | U12: 일반용(1) | V12: 일반용(1)(하절기) | W12: =COUNTIFS($B:$B,$U$4,$C:$C,U12) -> 3 | X12: {=MAX(IF($D:$D=V12,$A:$A))} -> 45139
A13: 44682 | B13: 정상매출 | C13: 취사난방용 | D13: 개별난방(취사) | E13: 16.7959 | F13: 0.5352 | G13: 22.8861 | H13: 384.38 | L13: 384.38 | R13: 0 | U13: 주한미군 | V13: 주한미군 | W13: =COUNTIFS($B:$B,$U$4,$C:$C,U13) -> 1 | X13: {=MAX(IF($D:$D=V13,$A:$A))} -> 45352
A14: 44743 | B14: 정상매출 | C14: 개별난방용 | D14: 개별난방 | E14: 17.9547 | F14: 2.1878 | G14: 93.6824 | H14: 1682.03 | L14: 1682.03 | R14: 0 | U14: 업무난방용 | V14: 업무난방 | W14: =COUNTIFS($B:$B,$U$4,$C:$C,U14) -> 5 | X14: {=MAX(IF($D:$D=V14,$A:$A))} -> 45444
A15: 44743 | B15: 정상매출 | C15: 취사난방용 | D15: 개별난방(취사) | E15: 17.9547 | F15: 0.8071 | G15: 34.5167 | H15: 619.72 | L15: 619.72 | R15: 0 | U15: 중앙난방용 | V15: 중앙난방 | W15: =COUNTIFS($B:$B,$U$4,$C:$C,U15) -> 1 | X15: {=MAX(IF($D:$D=V15,$A:$A))} -> 45139
A16: 44835 | B16: 정상매출 | C16: 취사용 | D16: 취사용 | E16: 20.6547 | F16: 5.9035 | G16: 252.6116 | H16: 5217.58 | I16: 8940 | J16: 1160 | L16: 5217.58 | R16: 0 | U16: 일반용(2) | V16: 일반용(2)(동절기) | W16: =COUNTIFS($B:$B,$U$4,$C:$C,U16) -> 2 | X16: {=MAX(IF($D:$D=V16,$A:$A))} -> 0
A17: 44835 | B17: 정상매출 | C17: 개별난방용 | D17: 개별난방 | E17: 20.6547 | F17: 24.2009 | G17: 1034.3156 | H17: 21363.45 | I17: 2700 | J17: 580 | L17: 21363.45 | R17: 0 | U17: 일반용(2) | V17: 일반용(2)(기타) | W17: =COUNTIFS($B:$B,$U$4,$C:$C,U17) -> 2 | X17: {=MAX(IF($D:$D=V17,$A:$A))} -> 45139
A18: 44835 | B18: 정상매출 | C18: 취사난방용 | D18: 개별난방(취사) | E18: 20.6547 | F18: 15.146 | G18: 647.4868 | H18: 13373.59 | I18: 6300 | L18: 13373.59 | R18: 0 | U18: 일반용(2) | V18: 일반용(2)(하절기) | W18: =COUNTIFS($B:$B,$U$4,$C:$C,U18) -> 2 | X18: {=MAX(IF($D:$D=V18,$A:$A))} -> 45139
A19: 44835 | B19: 정상매출 | C19: 취사난방용 | D19: 개별난방 | E19: 20.6547 | F19: 76.333 | G19: 3264.5569 | H19: 67428.42 | L19: 67428.42 | R19: 0 | U19: 자가열전용 | V19: 자가열전용 | W19: =COUNTIFS($B:$B,$U$4,$C:$C,U19) -> 1 | X19: {=MAX(IF($D:$D=V19,$A:$A))} -> 45139
A20: 45062 | B20: 정상매출 | C20: 취사용 | D20: 취사용 | E20: 21.6991 | F20: 8.8399 | G20: 377.5479 | H20: 8192.39 | I20: 8350 | J20: 1160 | L20: 8192.39 | R20: 0 | U20: 산업용 | V20: 산업용(동절기) | W20: =COUNTIFS($B:$B,$U$4,$C:$C,U20) -> 2 | X20: {=MAX(IF($D:$D=V20,$A:$A))} -> 0
A21: 45062 | B21: 정상매출 | C21: 개별난방용 | D21: 개별난방 | E21: 21.6991 | F21: 23.0577 | G21: 985.015 | H21: 21373.9 | L21: 21373.9 | R21: 0 | U21: 산업용 | V21: 산업용(기타) | W21: =COUNTIFS($B:$B,$U$4,$C:$C,U21) -> 2 | X21: {=MAX(IF($D:$D=V21,$A:$A))} -> 45413
A22: 45062 | B22: 정상매출 | C22: 취사난방용 | D22: 개별난방(취사) | E22: 21.6991 | F22: 13.9899 | G22: 597.6859 | H22: 12969.19 | I22: 2700 | L22: 12969.19 | R22: 0 | U22: 산업용 | V22: 산업용(하절기) | W22: =COUNTIFS($B:$B,$U$4,$C:$C,U22) -> 2 | X22: {=MAX(IF($D:$D=V22,$A:$A))} -> 45444
A23: 45062 | B23: 정상매출 | C23: 취사난방용 | D23: 개별난방 | E23: 21.6991 | F23: 49.7608 | G23: 2127.2721 | H23: 46159.87 | L23: 46159.87 | R23: 0 | U23: 냉난방용(업무) | V23: 냉난방(동절기) | W23: =COUNTIFS($B:$B,$U$4,$C:$C,U23) -> 3 | X23: {=MAX(IF($D:$D=V23,$A:$A))} -> 0
A24: 45139 | B24: 정상매출 | C24: 취사용 | D24: 취사용 | E24: 21.8472 | F24: 480547.55 | G24: 20505703 | H24: 4.4793194e+08 | I24: 92691770 | J24: 17135370 | L24: 4.4796404e+08 | M24: 32105 | R24: 0 | U24: 냉난방용(업무) | V24: 냉난방(기타) | W24: =COUNTIFS($B:$B,$U$4,$C:$C,U24) -> 3 | X24: {=MAX(IF($D:$D=V24,$A:$A))} -> 0
A25: 45139 | B25: 정상매출 | C25: 개별난방용 | D25: 개별난방 | E25: 21.8472 | F25: 10846906 | G25: 4.6203551e+08 | H25: 1.009365e+10 | I25: 526008600 | J25: 119152980 | L25: 1.0093901e+10 | M25: 251663 | R25: 0 | U25: 냉난방용(업무) | V25: 냉난방(하절기) | W25: =COUNTIFS($B:$B,$U$4,$C:$C,U25) -> 3 | X25: {=MAX(IF($D:$D=V25,$A:$A))} -> 45444
A26: 45139 | B26: 정상매출 | C26: 취사난방용 | D26: 개별난방(취사) | E26: 21.8472 | F26: 4795920.8 | G26: 2.0428957e+08 | H26: 4.4628248e+09 | I26: 417552300 | J26: 37963000 | L26: 4.4630846e+09 | M26: 259746.18 | R26: 0 | U26: 냉난방용(업무) | V26: 중앙난방 | W26: =COUNTIFS($B:$B,$U$4,$C:$C,U26) -> 3 | X26: {=MAX(IF($D:$D=V26,$A:$A))} -> 45139
A27: 45139 | B27: 정상매출 | C27: 취사난방용 | D27: 개별난방 | E27: 21.8472 | F27: 6119621.4 | G27: 2.6067845e+08 | H27: 5.6943698e+09 | L27: 5.6949365e+09 | M27: 566772.82 | R27: 0 | U27: 열전용설비용 | V27: 열전용설비용 | W27: =COUNTIFS($B:$B,$U$4,$C:$C,U27) -> 1 | X27: {=MAX(IF($D:$D=V27,$A:$A))} -> 45444
A28: 45139 | B28: 정상매출 | C28: 중앙난방용 | D28: 중앙난방 | E28: 21.8144 | F28: 469114.53 | G28: 19916008 | H28: 434455731 | J28: 1804180 | K28: 1049000 | L28: 434455731 | R28: 0 | U28: 냉난방용(주택) | V28: 냉난방(하절기) | W28: =COUNTIFS($B:$B,$U$4,$C:$C,U28) -> 2 | X28: {=MAX(IF($D:$D=V28,$A:$A))} -> 45444
A29: 45139 | B29: 정상매출 | C29: 일반용(1) | D29: 일반용(1)(동절기) | E29: 21.1877 | F29: 47.5751 | G29: 2036.4354 | H29: 43147.36 | J29: 1300 | L29: 43147.36 | R29: 0 | U29: 냉난방용(주택) | V29: 냉난방(기타) | W29: =COUNTIFS($B:$B,$U$4,$C:$C,U29) -> 2 | X29: {=MAX(IF($D:$D=V29,$A:$A))} -> 0
A30: 45139 | B30: 정상매출 | C30: 일반용(1) | D30: 일반용(1)(하절기) | E30: 20.9808 | F30: 1131902.4 | G30: 48106659 | H30: 1.0084343e+09 | J30: 618880 | K30: 117600 | L30: 1.0093064e+09 | M30: 872144.69 | R30: 0 | U30: 냉난방용(주택) | V30: 중앙난방 | W30: =COUNTIFS($B:$B,$U$4,$C:$C,U30) -> 2 | X30: {=MAX(IF($D:$D=V30,$A:$A))} -> 45139
A31: 45139 | B31: 정상매출 | C31: 일반용(1) | D31: 일반용(1)(기타) | E31: 20.9934 | F31: 3695365 | G31: 1.5733697e+08 | H31: 3.3019727e+09 | J31: 38016940 | K31: 1168900 | L31: 3.3030378e+09 | M31: 1065083.3 | R31: 0 | U31: 열병합용 | V31: 열병합용(동절기) | W31: =COUNTIFS($B:$B,$U$4,$C:$C,U31) -> 3 | X31: {=MAX(IF($C:$C=U31,$A:$A))} -> 45444
A32: 45139 | B32: 정상매출 | C32: 일반용(2) | D32: 일반용(2)(하절기) | E32: 20.9808 | F32: 841753.16 | G32: 35745418 | H32: 7.4910574e+08 | J32: 186700 | K32: 29400 | L32: 7.4996702e+08 | M32: 861283.42 | R32: 0 | U32: 열병합용 | V32: 열병합용(기타) | W32: =COUNTIFS($B:$B,$U$4,$C:$C,U32) -> 3 | X32: {=MAX(IF($C:$C=U32,$A:$A))} -> 45444
A33: 45139 | B33: 정상매출 | C33: 일반용(2) | D33: 일반용(2)(기타) | E33: 20.9934 | F33: 709236.7 | G33: 30144216 | H33: 6.3230675e+08 | J33: 10158960 | K33: 2578400 | L33: 6.3282958e+08 | M33: 522836.58 | R33: 0 | U33: 열병합용 | V33: 열병합용(하절기) | W33: =COUNTIFS($B:$B,$U$4,$C:$C,U33) -> 3 | X33: {=MAX(IF($C:$C=U33,$A:$A))} -> 45444
A34: 45139 | B34: 정상매출 | C34: 자가열전용 | D34: 자가열전용 | E34: 21.8144 | F34: 126655 | G34: 5375871.5 | H34: 117271403 | J34: 712570 | K34: 735000 | L34: 117271403 | R34: 0 | U34: 연료전지 | V34: 연료전지(하절기) | W34: =COUNTIFS($B:$B,$U$4,$C:$C,U34) -> 3 | X34: {=MAX(IF($D:$D=V34,$A:$A))} -> 45444
A35: 45323 | B35: 정상매출 | C35: 업무난방용 | D35: 업무난방 | E35: 24.6278 | F35: 0.3956 | G35: 16.937 | H35: 417.12 | J35: 320 | L35: 417.12 | R35: 0 | U35: 연료전지 | V35: 연료전지(기타) | W35: =COUNTIFS($B:$B,$U$4,$C:$C,U35) -> 3 | X35: {=MAX(IF($D:$D=V35,$A:$A))} -> 45413
